Workbook
Name К1_Общий_8_2: SIGNAL!$T:$W
Name К1_Черновая_8_2: SIGNAL!$Z:$AC
Name К1_Чистовая_8_2: SIGNAL!$AF:$AI
Name К2_Общий_8_2: SIGNAL!$AL:$AO
Name К2_Черновая_8_2: SIGNAL!$AR:$AU
Name К2_Чистовая_8_2: SIGNAL!$AX:$BA
Name К3_Общий_8_2: SIGNAL!$BD:$BG
Name К3_Черновая_8_2: SIGNAL!$BJ:$BM
Name К3_Чистовая_8_2: SIGNAL!$BP:$BS
Name Общая: SIGNAL!$CN:$CQ
Name Общий_8_1: SIGNAL!$B:$E
Name Общий_8_2: SIGNAL!$BV:$BY
Name Черновая: SIGNAL!$CT:$CW
Name Черновая_8_1: SIGNAL!$H:$K
Name Черновая_8_2: SIGNAL!$CB:$CE
Name Чистовая: SIGNAL!$CZ:$DC
Name Чистовая_8_1: SIGNAL!$N:$Q
Name Чистовая_8_2: SIGNAL!$CH:$CK

Sheet СПРАВОЧНИК
A1: СПРАВОЧНИК КАТЕГОРИЙ ОТДЕЛКИ
A2: Код | B2: Часть | C2: Название | D2: План м² | E2: Вес черн. | F2: Вес чист. | G2: ∑ весов | H2: Черн:Пол | I2: Черн:Стены | J2: Черн:Потолок | K2: ∑ черн. | L2: Чист:Пол | M2: Чист:Стены | N2: Чист:Потолок | O2: Чист:Мебл. | P2: ∑ чист. | Q2: Начало | R2: Окончание | S2: Длит.(дни) | T2: Труд-proxy | U2: Вес ур.3 (авто) | V2: Вес ур.3 | W2: Глоб. вес
A3: 8.1.1 | B3: Подзем. | C3: Отделка паркинг и рампы | D3: 0 | E3: 0.45 | F3: 0.55 | G3: =E3+F3 -> 1 | H3: 0.38 | I3: 0.41 | J3: 0.21 | K3: =SUM(H3:J3) -> 1 | L3: 0.52 | M3: 0.34 | N3: 0.14 | O3: 0 | P3: =SUM(L3:O3) -> 1 | S3: =IF(OR(Q3="",R3=""),0,R3-Q3) -> 0 | T3: =S3*D3 -> 0 | U3: =IFERROR(T3/SUMIF($B$3:$B$15,$B3,$T$3:$T$15),0) -> 0 | V3: =U3 -> 0 | W3: =V3*IF($B3="Подзем.",$V$18,$V$19) -> 0
A4: 8.1.2 | B4: Подзем. | C4: Отделка эвакуац. лестн. клетки подзем. | D4: 0 | E4: 0.33 | F4: 0.67 | G4: =E4+F4 -> 1 | H4: 0.2 | I4: 0.61 | J4: 0.19 | K4: =SUM(H4:J4) -> 1 | L4: 0.38 | M4: 0.35 | N4: 0.27 | O4: 0 | P4: =SUM(L4:O4) -> 1 | S4: =IF(OR(Q4="",R4=""),0,R4-Q4) -> 0 | T4: =S4*D4 -> 0 | U4: =IFERROR(T4/SUMIF($B$3:$B$15,$B4,$T$3:$T$15),0) -> 0 | V4: =U4 -> 0 | W4: =V4*IF($B4="Подзем.",$V$18,$V$19) -> 0
A5: 8.1.3 | B5: Подзем. | C5: Лифт. холлы, тамбур-шлюзы подзем. | D5: 0 | E5: 0.4 | F5: 0.6 | G5: =E5+F5 -> 1 | H5: 0.4 | I5: 0.3 | J5: 0.3 | K5: =SUM(H5:J5) -> 1 | L5: 0.2 | M5: 0.6 | N5: 0.2 | O5: 0 | P5: =SUM(L5:O5) -> 1 | S5: =IF(OR(Q5="",R5=""),0,R5-Q5) -> 0 | T5: =S5*D5 -> 0 | U5: =IFERROR(T5/SUMIF($B$3:$B$15,$B5,$T$3:$T$15),0) -> 0 | V5: =U5 -> 0 | W5: =V5*IF($B5="Подзем.",$V$18,$V$19) -> 0
A6: 8.1.4 | B6: Подзем. | C6: Технич. помещения подзем. | D6: 0 | E6: 0.32 | F6: 0.68 | G6: =E6+F6 -> 1 | H6: 0.3 | I6: 0.52 | J6: 0.18 | K6: =SUM(H6:J6) -> 1 | L6: 0.39 | M6: 0.45 | N6: 0.16 | O6: 0 | P6: =SUM(L6:O6) -> 1 | S6: =IF(OR(Q6="",R6=""),0,R6-Q6) -> 0 | T6: =S6*D6 -> 0 | U6: =IFERROR(T6/SUMIF($B$3:$B$15,$B6,$T$3:$T$15),0) -> 0 | V6: =U6 -> 0 | W6: =V6*IF($B6="Подзем.",$V$18,$V$19) -> 0
A7: 8.1.5 | B7: Подзем. | C7: Прочие помещения подзем. | D7: 0 | E7: 0.4 | F7: 0.6 | G7: =E7+F7 -> 1 | H7: 0.31 | I7: 0.49 | J7: 0.2 | K7: =SUM(H7:J7) -> 1 | L7: 0.4 | M7: 0.48 | N7: 0.12 | O7: 0 | P7: =SUM(L7:O7) -> 1 | S7: =IF(OR(Q7="",R7=""),0,R7-Q7) -> 0 | T7: =S7*D7 -> 0 | U7: =IFERROR(T7/SUMIF($B$3:$B$15,$B7,$T$3:$T$15),0) -> 0 | V7: =U7 -> 0 | W7: =V7*IF($B7="Подзем.",$V$18,$V$19) -> 0
A8: 8.1.6 | B8: Подзем. | C8: Коммерч. помещения подзем. | D8: 0 | E8: 0.5 | F8: 0.5 | G8: =E8+F8 -> 1 | H8: 0.3 | I8: 0.69 | J8: 0.01 | K8: =SUM(H8:J8) -> 1 | L8: 0.2 | M8: 0.6 | N8: 0.2 | O8: 0 | P8: =SUM(L8:O8) -> 1 | S8: =IF(OR(Q8="",R8=""),0,R8-Q8) -> 0 | T8: =S8*D8 -> 0 | U8: =IFERROR(T8/SUMIF($B$3:$B$15,$B8,$T$3:$T$15),0) -> 0 | V8: =U8 -> 0 | W8: =V8*IF($B8="Подзем.",$V$18,$V$19) -> 0
A9: 8.2.1 | B9: Надзем. | C9: Отделка лобби/гранд-лобби | D9: =B28+B29+B30 -> 0 | E9: 0.4 | F9: 0.6 | G9: =E9+F9 -> 1 | H9: 0.2 | I9: 0.63 | J9: 0.17 | K9: =SUM(H9:J9) -> 1 | L9: 0.14 | M9: 0.41 | N9: 0.36 | O9: 0.09 | P9: =SUM(L9:O9) -> 1 | S9: =IF(OR(Q9="",R9=""),0,R9-Q9) -> 0 | T9: =S9*D9 -> 0 | U9: =IFERROR(T9/SUMIF($B$3:$B$15,$B9,$T$3:$T$15),0) -> 0 | V9: =U9 -> 0 | W9: =V9*IF($B9="Подзем.",$V$18,$V$19) -> 0
A10: 8.2.2 | B10: Надзем. | C10: Отделка эвакуац. лестн. клетки надзем. | D10: =C28+C29+C30 -> 0 | E10: 0.33 | F10: 0.67 | G10: =E10+F10 -> 1 | H10: 0.2 | I10: 0.61 | J10: 0.19 | K10: =SUM(H10:J10) -> 1 | L10: 0.38 | M10: 0.35 | N10: 0.27 | O10: 0 | P10: =SUM(L10:O10) -> 1 | S10: =IF(OR(Q10="",R10=""),0,R10-Q10) -> 0 | T10: =S10*D10 -> 0 | U10: =IFERROR(T10/SUMIF($B$3:$B$15,$B10,$T$3:$T$15),0) -> 0 | V10: =U10 -> 0 | W10: =V10*IF($B10="Подзем.",$V$18,$V$19) -> 0
A11: 8.2.3 | B11: Надзем. | C11: Лифт. холлы, тамбур-шлюзы надзем. | D11: =D28+D29+D30 -> 0 | E11: 0.4 | F11: 0.6 | G11: =E11+F11 -> 1 | H11: 0.4 | I11: 0.3 | J11: 0.3 | K11: =SUM(H11:J11) -> 1 | L11: 0.2 | M11: 0.6 | N11: 0.2 | O11: 0 | P11: =SUM(L11:O11) -> 1 | S11: =IF(OR(Q11="",R11=""),0,R11-Q11) -> 0 | T11: =S11*D11 -> 0 | U11: =IFERROR(T11/SUMIF($B$3:$B$15,$B11,$T$3:$T$15),0) -> 0 | V11: =U11 -> 0 | W11: =V11*IF($B11="Подзем.",$V$18,$V$19) -> 0
A12: 8.2.4 | B12: Надзем. | C12: Технич. помещения надзем. | D12: =E28+E29+E30 -> 0 | E12: 0.32 | F12: 0.68 | G12: =E12+F12 -> 1 | H12: 0.3 | I12: 0.52 | J12: 0.18 | K12: =SUM(H12:J12) -> 1 | L12: 0.39 | M12: 0.45 | N12: 0.16 | O12: 0 | P12: =SUM(L12:O12) -> 1 | S12: =IF(OR(Q12="",R12=""),0,R12-Q12) -> 0 | T12: =S12*D12 -> 0 | U12: =IFERROR(T12/SUMIF($B$3:$B$15,$B12,$T$3:$T$15),0) -> 0 | V12: =U12 -> 0 | W12: =V12*IF($B12="Подзем.",$V$18,$V$19) -> 0
A13: 8.2.5 | B13: Надзем. | C13: Прочие помещения надзем. | D13: =F28+F29+F30 -> 0 | E13: 0.4 | F13: 0.6 | G13: =E13+F13 -> 1 | H13: 0.31 | I13: 0.49 | J13: 0.2 | K13: =SUM(H13:J13) -> 1 | L13: 0.4 | M13: 0.48 | N13: 0.12 | O13: 0 | P13: =SUM(L13:O13) -> 1 | S13: =IF(OR(Q13="",R13=""),0,R13-Q13) -> 0 | T13: =S13*D13 -> 0 | U13: =IFERROR(T13/SUMIF($B$3:$B$15,$B13,$T$3:$T$15),0) -> 0 | V13: =U13 -> 0 | W13: =V13*IF($B13="Подзем.",$V$18,$V$19) -> 0
A14: 8.2.6 | B14: Надзем. | C14: Коммерч. помещения надзем. | D14: =G28+G29+G30 -> 0 | E14: 0.5 | F14: 0.5 | G14: =E14+F14 -> 1 | H14: 0.3 | I14: 0.69 | J14: 0.01 | K14: =SUM(H14:J14) -> 1 | L14: 0.2 | M14: 0.6 | N14: 0.2 | O14: 0 | P14: =SUM(L14:O14) -> 1 | S14: =IF(OR(Q14="",R14=""),0,R14-Q14) -> 0 | T14: =S14*D14 -> 0 | U14: =IFERROR(T14/SUMIF($B$3:$B$15,$B14,$T$3:$T$15),0) -> 0 | V14: =U14 -> 0 | W14: =V14*IF($B14="Подзем.",$V$18,$V$19) -> 0
A15: 8.2.7 | B15: Надзем. | C15: Паркинг и рампы надзем. | D15: =H28+H29+H30 -> 0 | E15: 0.5 | F15: 0.5 | G15: =E15+F15 -> 1 | H15: 0.3 | I15: 0.69 | J15: 0.01 | K15: =SUM(H15:J15) -> 1 | L15: 0.2 | M15: 0.6 | N15: 0.2 | O15: 0 | P15: =SUM(L15:O15) -> 1 | S15: =IF(OR(Q15="",R15=""),0,R15-Q15) -> 0 | T15: =S15*D15 -> 0 | U15: =IFERROR(T15/SUMIF($B$3:$B$15,$B15,$T$3:$T$15),0) -> 0 | V15: =U15 -> 0 | W15: =V15*IF($B15="Подзем.",$V$18,$V$19) -> 0
A17: АГРЕГАЦИЯ ПО УРОВНЯМ (ур.3 → ур.2 → ур.1)
A18: 8.1 | C18: Подземная часть | D18: =SUM(D3:D8) -> 0 | Q18: =MIN(Q3:Q8) -> 0 | R18: =MAX(R3:R8) -> 0 | S18: =IF(OR(Q18=0,R18=0),0,R18-Q18) -> 0 | T18: =SUM(T3:T8) -> 0 | U18: =IFERROR(T18/(T18+T19),0) -> 0 | V18: =U18 -> 0 | W18: =V18 -> 0
A19: 8.2 | C19: Надземная часть | D19: =SUM(D9:D15) -> 0 | Q19: =MIN(Q9:Q15) -> 0 | R19: =MAX(R9:R15) -> 0 | S19: =IF(OR(Q19=0,R19=0),0,R19-Q19) -> 0 | T19: =SUM(T9:T15) -> 0 | U19: =IFERROR(T19/(T18+T19),0) -> 0 | V19: =U19 -> 0 | W19: =V19 -> 0
C21: ✓ ∑ вес ур.3 подзем. | V21: =SUM(V3:V8) -> 0
C22: ✓ ∑ вес ур.3 надзем. | V22: =SUM(V9:V15) -> 0
C23: ✓ ∑ вес ур.2 | V23: =V18+V19 -> 0
C24: ✓ ∑ глоб. вес | W24: =SUM(W3:W15) -> 0
A26: РАСПРЕДЕЛЕНИЕ НАДЗЕМНОЙ ЧАСТИ ПО КОРПУСАМ
A27: Корпус | B27: 8.2.1 | C27: 8.2.2 | D27: 8.2.3 | E27: 8.2.4 | F27: 8.2.5 | G27: 8.2.6 | H27: 8.2.7 | I27: Σ план | J27: Вес корп.(авто) | K27: Вес корп.
A28: К1 | B28: 0 | C28: 0 | D28: 0 | E28: 0 | F28: 0 | G28: 0 | H28: 0 | I28: =SUM(B28:H28) -> 0 | J28: =IFERROR(I28/(I28+I29+I30),0) -> 0 | K28: =J28 -> 0
A29: К2 | B29: 0 | C29: 0 | D29: 0 | E29: 0 | F29: 0 | G29: 0 | H29: 0 | I29: =SUM(B29:H29) -> 0 | J29: =IFERROR(I29/(I28+I29+I30),0) -> 0 | K29: =J29 -> 0
A30: К3 | B30: 0 | C30: 0 | D30: 0 | E30: 0 | F30: 0 | G30: 0 | H30: 0 | I30: =SUM(B30:H30) -> 0 | J30: =IFERROR(I30/(I28+I29+I30),0) -> 0 | K30: =J30 -> 0
A32: ✓ ∑ вес корп. | K32: =K28+K29+K30 -> 0
A35: Дата начала проекта | B35: 46174

Sheet ВВОД ПОДЗЕМ
A1: ВВОД ДАННЫХ — ВВОД ПОДЗЕМ
A2: Вводите м². Серые столбцы A-D не редактируйте.
A3: Дата | B3: Тип | C3: Код | D3: Категория | E3: Пол | F3: Стены | G3: Потолок | H3: Мебл. | I3: ✓
A4: =СПРАВОЧНИК!$B$35 -> 46174 | B4: Черновая | C4: 8.1.1 | D4: Отделка паркинг и рампы | I4: =COUNTA(E4:G4)&"/3" -> 0/3
A5: =A4 -> 46174 | B5: Черновая | C5: 8.1.2 | D5: Отделка эвакуац. лестн. клетки подзем. | I5: =COUNTA(E5:G5)&"/3" -> 0/3
A6: =A4 -> 46174 | B6: Черновая | C6: 8.1.3 | D6: Лифт. холлы, тамбур-шлюзы подзем. | I6: =COUNTA(E6:G6)&"/3" -> 0/3
A7: =A4 -> 46174 | B7: Черновая | C7: 8.1.4 | D7: Технич. помещения подзем. | I7: =COUNTA(E7:G7)&"/3" -> 0/3
A8: =A4 -> 46174 | B8: Черновая | C8: 8.1.5 | D8: Прочие помещения подзем. | I8: =COUNTA(E8:G8)&"/3" -> 0/3
A9: =A4 -> 46174 | B9: Черновая | C9: 8.1.6 | D9: Коммерч. помещения подзем. | I9: =COUNTA(E9:G9)&"/3" -> 0/3
A10: =A4 -> 46174 | B10: Чистовая | C10: 8.1.1 | D10: Отделка паркинг и рампы | I10: =COUNTA(E10:G10)&"/3" -> 0/3
A11: =A4 -> 46174 | B11: Чистовая | C11: 8.1.2 | D11: Отделка эвакуац. лестн. клетки подзем. | I11: =COUNTA(E11:G11)&"/3" -> 0/3
A12: =A4 -> 46174 | B12: Чистовая | C12: 8.1.3 | D12: Лифт. холлы, тамбур-шлюзы подзем. | I12: =COUNTA(E12:G12)&"/3" -> 0/3
A13: =A4 -> 46174 | B13: Чистовая | C13: 8.1.4 | D13: Технич. помещения подзем. | I13: =COUNTA(E13:G13)&"/3" -> 0/3
A14: =A4 -> 46174 | B14: Чистовая | C14: 8.1.5 | D14: Прочие помещения подзем. | I14: =COUNTA(E14:G14)&"/3" -> 0/3
A15: =A4 -> 46174 | B15: Чистовая | C15: 8.1.6 | D15: Коммерч. помещения подзем. | I15: =COUNTA(E15:G15)&"/3" -> 0/3
A16: =A4+7 -> 46181 | B16: Черновая | C16: 8.1.1 | D16: Отделка паркинг и рампы | I16: =COUNTA(E16:G16)&"/3" -> 0/3
A17: =A16 -> 46181 | B17: Черновая | C17: 8.1.2 | D17: Отделка эвакуац. лестн. клетки подзем. | I17: =COUNTA(E17:G17)&"/3" -> 0/3
A18: =A16 -> 46181 | B18: Черновая | C18: 8.1.3 | D18: Лифт. холлы, тамбур-шлюзы подзем. | I18: =COUNTA(E18:G18)&"/3" -> 0/3
A19: =A16 -> 46181 | B19: Черновая | C19: 8.1.4 | D19: Технич. помещения подзем. | I19: =COUNTA(E19:G19)&"/3" -> 0/3
A20: =A16 -> 46181 | B20: Черновая | C20: 8.1.5 | D20: Прочие помещения подзем. | I20: =COUNTA(E20:G20)&"/3" -> 0/3
A21: =A16 -> 46181 | B21: Черновая | C21: 8.1.6 | D21: Коммерч. помещения подзем. | I21: =COUNTA(E21:G21)&"/3" -> 0/3
A22: =A16 -> 46181 | B22: Чистовая | C22: 8.1.1 | D22: Отделка паркинг и рампы | I22: =COUNTA(E22:G22)&"/3" -> 0/3
A23: =A16 -> 46181 | B23: Чистовая | C23: 8.1.2 | D23: Отделка эвакуац. лестн. клетки подзем. | I23: =COUNTA(E23:G23)&"/3" -> 0/3
A24: =A16 -> 46181 | B24: Чистовая | C24: 8.1.3 | D24: Лифт. холлы, тамбур-шлюзы подзем. | I24: =COUNTA(E24:G24)&"/3" -> 0/3
A25: =A16 -> 46181 | B25: Чистовая | C25: 8.1.4 | D25: Технич. помещения подзем. | I25: =COUNTA(E25:G25)&"/3" -> 0/3
A26: =A16 -> 46181 | B26: Чистовая | C26: 8.1.5 | D26: Прочие помещения подзем. | I26: =COUNTA(E26:G26)&"/3" -> 0/3
A27: =A16 -> 46181 | B27: Чистовая | C27: 8.1.6 | D27: Коммерч. помещения подзем. | I27: =COUNTA(E27:G27)&"/3" -> 0/3
A28: =A16+7 -> 46188 | B28: Черновая | C28: 8.1.1 | D28: Отделка паркинг и рампы | I28: =COUNTA(E28:G28)&"/3" -> 0/3
A29: =A28 -> 46188 | B29: Черновая | C29: 8.1.2 | D29: Отделка эвакуац. лестн. клетки подзем. | I29: =COUNTA(E29:G29)&"/3" -> 0/3
A30: =A28 -> 46188 | B30: Черновая | C30: 8.1.3 | D30: Лифт. холлы, тамбур-шлюзы подзем. | I30: =COUNTA(E30:G30)&"/3" -> 0/3
A31: =A28 -> 46188 | B31: Черновая | C31: 8.1.4 | D31: Технич. помещения подзем. | I31: =COUNTA(E31:G31)&"/3" -> 0/3
A32: =A28 -> 46188 | B32: Черновая | C32: 8.1.5 | D32: Прочие помещения подзем. | I32: =COUNTA(E32:G32)&"/3" -> 0/3
A33: =A28 -> 46188 | B33: Черновая | C33: 8.1.6 | D33: Коммерч. помещения подзем. | I33: =COUNTA(E33:G33)&"/3" -> 0/3
A34: =A28 -> 46188 | B34: Чистовая | C34: 8.1.1 | D34: Отделка паркинг и рампы | I34: =COUNTA(E34:G34)&"/3" -> 0/3
A35: =A28 -> 46188 | B35: Чистовая | C35: 8.1.2 | D35: Отделка эвакуац. лестн. клетки подзем. | I35: =COUNTA(E35:G35)&"/3" -> 0/3
A36: =A28 -> 46188 | B36: Чистовая | C36: 8.1.3 | D36: Лифт. холлы, тамбур-шлюзы подзем. | I36: =COUNTA(E36:G36)&"/3" -> 0/3
A37: =A28 -> 46188 | B37: Чистовая | C37: 8.1.4 | D37: Технич. помещения подзем. | I37: =COUNTA(E37:G37)&"/3" -> 0/3
A38: =A28 -> 46188 | B38: Чистовая | C38: 8.1.5 | D38: Прочие помещения подзем. | I38: =COUNTA(E38:G38)&"/3" -> 0/3
A39: =A28 -> 46188 | B39: Чистовая | C39: 8.1.6 | D39: Коммерч. помещения подзем. | I39: =COUNTA(E39:G39)&"/3" -> 0/3
A40: =A28+7 -> 46195 | B40: Черновая | C40: 8.1.1 | D40: Отделка паркинг и рампы | I40: =COUNTA(E40:G40)&"/3" -> 0/3
...

Sheet ВВОД К1
A1: ВВОД ДАННЫХ — ВВОД К1
A2: Вводите м². Серые столбцы A-D не редактируйте.
A3: Дата | B3: Тип | C3: Код | D3: Категория | E3: Пол | F3: Стены | G3: Потолок | H3: Мебл. | I3: ✓
A4: =СПРАВОЧНИК!$B$35 -> 46174 | B4: Черновая | C4: 8.2.1 | D4: Отделка лобби/гранд-лобби | I4: =COUNTA(E4:G4)&"/3" -> 0/3
A5: =A4 -> 46174 | B5: Черновая | C5: 8.2.2 | D5: Отделка эвакуац. лестн. клетки надзем. | I5: =COUNTA(E5:G5)&"/3" -> 0/3
A6: =A4 -> 46174 | B6: Черновая | C6: 8.2.3 | D6: Лифт. холлы, тамбур-шлюзы надзем. | I6: =COUNTA(E6:G6)&"/3" -> 0/3
A7: =A4 -> 46174 | B7: Черновая | C7: 8.2.4 | D7: Технич. помещения надзем. | I7: =COUNTA(E7:G7)&"/3" -> 0/3
A8: =A4 -> 46174 | B8: Черновая | C8: 8.2.5 | D8: Прочие помещения надзем. | I8: =COUNTA(E8:G8)&"/3" -> 0/3
A9: =A4 -> 46174 | B9: Черновая | C9: 8.2.6 | D9: Коммерч. помещения надзем. | I9: =COUNTA(E9:G9)&"/3" -> 0/3
A10: =A4 -> 46174 | B10: Черновая | C10: 8.2.7 | D10: Паркинг и рампы надзем. | I10: =COUNTA(E10:G10)&"/3" -> 0/3
A11: =A4 -> 46174 | B11: Чистовая | C11: 8.2.1 | D11: Отделка лобби/гранд-лобби | I11: =COUNTA(E11:H11)&"/4" -> 0/4
A12: =A4 -> 46174 | B12: Чистовая | C12: 8.2.2 | D12: Отделка эвакуац. лестн. клетки надзем. | I12: =COUNTA(E12:G12)&"/3" -> 0/3
A13: =A4 -> 46174 | B13: Чистовая | C13: 8.2.3 | D13: Лифт. холлы, тамбур-шлюзы надзем. | I13: =COUNTA(E13:G13)&"/3" -> 0/3
A14: =A4 -> 46174 | B14: Чистовая | C14: 8.2.4 | D14: Технич. помещения надзем. | I14: =COUNTA(E14:G14)&"/3" -> 0/3
A15: =A4 -> 46174 | B15: Чистовая | C15: 8.2.5 | D15: Прочие помещения надзем. | I15: =COUNTA(E15:G15)&"/3" -> 0/3
A16: =A4 -> 46174 | B16: Чистовая | C16: 8.2.6 | D16: Коммерч. помещения надзем. | I16: =COUNTA(E16:G16)&"/3" -> 0/3
A17: =A4 -> 46174 | B17: Чистовая | C17: 8.2.7 | D17: Паркинг и рампы надзем. | I17: =COUNTA(E17:G17)&"/3" -> 0/3
A18: =A4+7 -> 46181 | B18: Черновая | C18: 8.2.1 | D18: Отделка лобби/гранд-лобби | I18: =COUNTA(E18:G18)&"/3" -> 0/3
A19: =A18 -> 46181 | B19: Черновая | C19: 8.2.2 | D19: Отделка эвакуац. лестн. клетки надзем. | I19: =COUNTA(E19:G19)&"/3" -> 0/3
A20: =A18 -> 46181 | B20: Черновая | C20: 8.2.3 | D20: Лифт. холлы, тамбур-шлюзы надзем. | I20: =COUNTA(E20:G20)&"/3" -> 0/3
A21: =A18 -> 46181 | B21: Черновая | C21: 8.2.4 | D21: Технич. помещения надзем. | I21: =COUNTA(E21:G21)&"/3" -> 0/3
A22: =A18 -> 46181 | B22: Черновая | C22: 8.2.5 | D22: Прочие помещения надзем. | I22: =COUNTA(E22:G22)&"/3" -> 0/3
A23: =A18 -> 46181 | B23: Черновая | C23: 8.2.6 | D23: Коммерч. помещения надзем. | I23: =COUNTA(E23:G23)&"/3" -> 0/3
A24: =A18 -> 46181 | B24: Черновая | C24: 8.2.7 | D24: Паркинг и рампы надзем. | I24: =COUNTA(E24:G24)&"/3" -> 0/3
A25: =A18 -> 46181 | B25: Чистовая | C25: 8.2.1 | D25: Отделка лобби/гранд-лобби | I25: =COUNTA(E25:H25)&"/4" -> 0/4
A26: =A18 -> 46181 | B26: Чистовая | C26: 8.2.2 | D26: Отделка эвакуац. лестн. клетки надзем. | I26: =COUNTA(E26:G26)&"/3" -> 0/3
A27: =A18 -> 46181 | B27: Чистовая | C27: 8.2.3 | D27: Лифт. холлы, тамбур-шлюзы надзем. | I27: =COUNTA(E27:G27)&"/3" -> 0/3
A28: =A18 -> 46181 | B28: Чистовая | C28: 8.2.4 | D28: Технич. помещения надзем. | I28: =COUNTA(E28:G28)&"/3" -> 0/3
A29: =A18 -> 46181 | B29: Чистовая | C29: 8.2.5 | D29: Прочие помещения надзем. | I29: =COUNTA(E29:G29)&"/3" -> 0/3
A30: =A18 -> 46181 | B30: Чистовая | C30: 8.2.6 | D30: Коммерч. помещения надзем. | I30: =COUNTA(E30:G30)&"/3" -> 0/3
A31: =A18 -> 46181 | B31: Чистовая | C31: 8.2.7 | D31: Паркинг и рампы надзем. | I31: =COUNTA(E31:G31)&"/3" -> 0/3
A32: =A18+7 -> 46188 | B32: Черновая | C32: 8.2.1 | D32: Отделка лобби/гранд-лобби | I32: =COUNTA(E32:G32)&"/3" -> 0/3
A33: =A32 -> 46188 | B33: Черновая | C33: 8.2.2 | D33: Отделка эвакуац. лестн. клетки надзем. | I33: =COUNTA(E33:G33)&"/3" -> 0/3
A34: =A32 -> 46188 | B34: Черновая | C34: 8.2.3 | D34: Лифт. холлы, тамбур-шлюзы надзем. | I34: =COUNTA(E34:G34)&"/3" -> 0/3
A35: =A32 -> 46188 | B35: Черновая | C35: 8.2.4 | D35: Технич. помещения надзем. | I35: =COUNTA(E35:G35)&"/3" -> 0/3
A36: =A32 -> 46188 | B36: Черновая | C36: 8.2.5 | D36: Прочие помещения надзем. | I36: =COUNTA(E36:G36)&"/3" -> 0/3
A37: =A32 -> 46188 | B37: Черновая | C37: 8.2.6 | D37: Коммерч. помещения надзем. | I37: =COUNTA(E37:G37)&"/3" -> 0/3
A38: =A32 -> 46188 | B38: Черновая | C38: 8.2.7 | D38: Паркинг и рампы надзем. | I38: =COUNTA(E38:G38)&"/3" -> 0/3
A39: =A32 -> 46188 | B39: Чистовая | C39: 8.2.1 | D39: Отделка лобби/гранд-лобби | I39: =COUNTA(E39:H39)&"/4" -> 0/4
A40: =A32 -> 46188 | B40: Чистовая | C40: 8.2.2 | D40: Отделка эвакуац. лестн. клетки надзем. | I40: =COUNTA(E40:G40)&"/3" -> 0/3
...

Sheet ВВОД К2
A1: ВВОД ДАННЫХ — ВВОД К2
A2: Вводите м². Серые столбцы A-D не редактируйте.
A3: Дата | B3: Тип | C3: Код | D3: Категория | E3: Пол | F3: Стены | G3: Потолок | H3: Мебл. | I3: ✓
A4: =СПРАВОЧНИК!$B$35 -> 46174 | B4: Черновая | C4: 8.2.1 | D4: Отделка лобби/гранд-лобби | I4: =COUNTA(E4:G4)&"/3" -> 0/3
A5: =A4 -> 46174 | B5: Черновая | C5: 8.2.2 | D5: Отделка эвакуац. лестн. клетки надзем. | I5: =COUNTA(E5:G5)&"/3" -> 0/3
A6: =A4 -> 46174 | B6: Черновая | C6: 8.2.3 | D6: Лифт. холлы, тамбур-шлюзы надзем. | I6: =COUNTA(E6:G6)&"/3" -> 0/3
A7: =A4 -> 46174 | B7: Черновая | C7: 8.2.4 | D7: Технич. помещения надзем. | I7: =COUNTA(E7:G7)&"/3" -> 0/3
A8: =A4 -> 46174 | B8: Черновая | C8: 8.2.5 | D8: Прочие помещения надзем. | I8: =COUNTA(E8:G8)&"/3" -> 0/3
A9: =A4 -> 46174 | B9: Черновая | C9: 8.2.6 | D9: Коммерч. помещения надзем. | I9: =COUNTA(E9:G9)&"/3" -> 0/3
A10: =A4 -> 46174 | B10: Черновая | C10: 8.2.7 | D10: Паркинг и рампы надзем. | I10: =COUNTA(E10:G10)&"/3" -> 0/3
A11: =A4 -> 46174 | B11: Чистовая | C11: 8.2.1 | D11: Отделка лобби/гранд-лобби | I11: =COUNTA(E11:H11)&"/4" -> 0/4
A12: =A4 -> 46174 | B12: Чистовая | C12: 8.2.2 | D12: Отделка эвакуац. лестн. клетки надзем. | I12: =COUNTA(E12:G12)&"/3" -> 0/3
A13: =A4 -> 46174 | B13: Чистовая | C13: 8.2.3 | D13: Лифт. холлы, тамбур-шлюзы надзем. | I13: =COUNTA(E13:G13)&"/3" -> 0/3
A14: =A4 -> 46174 | B14: Чистовая | C14: 8.2.4 | D14: Технич. помещения надзем. | I14: =COUNTA(E14:G14)&"/3" -> 0/3
A15: =A4 -> 46174 | B15: Чистовая | C15: 8.2.5 | D15: Прочие помещения надзем. | I15: =COUNTA(E15:G15)&"/3" -> 0/3
A16: =A4 -> 46174 | B16: Чистовая | C16: 8.2.6 | D16: Коммерч. помещения надзем. | I16: =COUNTA(E16:G16)&"/3" -> 0/3
A17: =A4 -> 46174 | B17: Чистовая | C17: 8.2.7 | D17: Паркинг и рампы надзем. | I17: =COUNTA(E17:G17)&"/3" -> 0/3
A18: =A4+7 -> 46181 | B18: Черновая | C18: 8.2.1 | D18: Отделка лобби/гранд-лобби | I18: =COUNTA(E18:G18)&"/3" -> 0/3
A19: =A18 -> 46181 | B19: Черновая | C19: 8.2.2 | D19: Отделка эвакуац. лестн. клетки надзем. | I19: =COUNTA(E19:G19)&"/3" -> 0/3
A20: =A18 -> 46181 | B20: Черновая | C20: 8.2.3 | D20: Лифт. холлы, тамбур-шлюзы надзем. | I20: =COUNTA(E20:G20)&"/3" -> 0/3
A21: =A18 -> 46181 | B21: Черновая | C21: 8.2.4 | D21: Технич. помещения надзем. | I21: =COUNTA(E21:G21)&"/3" -> 0/3
A22: =A18 -> 46181 | B22: Черновая | C22: 8.2.5 | D22: Прочие помещения надзем. | I22: =COUNTA(E22:G22)&"/3" -> 0/3
A23: =A18 -> 46181 | B23: Черновая | C23: 8.2.6 | D23: Коммерч. помещения надзем. | I23: =COUNTA(E23:G23)&"/3" -> 0/3
A24: =A18 -> 46181 | B24: Черновая | C24: 8.2.7 | D24: Паркинг и рампы надзем. | I24: =COUNTA(E24:G24)&"/3" -> 0/3
A25: =A18 -> 46181 | B25: Чистовая | C25: 8.2.1 | D25: Отделка лобби/гранд-лобби | I25: =COUNTA(E25:H25)&"/4" -> 0/4
A26: =A18 -> 46181 | B26: Чистовая | C26: 8.2.2 | D26: Отделка эвакуац. лестн. клетки надзем. | I26: =COUNTA(E26:G26)&"/3" -> 0/3
A27: =A18 -> 46181 | B27: Чистовая | C27: 8.2.3 | D27: Лифт. холлы, тамбур-шлюзы надзем. | I27: =COUNTA(E27:G27)&"/3" -> 0/3
A28: =A18 -> 46181 | B28: Чистовая | C28: 8.2.4 | D28: Технич. помещения надзем. | I28: =COUNTA(E28:G28)&"/3" -> 0/3
A29: =A18 -> 46181 | B29: Чистовая | C29: 8.2.5 | D29: Прочие помещения надзем. | I29: =COUNTA(E29:G29)&"/3" -> 0/3
A30: =A18 -> 46181 | B30: Чистовая | C30: 8.2.6 | D30: Коммерч. помещения надзем. | I30: =COUNTA(E30:G30)&"/3" -> 0/3
A31: =A18 -> 46181 | B31: Чистовая | C31: 8.2.7 | D31: Паркинг и рампы надзем. | I31: =COUNTA(E31:G31)&"/3" -> 0/3
A32: =A18+7 -> 46188 | B32: Черновая | C32: 8.2.1 | D32: Отделка лобби/гранд-лобби | I32: =COUNTA(E32:G32)&"/3" -> 0/3
A33: =A32 -> 46188 | B33: Черновая | C33: 8.2.2 | D33: Отделка эвакуац. лестн. клетки надзем. | I33: =COUNTA(E33:G33)&"/3" -> 0/3
A34: =A32 -> 46188 | B34: Черновая | C34: 8.2.3 | D34: Лифт. холлы, тамбур-шлюзы надзем. | I34: =COUNTA(E34:G34)&"/3" -> 0/3
A35: =A32 -> 46188 | B35: Черновая | C35: 8.2.4 | D35: Технич. помещения надзем. | I35: =COUNTA(E35:G35)&"/3" -> 0/3
A36: =A32 -> 46188 | B36: Черновая | C36: 8.2.5 | D36: Прочие помещения надзем. | I36: =COUNTA(E36:G36)&"/3" -> 0/3
A37: =A32 -> 46188 | B37: Черновая | C37: 8.2.6 | D37: Коммерч. помещения надзем. | I37: =COUNTA(E37:G37)&"/3" -> 0/3
A38: =A32 -> 46188 | B38: Черновая | C38: 8.2.7 | D38: Паркинг и рампы надзем. | I38: =COUNTA(E38:G38)&"/3" -> 0/3
A39: =A32 -> 46188 | B39: Чистовая | C39: 8.2.1 | D39: Отделка лобби/гранд-лобби | I39: =COUNTA(E39:H39)&"/4" -> 0/4
A40: =A32 -> 46188 | B40: Чистовая | C40: 8.2.2 | D40: Отделка эвакуац. лестн. клетки надзем. | I40: =COUNTA(E40:G40)&"/3" -> 0/3
...

Sheet ВВОД К3
A1: ВВОД ДАННЫХ — ВВОД К3
A2: Вводите м². Серые столбцы A-D не редактируйте.
A3: Дата | B3: Тип | C3: Код | D3: Категория | E3: Пол | F3: Стены | G3: Потолок | H3: Мебл. | I3: ✓
A4: =СПРАВОЧНИК!$B$35 -> 46174 | B4: Черновая | C4: 8.2.1 | D4: Отделка лобби/гранд-лобби | I4: =COUNTA(E4:G4)&"/3" -> 0/3
A5: =A4 -> 46174 | B5: Черновая | C5: 8.2.2 | D5: Отделка эвакуац. лестн. клетки надзем. | I5: =COUNTA(E5:G5)&"/3" -> 0/3
A6: =A4 -> 46174 | B6: Черновая | C6: 8.2.3 | D6: Лифт. холлы, тамбур-шлюзы надзем. | I6: =COUNTA(E6:G6)&"/3" -> 0/3
A7: =A4 -> 46174 | B7: Черновая | C7: 8.2.4 | D7: Технич. помещения надзем. | I7: =COUNTA(E7:G7)&"/3" -> 0/3
A8: =A4 -> 46174 | B8: Черновая | C8: 8.2.5 | D8: Прочие помещения надзем. | I8: =COUNTA(E8:G8)&"/3" -> 0/3
A9: =A4 -> 46174 | B9: Черновая | C9: 8.2.6 | D9: Коммерч. помещения надзем. | I9: =COUNTA(E9:G9)&"/3" -> 0/3
A10: =A4 -> 46174 | B10: Черновая | C10: 8.2.7 | D10: Паркинг и рампы надзем. | I10: =COUNTA(E10:G10)&"/3" -> 0/3
A11: =A4 -> 46174 | B11: Чистовая | C11: 8.2.1 | D11: Отделка лобби/гранд-лобби | I11: =COUNTA(E11:H11)&"/4" -> 0/4
A12: =A4 -> 46174 | B12: Чистовая | C12: 8.2.2 | D12: Отделка эвакуац. лестн. клетки надзем. | I12: =COUNTA(E12:G12)&"/3" -> 0/3
A13: =A4 -> 46174 | B13: Чистовая | C13: 8.2.3 | D13: Лифт. холлы, тамбур-шлюзы надзем. | I13: =COUNTA(E13:G13)&"/3" -> 0/3
A14: =A4 -> 46174 | B14: Чистовая | C14: 8.2.4 | D14: Технич. помещения надзем. | I14: =COUNTA(E14:G14)&"/3" -> 0/3
A15: =A4 -> 46174 | B15: Чистовая | C15: 8.2.5 | D15: Прочие помещения надзем. | I15: =COUNTA(E15:G15)&"/3" -> 0/3
A16: =A4 -> 46174 | B16: Чистовая | C16: 8.2.6 | D16: Коммерч. помещения надзем. | I16: =COUNTA(E16:G16)&"/3" -> 0/3
A17: =A4 -> 46174 | B17: Чистовая | C17: 8.2.7 | D17: Паркинг и рампы надзем. | I17: =COUNTA(E17:G17)&"/3" -> 0/3
A18: =A4+7 -> 46181 | B18: Черновая | C18: 8.2.1 | D18: Отделка лобби/гранд-лобби | I18: =COUNTA(E18:G18)&"/3" -> 0/3
A19: =A18 -> 46181 | B19: Черновая | C19: 8.2.2 | D19: Отделка эвакуац. лестн. клетки надзем. | I19: =COUNTA(E19:G19)&"/3" -> 0/3
A20: =A18 -> 46181 | B20: Черновая | C20: 8.2.3 | D20: Лифт. холлы, тамбур-шлюзы надзем. | I20: =COUNTA(E20:G20)&"/3" -> 0/3
A21: =A18 -> 46181 | B21: Черновая | C21: 8.2.4 | D21: Технич. помещения надзем. | I21: =COUNTA(E21:G21)&"/3" -> 0/3
A22: =A18 -> 46181 | B22: Черновая | C22: 8.2.5 | D22: Прочие помещения надзем. | I22: =COUNTA(E22:G22)&"/3" -> 0/3
A23: =A18 -> 46181 | B23: Черновая | C23: 8.2.6 | D23: Коммерч. помещения надзем. | I23: =COUNTA(E23:G23)&"/3" -> 0/3
A24: =A18 -> 46181 | B24: Черновая | C24: 8.2.7 | D24: Паркинг и рампы надзем. | I24: =COUNTA(E24:G24)&"/3" -> 0/3
A25: =A18 -> 46181 | B25: Чистовая | C25: 8.2.1 | D25: Отделка лобби/гранд-лобби | I25: =COUNTA(E25:H25)&"/4" -> 0/4
A26: =A18 -> 46181 | B26: Чистовая | C26: 8.2.2 | D26: Отделка эвакуац. лестн. клетки надзем. | I26: =COUNTA(E26:G26)&"/3" -> 0/3
A27: =A18 -> 46181 | B27: Чистовая | C27: 8.2.3 | D27: Лифт. холлы, тамбур-шлюзы надзем. | I27: =COUNTA(E27:G27)&"/3" -> 0/3
A28: =A18 -> 46181 | B28: Чистовая | C28: 8.2.4 | D28: Технич. помещения надзем. | I28: =COUNTA(E28:G28)&"/3" -> 0/3
A29: =A18 -> 46181 | B29: Чистовая | C29: 8.2.5 | D29: Прочие помещения надзем. | I29: =COUNTA(E29:G29)&"/3" -> 0/3
A30: =A18 -> 46181 | B30: Чистовая | C30: 8.2.6 | D30: Коммерч. помещения надзем. | I30: =COUNTA(E30:G30)&"/3" -> 0/3
A31: =A18 -> 46181 | B31: Чистовая | C31: 8.2.7 | D31: Паркинг и рампы надзем. | I31: =COUNTA(E31:G31)&"/3" -> 0/3
A32: =A18+7 -> 46188 | B32: Черновая | C32: 8.2.1 | D32: Отделка лобби/гранд-лобби | I32: =COUNTA(E32:G32)&"/3" -> 0/3
A33: =A32 -> 46188 | B33: Черновая | C33: 8.2.2 | D33: Отделка эвакуац. лестн. клетки надзем. | I33: =COUNTA(E33:G33)&"/3" -> 0/3
A34: =A32 -> 46188 | B34: Черновая | C34: 8.2.3 | D34: Лифт. холлы, тамбур-шлюзы надзем. | I34: =COUNTA(E34:G34)&"/3" -> 0/3
A35: =A32 -> 46188 | B35: Черновая | C35: 8.2.4 | D35: Технич. помещения надзем. | I35: =COUNTA(E35:G35)&"/3" -> 0/3
A36: =A32 -> 46188 | B36: Черновая | C36: 8.2.5 | D36: Прочие помещения надзем. | I36: =COUNTA(E36:G36)&"/3" -> 0/3
A37: =A32 -> 46188 | B37: Черновая | C37: 8.2.6 | D37: Коммерч. помещения надзем. | I37: =COUNTA(E37:G37)&"/3" -> 0/3
A38: =A32 -> 46188 | B38: Черновая | C38: 8.2.7 | D38: Паркинг и рампы надзем. | I38: =COUNTA(E38:G38)&"/3" -> 0/3
A39: =A32 -> 46188 | B39: Чистовая | C39: 8.2.1 | D39: Отделка лобби/гранд-лобби | I39: =COUNTA(E39:H39)&"/4" -> 0/4
A40: =A32 -> 46188 | B40: Чистовая | C40: 8.2.2 | D40: Отделка эвакуац. лестн. клетки надзем. | I40: =COUNTA(E40:G40)&"/3" -> 0/3
...

Sheet ПЛАН ЧЕРН ПОДЗЕМ
A1: ПЛАН ЧЕРН ПОДЗЕМ | U1: Итого подзем.
A2: Дата | B2: Подземная часть
B3: 8.1.1 Отделка паркинг и рампы | E3: 8.1.2 Отделка эвакуац. лестн. клетки подзем. | H3: 8.1.3 Лифт. холлы, тамбур-шлюзы подзем. | K3: 8.1.4 Технич. помещения подзем. | N3: 8.1.5 Прочие помещения подзем. | Q3: 8.1.6 Коммерч. помещения подзем. | U3: Пол | V3: Стены | W3: Потолок
B4: Пол | C4: Стены | D4: Потолок | E4: Пол | F4: Стены | G4: Потолок | H4: Пол | I4: Стены | J4: Потолок | K4: Пол | L4: Стены | M4: Потолок | N4: Пол | O4: Стены | P4: Потолок | Q4: Пол | R4: Стены | S4: Потолок
A5: =СПРАВОЧНИК!$B$35 -> 46174 | U5: =B5+E5+H5+K5+N5+Q5 -> 0 | V5: =C5+F5+I5+L5+O5+R5 -> 0 | W5: =D5+G5+J5+M5+P5+S5 -> 0
A6: =A5+7 -> 46181 | U6: =B6+E6+H6+K6+N6+Q6 -> 0 | V6: =C6+F6+I6+L6+O6+R6 -> 0 | W6: =D6+G6+J6+M6+P6+S6 -> 0
A7: =A6+7 -> 46188 | U7: =B7+E7+H7+K7+N7+Q7 -> 0 | V7: =C7+F7+I7+L7+O7+R7 -> 0 | W7: =D7+G7+J7+M7+P7+S7 -> 0
A8: =A7+7 -> 46195 | U8: =B8+E8+H8+K8+N8+Q8 -> 0 | V8: =C8+F8+I8+L8+O8+R8 -> 0 | W8: =D8+G8+J8+M8+P8+S8 -> 0
A9: =A8+7 -> 46202 | U9: =B9+E9+H9+K9+N9+Q9 -> 0 | V9: =C9+F9+I9+L9+O9+R9 -> 0 | W9: =D9+G9+J9+M9+P9+S9 -> 0
A10: =A9+7 -> 46209 | U10: =B10+E10+H10+K10+N10+Q10 -> 0 | V10: =C10+F10+I10+L10+O10+R10 -> 0 | W10: =D10+G10+J10+M10+P10+S10 -> 0
A11: =A10+7 -> 46216 | U11: =B11+E11+H11+K11+N11+Q11 -> 0 | V11: =C11+F11+I11+L11+O11+R11 -> 0 | W11: =D11+G11+J11+M11+P11+S11 -> 0
A12: =A11+7 -> 46223 | U12: =B12+E12+H12+K12+N12+Q12 -> 0 | V12: =C12+F12+I12+L12+O12+R12 -> 0 | W12: =D12+G12+J12+M12+P12+S12 -> 0
A13: =A12+7 -> 46230 | U13: =B13+E13+H13+K13+N13+Q13 -> 0 | V13: =C13+F13+I13+L13+O13+R13 -> 0 | W13: =D13+G13+J13+M13+P13+S13 -> 0
A14: =A13+7 -> 46237 | U14: =B14+E14+H14+K14+N14+Q14 -> 0 | V14: =C14+F14+I14+L14+O14+R14 -> 0 | W14: =D14+G14+J14+M14+P14+S14 -> 0
A15: =A14+7 -> 46244 | U15: =B15+E15+H15+K15+N15+Q15 -> 0 | V15: =C15+F15+I15+L15+O15+R15 -> 0 | W15: =D15+G15+J15+M15+P15+S15 -> 0
A16: =A15+7 -> 46251 | U16: =B16+E16+H16+K16+N16+Q16 -> 0 | V16: =C16+F16+I16+L16+O16+R16 -> 0 | W16: =D16+G16+J16+M16+P16+S16 -> 0
A17: =A16+7 -> 46258 | U17: =B17+E17+H17+K17+N17+Q17 -> 0 | V17: =C17+F17+I17+L17+O17+R17 -> 0 | W17: =D17+G17+J17+M17+P17+S17 -> 0
... A52: =A51+7 -> 46503 | U52: =B52+E52+H52+K52+N52+Q52 -> 0 | V52: =C52+F52+I52+L52+O52+R52 -> 0 | W52: =D52+G52+J52+M52+P52+S52 -> 0

Sheet ПЛАН ЧИСТ ПОДЗЕМ
A1: ПЛАН ЧИСТ ПОДЗЕМ | U1: Итого подзем.
A2: Дата | B2: Подземная часть
B3: 8.1.1 Отделка паркинг и рампы | E3: 8.1.2 Отделка эвакуац. лестн. клетки подзем. | H3: 8.1.3 Лифт. холлы, тамбур-шлюзы подзем. | K3: 8.1.4 Технич. помещения подзем. | N3: 8.1.5 Прочие помещения подзем. | Q3: 8.1.6 Коммерч. помещения подзем. | U3: Пол | V3: Стены | W3: Потолок
B4: Пол | C4: Стены | D4: Потолок | E4: Пол | F4: Стены | G4: Потолок | H4: Пол | I4: Стены | J4: Потолок | K4: Пол | L4: Стены | M4: Потолок | N4: Пол | O4: Стены | P4: Потолок | Q4: Пол | R4: Стены | S4: Потолок
A5: =СПРАВОЧНИК!$B$35 -> 46174 | U5: =B5+E5+H5+K5+N5+Q5 -> 0 | V5: =C5+F5+I5+L5+O5+R5 -> 0 | W5: =D5+G5+J5+M5+P5+S5 -> 0
A6: =A5+7 -> 46181 | U6: =B6+E6+H6+K6+N6+Q6 -> 0 | V6: =C6+F6+I6+L6+O6+R6 -> 0 | W6: =D6+G6+J6+M6+P6+S6 -> 0
A7: =A6+7 -> 46188 | U7: =B7+E7+H7+K7+N7+Q7 -> 0 | V7: =C7+F7+I7+L7+O7+R7 -> 0 | W7: =D7+G7+J7+M7+P7+S7 -> 0
A8: =A7+7 -> 46195 | U8: =B8+E8+H8+K8+N8+Q8 -> 0 | V8: =C8+F8+I8+L8+O8+R8 -> 0 | W8: =D8+G8+J8+M8+P8+S8 -> 0
A9: =A8+7 -> 46202 | U9: =B9+E9+H9+K9+N9+Q9 -> 0 | V9: =C9+F9+I9+L9+O9+R9 -> 0 | W9: =D9+G9+J9+M9+P9+S9 -> 0
A10: =A9+7 -> 46209 | U10: =B10+E10+H10+K10+N10+Q10 -> 0 | V10: =C10+F10+I10+L10+O10+R10 -> 0 | W10: =D10+G10+J10+M10+P10+S10 -> 0
A11: =A10+7 -> 46216 | U11: =B11+E11+H11+K11+N11+Q11 -> 0 | V11: =C11+F11+I11+L11+O11+R11 -> 0 | W11: =D11+G11+J11+M11+P11+S11 -> 0
A12: =A11+7 -> 46223 | U12: =B12+E12+H12+K12+N12+Q12 -> 0 | V12: =C12+F12+I12+L12+O12+R12 -> 0 | W12: =D12+G12+J12+M12+P12+S12 -> 0
A13: =A12+7 -> 46230 | U13: =B13+E13+H13+K13+N13+Q13 -> 0 | V13: =C13+F13+I13+L13+O13+R13 -> 0 | W13: =D13+G13+J13+M13+P13+S13 -> 0
A14: =A13+7 -> 46237 | U14: =B14+E14+H14+K14+N14+Q14 -> 0 | V14: =C14+F14+I14+L14+O14+R14 -> 0 | W14: =D14+G14+J14+M14+P14+S14 -> 0
A15: =A14+7 -> 46244 | U15: =B15+E15+H15+K15+N15+Q15 -> 0 | V15: =C15+F15+I15+L15+O15+R15 -> 0 | W15: =D15+G15+J15+M15+P15+S15 -> 0
A16: =A15+7 -> 46251 | U16: =B16+E16+H16+K16+N16+Q16 -> 0 | V16: =C16+F16+I16+L16+O16+R16 -> 0 | W16: =D16+G16+J16+M16+P16+S16 -> 0
A17: =A16+7 -> 46258 | U17: =B17+E17+H17+K17+N17+Q17 -> 0 | V17: =C17+F17+I17+L17+O17+R17 -> 0 | W17: =D17+G17+J17+M17+P17+S17 -> 0
... A52: =A51+7 -> 46503 | U52: =B52+E52+H52+K52+N52+Q52 -> 0 | V52: =C52+F52+I52+L52+O52+R52 -> 0 | W52: =D52+G52+J52+M52+P52+S52 -> 0

Sheet ПЛАН ЧЕРН К1
A1: ПЛАН ЧЕРН К1 | X1: Итого К1
A2: Дата | B2: Надземная часть
B3: 8.2.1 Отделка лобби/гранд-лобби | E3: 8.2.2 Отделка эвакуац. лестн. клетки надзем. | H3: 8.2.3 Лифт. холлы, тамбур-шлюзы надзем. | K3: 8.2.4 Технич. помещения надзем. | N3: 8.2.5 Прочие помещения надзем. | Q3: 8.2.6 Коммерч. помещения надзем. | T3: 8.2.7 Паркинг и рампы надзем. | X3: Пол | Y3: Стены | Z3: Потолок
B4: Пол | C4: Стены | D4: Потолок | E4: Пол | F4: Стены | G4: Потолок | H4: Пол | I4: Стены | J4: Потолок | K4: Пол | L4: Стены | M4: Потолок | N4: Пол | O4: Стены | P4: Потолок | Q4: Пол | R4: Стены | S4: Потолок | T4: Пол | U4: Стены | V4: Потолок
A5: =СПРАВОЧНИК!$B$35 -> 46174 | X5: =B5+E5+H5+K5+N5+Q5+T5 -> 0 | Y5: =C5+F5+I5+L5+O5+R5+U5 -> 0 | Z5: =D5+G5+J5+M5+P5+S5+V5 -> 0
A6: =A5+7 -> 46181 | X6: =B6+E6+H6+K6+N6+Q6+T6 -> 0 | Y6: =C6+F6+I6+L6+O6+R6+U6 -> 0 | Z6: =D6+G6+J6+M6+P6+S6+V6 -> 0
A7: =A6+7 -> 46188 | X7: =B7+E7+H7+K7+N7+Q7+T7 -> 0 | Y7: =C7+F7+I7+L7+O7+R7+U7 -> 0 | Z7: =D7+G7+J7+M7+P7+S7+V7 -> 0
A8: =A7+7 -> 46195 | X8: =B8+E8+H8+K8+N8+Q8+T8 -> 0 | Y8: =C8+F8+I8+L8+O8+R8+U8 -> 0 | Z8: =D8+G8+J8+M8+P8+S8+V8 -> 0
A9: =A8+7 -> 46202 | X9: =B9+E9+H9+K9+N9+Q9+T9 -> 0 | Y9: =C9+F9+I9+L9+O9+R9+U9 -> 0 | Z9: =D9+G9+J9+M9+P9+S9+V9 -> 0
A10: =A9+7 -> 46209 | X10: =B10+E10+H10+K10+N10+Q10+T10 -> 0 | Y10: =C10+F10+I10+L10+O10+R10+U10 -> 0 | Z10: =D10+G10+J10+M10+P10+S10+V10 -> 0
A11: =A10+7 -> 46216 | X11: =B11+E11+H11+K11+N11+Q11+T11 -> 0 | Y11: =C11+F11+I11+L11+O11+R11+U11 -> 0 | Z11: =D11+G11+J11+M11+P11+S11+V11 -> 0
A12: =A11+7 -> 46223 | X12: =B12+E12+H12+K12+N12+Q12+T12 -> 0 | Y12: =C12+F12+I12+L12+O12+R12+U12 -> 0 | Z12: =D12+G12+J12+M12+P12+S12+V12 -> 0
A13: =A12+7 -> 46230 | X13: =B13+E13+H13+K13+N13+Q13+T13 -> 0 | Y13: =C13+F13+I13+L13+O13+R13+U13 -> 0 | Z13: =D13+G13+J13+M13+P13+S13+V13 -> 0
A14: =A13+7 -> 46237 | X14: =B14+E14+H14+K14+N14+Q14+T14 -> 0 | Y14: =C14+F14+I14+L14+O14+R14+U14 -> 0 | Z14: =D14+G14+J14+M14+P14+S14+V14 -> 0
A15: =A14+7 -> 46244 | X15: =B15+E15+H15+K15+N15+Q15+T15 -> 0 | Y15: =C15+F15+I15+L15+O15+R15+U15 -> 0 | Z15: =D15+G15+J15+M15+P15+S15+V15 -> 0
A16: =A15+7 -> 46251 | X16: =B16+E16+H16+K16+N16+Q16+T16 -> 0 | Y16: =C16+F16+I16+L16+O16+R16+U16 -> 0 | Z16: =D16+G16+J16+M16+P16+S16+V16 -> 0
A17: =A16+7 -> 46258 | X17: =B17+E17+H17+K17+N17+Q17+T17 -> 0 | Y17: =C17+F17+I17+L17+O17+R17+U17 -> 0 | Z17: =D17+G17+J17+M17+P17+S17+V17 -> 0
... A52: =A51+7 -> 46503 | X52: =B52+E52+H52+K52+N52+Q52+T52 -> 0 | Y52: =C52+F52+I52+L52+O52+R52+U52 -> 0 | Z52: =D52+G52+J52+M52+P52+S52+V52 -> 0

Sheet ПЛАН ЧИСТ К1
A1: ПЛАН ЧИСТ К1 | Y1: Итого К1
A2: Дата | B2: Надземная часть
B3: 8.2.1 Отделка лобби/гранд-лобби | F3: 8.2.2 Отделка эвакуац. лестн. клетки надзем. | I3: 8.2.3 Лифт. холлы, тамбур-шлюзы надзем. | L3: 8.2.4 Технич. помещения надзем. | O3: 8.2.5 Прочие помещения надзем. | R3: 8.2.6 Коммерч. помещения надзем. | U3: 8.2.7 Паркинг и рампы надзем. | Y3: Пол | Z3: Стены | AA3: Потолок
B4: Пол | C4: Стены | D4: Потолок | E4: Мебл. | F4: Пол | G4: Стены | H4: Потолок | I4: Пол | J4: Стены | K4: Потолок | L4: Пол | M4: Стены | N4: Потолок | O4: Пол | P4: Стены | Q4: Потолок | R4: Пол | S4: Стены | T4: Потолок | U4: Пол | V4: Стены | W4: Потолок
A5: =СПРАВОЧНИК!$B$35 -> 46174 | Y5: =B5+F5+I5+L5+O5+R5+U5 -> 0 | Z5: =C5+G5+J5+M5+P5+S5+V5 -> 0 | AA5: =D5+H5+K5+N5+Q5+T5+W5 -> 0
A6: =A5+7 -> 46181 | Y6: =B6+F6+I6+L6+O6+R6+U6 -> 0 | Z6: =C6+G6+J6+M6+P6+S6+V6 -> 0 | AA6: =D6+H6+K6+N6+Q6+T6+W6 -> 0
A7: =A6+7 -> 46188 | Y7: =B7+F7+I7+L7+O7+R7+U7 -> 0 | Z7: =C7+G7+J7+M7+P7+S7+V7 -> 0 | AA7: =D7+H7+K7+N7+Q7+T7+W7 -> 0
A8: =A7+7 -> 46195 | Y8: =B8+F8+I8+L8+O8+R8+U8 -> 0 | Z8: =C8+G8+J8+M8+P8+S8+V8 -> 0 | AA8: =D8+H8+K8+N8+Q8+T8+W8 -> 0
A9: =A8+7 -> 46202 | Y9: =B9+F9+I9+L9+O9+R9+U9 -> 0 | Z9: =C9+G9+J9+M9+P9+S9+V9 -> 0 | AA9: =D9+H9+K9+N9+Q9+T9+W9 -> 0
A10: =A9+7 -> 46209 | Y10: =B10+F10+I10+L10+O10+R10+U10 -> 0 | Z10: =C10+G10+J10+M10+P10+S10+V10 -> 0 | AA10: =D10+H10+K10+N10+Q10+T10+W10 -> 0
A11: =A10+7 -> 46216 | Y11: =B11+F11+I11+L11+O11+R11+U11 -> 0 | Z11: =C11+G11+J11+M11+P11+S11+V11 -> 0 | AA11: =D11+H11+K11+N11+Q11+T11+W11 -> 0
A12: =A11+7 -> 46223 | Y12: =B12+F12+I12+L12+O12+R12+U12 -> 0 | Z12: =C12+G12+J12+M12+P12+S12+V12 -> 0 | AA12: =D12+H12+K12+N12+Q12+T12+W12 -> 0
A13: =A12+7 -> 46230 | Y13: =B13+F13+I13+L13+O13+R13+U13 -> 0 | Z13: =C13+G13+J13+M13+P13+S13+V13 -> 0 | AA13: =D13+H13+K13+N13+Q13+T13+W13 -> 0
A14: =A13+7 -> 46237 | Y14: =B14+F14+I14+L14+O14+R14+U14 -> 0 | Z14: =C14+G14+J14+M14+P14+S14+V14 -> 0 | AA14: =D14+H14+K14+N14+Q14+T14+W14 -> 0
A15: =A14+7 -> 46244 | Y15: =B15+F15+I15+L15+O15+R15+U15 -> 0 | Z15: =C15+G15+J15+M15+P15+S15+V15 -> 0 | AA15: =D15+H15+K15+N15+Q15+T15+W15 -> 0
A16: =A15+7 -> 46251 | Y16: =B16+F16+I16+L16+O16+R16+U16 -> 0 | Z16: =C16+G16+J16+M16+P16+S16+V16 -> 0 | AA16: =D16+H16+K16+N16+Q16+T16+W16 -> 0
A17: =A16+7 -> 46258 | Y17: =B17+F17+I17+L17+O17+R17+U17 -> 0 | Z17: =C17+G17+J17+M17+P17+S17+V17 -> 0 | AA17: =D17+H17+K17+N17+Q17+T17+W17 -> 0
... A52: =A51+7 -> 46503 | Y52: =B52+F52+I52+L52+O52+R52+U52 -> 0 | Z52: =C52+G52+J52+M52+P52+S52+V52 -> 0 | AA52: =D52+H52+K52+N52+Q52+T52+W52 -> 0

Sheet ПЛАН ЧЕРН К2
A1: ПЛАН ЧЕРН К2 | X1: Итого К2
A2: Дата | B2: Надземная часть
B3: 8.2.1 Отделка лобби/гранд-лобби | E3: 8.2.2 Отделка эвакуац. лестн. клетки надзем. | H3: 8.2.3 Лифт. холлы, тамбур-шлюзы надзем. | K3: 8.2.4 Технич. помещения надзем. | N3: 8.2.5 Прочие помещения надзем. | Q3: 8.2.6 Коммерч. помещения надзем. | T3: 8.2.7 Паркинг и рампы надзем. | X3: Пол | Y3: Стены | Z3: Потолок
B4: Пол | C4: Стены | D4: Потолок | E4: Пол | F4: Стены | G4: Потолок | H4: Пол | I4: Стены | J4: Потолок | K4: Пол | L4: Стены | M4: Потолок | N4: Пол | O4: Стены | P4: Потолок | Q4: Пол | R4: Стены | S4: Потолок | T4: Пол | U4: Стены | V4: Потолок
A5: =СПРАВОЧНИК!$B$35 -> 46174 | X5: =B5+E5+H5+K5+N5+Q5+T5 -> 0 | Y5: =C5+F5+I5+L5+O5+R5+U5 -> 0 | Z5: =D5+G5+J5+M5+P5+S5+V5 -> 0
A6: =A5+7 -> 46181 | X6: =B6+E6+H6+K6+N6+Q6+T6 -> 0 | Y6: =C6+F6+I6+L6+O6+R6+U6 -> 0 | Z6: =D6+G6+J6+M6+P6+S6+V6 -> 0
A7: =A6+7 -> 46188 | X7: =B7+E7+H7+K7+N7+Q7+T7 -> 0 | Y7: =C7+F7+I7+L7+O7+R7+U7 -> 0 | Z7: =D7+G7+J7+M7+P7+S7+V7 -> 0
A8: =A7+7 -> 46195 | X8: =B8+E8+H8+K8+N8+Q8+T8 -> 0 | Y8: =C8+F8+I8+L8+O8+R8+U8 -> 0 | Z8: =D8+G8+J8+M8+P8+S8+V8 -> 0
A9: =A8+7 -> 46202 | X9: =B9+E9+H9+K9+N9+Q9+T9 -> 0 | Y9: =C9+F9+I9+L9+O9+R9+U9 -> 0 | Z9: =D9+G9+J9+M9+P9+S9+V9 -> 0
A10: =A9+7 -> 46209 | X10: =B10+E10+H10+K10+N10+Q10+T10 -> 0 | Y10: =C10+F10+I10+L10+O10+R10+U10 -> 0 | Z10: =D10+G10+J10+M10+P10+S10+V10 -> 0
A11: =A10+7 -> 46216 | X11: =B11+E11+H11+K11+N11+Q11+T11 -> 0 | Y11: =C11+F11+I11+L11+O11+R11+U11 -> 0 | Z11: =D11+G11+J11+M11+P11+S11+V11 -> 0
A12: =A11+7 -> 46223 | X12: =B12+E12+H12+K12+N12+Q12+T12 -> 0 | Y12: =C12+F12+I12+L12+O12+R12+U12 -> 0 | Z12: =D12+G12+J12+M12+P12+S12+V12 -> 0
A13: =A12+7 -> 46230 | X13: =B13+E13+H13+K13+N13+Q13+T13 -> 0 | Y13: =C13+F13+I13+L13+O13+R13+U13 -> 0 | Z13: =D13+G13+J13+M13+P13+S13+V13 -> 0
A14: =A13+7 -> 46237 | X14: =B14+E14+H14+K14+N14+Q14+T14 -> 0 | Y14: =C14+F14+I14+L14+O14+R14+U14 -> 0 | Z14: =D14+G14+J14+M14+P14+S14+V14 -> 0
A15: =A14+7 -> 46244 | X15: =B15+E15+H15+K15+N15+Q15+T15 -> 0 | Y15: =C15+F15+I15+L15+O15+R15+U15 -> 0 | Z15: =D15+G15+J15+M15+P15+S15+V15 -> 0
A16: =A15+7 -> 46251 | X16: =B16+E16+H16+K16+N16+Q16+T16 -> 0 | Y16: =C16+F16+I16+L16+O16+R16+U16 -> 0 | Z16: =D16+G16+J16+M16+P16+S16+V16 -> 0
A17: =A16+7 -> 46258 | X17: =B17+E17+H17+K17+N17+Q17+T17 -> 0 | Y17: =C17+F17+I17+L17+O17+R17+U17 -> 0 | Z17: =D17+G17+J17+M17+P17+S17+V17 -> 0
... A52: =A51+7 -> 46503 | X52: =B52+E52+H52+K52+N52+Q52+T52 -> 0 | Y52: =C52+F52+I52+L52+O52+R52+U52 -> 0 | Z52: =D52+G52+J52+M52+P52+S52+V52 -> 0

Sheet ПЛАН ЧИСТ К2
A1: ПЛАН ЧИСТ К2 | Y1: Итого К2
A2: Дата | B2: Надземная часть
B3: 8.2.1 Отделка лобби/гранд-лобби | F3: 8.2.2 Отделка эвакуац. лестн. клетки надзем. | I3: 8.2.3 Лифт. холлы, тамбур-шлюзы надзем. | L3: 8.2.4 Технич. помещения надзем. | O3: 8.2.5 Прочие помещения надзем. | R3: 8.2.6 Коммерч. помещения надзем. | U3: 8.2.7 Паркинг и рампы надзем. | Y3: Пол | Z3: Стены | AA3: Потолок
B4: Пол | C4: Стены | D4: Потолок | E4: Мебл. | F4: Пол | G4: Стены | H4: Потолок | I4: Пол | J4: Стены | K4: Потолок | L4: Пол | M4: Стены | N4: Потолок | O4: Пол | P4: Стены | Q4: Потолок | R4: Пол | S4: Стены | T4: Потолок | U4: Пол | V4: Стены | W4: Потолок
A5: =СПРАВОЧНИК!$B$35 -> 46174 | Y5: =B5+F5+I5+L5+O5+R5+U5 -> 0 | Z5: =C5+G5+J5+M5+P5+S5+V5 -> 0 | AA5: =D5+H5+K5+N5+Q5+T5+W5 -> 0
A6: =A5+7 -> 46181 | Y6: =B6+F6+I6+L6+O6+R6+U6 -> 0 | Z6: =C6+G6+J6+M6+P6+S6+V6 -> 0 | AA6: =D6+H6+K6+N6+Q6+T6+W6 -> 0
A7: =A6+7 -> 46188 | Y7: =B7+F7+I7+L7+O7+R7+U7 -> 0 | Z7: =C7+G7+J7+M7+P7+S7+V7 -> 0 | AA7: =D7+H7+K7+N7+Q7+T7+W7 -> 0
A8: =A7+7 -> 46195 | Y8: =B8+F8+I8+L8+O8+R8+U8 -> 0 | Z8: =C8+G8+J8+M8+P8+S8+V8 -> 0 | AA8: =D8+H8+K8+N8+Q8+T8+W8 -> 0
A9: =A8+7 -> 46202 | Y9: =B9+F9+I9+L9+O9+R9+U9 -> 0 | Z9: =C9+G9+J9+M9+P9+S9+V9 -> 0 | AA9: =D9+H9+K9+N9+Q9+T9+W9 -> 0
A10: =A9+7 -> 46209 | Y10: =B10+F10+I10+L10+O10+R10+U10 -> 0 | Z10: =C10+G10+J10+M10+P10+S10+V10 -> 0 | AA10: =D10+H10+K10+N10+Q10+T10+W10 -> 0
A11: =A10+7 -> 46216 | Y11: =B11+F11+I11+L11+O11+R11+U11 -> 0 | Z11: =C11+G11+J11+M11+P11+S11+V11 -> 0 | AA11: =D11+H11+K11+N11+Q11+T11+W11 -> 0
A12: =A11+7 -> 46223 | Y12: =B12+F12+I12+L12+O12+R12+U12 -> 0 | Z12: =C12+G12+J12+M12+P12+S12+V12 -> 0 | AA12: =D12+H12+K12+N12+Q12+T12+W12 -> 0
A13: =A12+7 -> 46230 | Y13: =B13+F13+I13+L13+O13+R13+U13 -> 0 | Z13: =C13+G13+J13+M13+P13+S13+V13 -> 0 | AA13: =D13+H13+K13+N13+Q13+T13+W13 -> 0
A14: =A13+7 -> 46237 | Y14: =B14+F14+I14+L14+O14+R14+U14 -> 0 | Z14: =C14+G14+J14+M14+P14+S14+V14 -> 0 | AA14: =D14+H14+K14+N14+Q14+T14+W14 -> 0
A15: =A14+7 -> 46244 | Y15: =B15+F15+I15+L15+O15+R15+U15 -> 0 | Z15: =C15+G15+J15+M15+P15+S15+V15 -> 0 | AA15: =D15+H15+K15+N15+Q15+T15+W15 -> 0
A16: =A15+7 -> 46251 | Y16: =B16+F16+I16+L16+O16+R16+U16 -> 0 | Z16: =C16+G16+J16+M16+P16+S16+V16 -> 0 | AA16: =D16+H16+K16+N16+Q16+T16+W16 -> 0
A17: =A16+7 -> 46258 | Y17: =B17+F17+I17+L17+O17+R17+U17 -> 0 | Z17: =C17+G17+J17+M17+P17+S17+V17 -> 0 | AA17: =D17+H17+K17+N17+Q17+T17+W17 -> 0
... A52: =A51+7 -> 46503 | Y52: =B52+F52+I52+L52+O52+R52+U52 -> 0 | Z52: =C52+G52+J52+M52+P52+S52+V52 -> 0 | AA52: =D52+H52+K52+N52+Q52+T52+W52 -> 0

Sheet ПЛАН ЧЕРН К3
A1: ПЛАН ЧЕРН К3 | X1: Итого К3
A2: Дата | B2: Надземная часть
B3: 8.2.1 Отделка лобби/гранд-лобби | E3: 8.2.2 Отделка эвакуац. лестн. клетки надзем. | H3: 8.2.3 Лифт. холлы, тамбур-шлюзы надзем. | K3: 8.2.4 Технич. помещения надзем. | N3: 8.2.5 Прочие помещения надзем. | Q3: 8.2.6 Коммерч. помещения надзем. | T3: 8.2.7 Паркинг и рампы надзем. | X3: Пол | Y3: Стены | Z3: Потолок
B4: Пол | C4: Стены | D4: Потолок | E4: Пол | F4: Стены | G4: Потолок | H4: Пол | I4: Стены | J4: Потолок | K4: Пол | L4: Стены | M4: Потолок | N4: Пол | O4: Стены | P4: Потолок | Q4: Пол | R4: Стены | S4: Потолок | T4: Пол | U4: Стены | V4: Потолок
A5: =СПРАВОЧНИК!$B$35 -> 46174 | X5: =B5+E5+H5+K5+N5+Q5+T5 -> 0 | Y5: =C5+F5+I5+L5+O5+R5+U5 -> 0 | Z5: =D5+G5+J5+M5+P5+S5+V5 -> 0
A6: =A5+7 -> 46181 | X6: =B6+E6+H6+K6+N6+Q6+T6 -> 0 | Y6: =C6+F6+I6+L6+O6+R6+U6 -> 0 | Z6: =D6+G6+J6+M6+P6+S6+V6 -> 0
A7: =A6+7 -> 46188 | X7: =B7+E7+H7+K7+N7+Q7+T7 -> 0 | Y7: =C7+F7+I7+L7+O7+R7+U7 -> 0 | Z7: =D7+G7+J7+M7+P7+S7+V7 -> 0
A8: =A7+7 -> 46195 | X8: =B8+E8+H8+K8+N8+Q8+T8 -> 0 | Y8: =C8+F8+I8+L8+O8+R8+U8 -> 0 | Z8: =D8+G8+J8+M8+P8+S8+V8 -> 0
A9: =A8+7 -> 46202 | X9: =B9+E9+H9+K9+N9+Q9+T9 -> 0 | Y9: =C9+F9+I9+L9+O9+R9+U9 -> 0 | Z9: =D9+G9+J9+M9+P9+S9+V9 -> 0
A10: =A9+7 -> 46209 | X10: =B10+E10+H10+K10+N10+Q10+T10 -> 0 | Y10: =C10+F10+I10+L10+O10+R10+U10 -> 0 | Z10: =D10+G10+J10+M10+P10+S10+V10 -> 0
A11: =A10+7 -> 46216 | X11: =B11+E11+H11+K11+N11+Q11+T11 -> 0 | Y11: =C11+F11+I11+L11+O11+R11+U11 -> 0 | Z11: =D11+G11+J11+M11+P11+S11+V11 -> 0
A12: =A11+7 -> 46223 | X12: =B12+E12+H12+K12+N12+Q12+T12 -> 0 | Y12: =C12+F12+I12+L12+O12+R12+U12 -> 0 | Z12: =D12+G12+J12+M12+P12+S12+V12 -> 0
A13: =A12+7 -> 46230 | X13: =B13+E13+H13+K13+N13+Q13+T13 -> 0 | Y13: =C13+F13+I13+L13+O13+R13+U13 -> 0 | Z13: =D13+G13+J13+M13+P13+S13+V13 -> 0
A14: =A13+7 -> 46237 | X14: =B14+E14+H14+K14+N14+Q14+T14 -> 0 | Y14: =C14+F14+I14+L14+O14+R14+U14 -> 0 | Z14: =D14+G14+J14+M14+P14+S14+V14 -> 0
A15: =A14+7 -> 46244 | X15: =B15+E15+H15+K15+N15+Q15+T15 -> 0 | Y15: =C15+F15+I15+L15+O15+R15+U15 -> 0 | Z15: =D15+G15+J15+M15+P15+S15+V15 -> 0
A16: =A15+7 -> 46251 | X16: =B16+E16+H16+K16+N16+Q16+T16 -> 0 | Y16: =C16+F16+I16+L16+O16+R16+U16 -> 0 | Z16: =D16+G16+J16+M16+P16+S16+V16 -> 0
A17: =A16+7 -> 46258 | X17: =B17+E17+H17+K17+N17+Q17+T17 -> 0 | Y17: =C17+F17+I17+L17+O17+R17+U17 -> 0 | Z17: =D17+G17+J17+M17+P17+S17+V17 -> 0
... A52: =A51+7 -> 46503 | X52: =B52+E52+H52+K52+N52+Q52+T52 -> 0 | Y52: =C52+F52+I52+L52+O52+R52+U52 -> 0 | Z52: =D52+G52+J52+M52+P52+S52+V52 -> 0

Sheet ПЛАН ЧИСТ К3
A1: ПЛАН ЧИСТ К3 | Y1: Итого К3
A2: Дата | B2: Надземная часть
B3: 8.2.1 Отделка лобби/гранд-лобби | F3: 8.2.2 Отделка эвакуац. лестн. клетки надзем. | I3: 8.2.3 Лифт. холлы, тамбур-шлюзы надзем. | L3: 8.2.4 Технич. помещения надзем. | O3: 8.2.5 Прочие помещения надзем. | R3: 8.2.6 Коммерч. помещения надзем. | U3: 8.2.7 Паркинг и рампы надзем. | Y3: Пол | Z3: Стены | AA3: Потолок
B4: Пол | C4: Стены | D4: Потолок | E4: Мебл. | F4: Пол | G4: Стены | H4: Потолок | I4: Пол | J4: Стены | K4: Потолок | L4: Пол | M4: Стены | N4: Потолок | O4: Пол | P4: Стены | Q4: Потолок | R4: Пол | S4: Стены | T4: Потолок | U4: Пол | V4: Стены | W4: Потолок
A5: =СПРАВОЧНИК!$B$35 -> 46174 | Y5: =B5+F5+I5+L5+O5+R5+U5 -> 0 | Z5: =C5+G5+J5+M5+P5+S5+V5 -> 0 | AA5: =D5+H5+K5+N5+Q5+T5+W5 -> 0
A6: =A5+7 -> 46181 | Y6: =B6+F6+I6+L6+O6+R6+U6 -> 0 | Z6: =C6+G6+J6+M6+P6+S6+V6 -> 0 | AA6: =D6+H6+K6+N6+Q6+T6+W6 -> 0
A7: =A6+7 -> 46188 | Y7: =B7+F7+I7+L7+O7+R7+U7 -> 0 | Z7: =C7+G7+J7+M7+P7+S7+V7 -> 0 | AA7: =D7+H7+K7+N7+Q7+T7+W7 -> 0
A8: =A7+7 -> 46195 | Y8: =B8+F8+I8+L8+O8+R8+U8 -> 0 | Z8: =C8+G8+J8+M8+P8+S8+V8 -> 0 | AA8: =D8+H8+K8+N8+Q8+T8+W8 -> 0
A9: =A8+7 -> 46202 | Y9: =B9+F9+I9+L9+O9+R9+U9 -> 0 | Z9: =C9+G9+J9+M9+P9+S9+V9 -> 0 | AA9: =D9+H9+K9+N9+Q9+T9+W9 -> 0
A10: =A9+7 -> 46209 | Y10: =B10+F10+I10+L10+O10+R10+U10 -> 0 | Z10: =C10+G10+J10+M10+P10+S10+V10 -> 0 | AA10: =D10+H10+K10+N10+Q10+T10+W10 -> 0
A11: =A10+7 -> 46216 | Y11: =B11+F11+I11+L11+O11+R11+U11 -> 0 | Z11: =C11+G11+J11+M11+P11+S11+V11 -> 0 | AA11: =D11+H11+K11+N11+Q11+T11+W11 -> 0
A12: =A11+7 -> 46223 | Y12: =B12+F12+I12+L12+O12+R12+U12 -> 0 | Z12: =C12+G12+J12+M12+P12+S12+V12 -> 0 | AA12: =D12+H12+K12+N12+Q12+T12+W12 -> 0
A13: =A12+7 -> 46230 | Y13: =B13+F13+I13+L13+O13+R13+U13 -> 0 | Z13: =C13+G13+J13+M13+P13+S13+V13 -> 0 | AA13: =D13+H13+K13+N13+Q13+T13+W13 -> 0
A14: =A13+7 -> 46237 | Y14: =B14+F14+I14+L14+O14+R14+U14 -> 0 | Z14: =C14+G14+J14+M14+P14+S14+V14 -> 0 | AA14: =D14+H14+K14+N14+Q14+T14+W14 -> 0
A15: =A14+7 -> 46244 | Y15: =B15+F15+I15+L15+O15+R15+U15 -> 0 | Z15: =C15+G15+J15+M15+P15+S15+V15 -> 0 | AA15: =D15+H15+K15+N15+Q15+T15+W15 -> 0
A16: =A15+7 -> 46251 | Y16: =B16+F16+I16+L16+O16+R16+U16 -> 0 | Z16: =C16+G16+J16+M16+P16+S16+V16 -> 0 | AA16: =D16+H16+K16+N16+Q16+T16+W16 -> 0
A17: =A16+7 -> 46258 | Y17: =B17+F17+I17+L17+O17+R17+U17 -> 0 | Z17: =C17+G17+J17+M17+P17+S17+V17 -> 0 | AA17: =D17+H17+K17+N17+Q17+T17+W17 -> 0
... A52: =A51+7 -> 46503 | Y52: =B52+F52+I52+L52+O52+R52+U52 -> 0 | Z52: =C52+G52+J52+M52+P52+S52+V52 -> 0 | AA52: =D52+H52+K52+N52+Q52+T52+W52 -> 0

Sheet ФАКТ ЧЕРН ПОДЗЕМ
A1: ФАКТ ЧЕРН ПОДЗЕМ | U1: Итого подзем.
A2: Дата | B2: Подземная часть
B3: 8.1.1 Отделка паркинг и рампы | E3: 8.1.2 Отделка эвакуац. лестн. клетки подзем. | H3: 8.1.3 Лифт. холлы, тамбур-шлюзы подзем. | K3: 8.1.4 Технич. помещения подзем. | N3: 8.1.5 Прочие помещения подзем. | Q3: 8.1.6 Коммерч. помещения подзем. | U3: Пол | V3: Стены | W3: Потолок
B4: Пол | C4: Стены | D4: Потолок | E4: Пол | F4: Стены | G4: Потолок | H4: Пол | I4: Стены | J4: Потолок | K4: Пол | L4: Стены | M4: Потолок | N4: Пол | O4: Стены | P4: Потолок | Q4: Пол | R4: Стены | S4: Потолок
A5: =СПРАВОЧНИК!$B$35 -> 46174 | U5: =B5+E5+H5+K5+N5+Q5 -> 0 | V5: =C5+F5+I5+L5+O5+R5 -> 0 | W5: =D5+G5+J5+M5+P5+S5 -> 0
A6: =A5+7 -> 46181 | U6: =B6+E6+H6+K6+N6+Q6 -> 0 | V6: =C6+F6+I6+L6+O6+R6 -> 0 | W6: =D6+G6+J6+M6+P6+S6 -> 0
A7: =A6+7 -> 46188 | U7: =B7+E7+H7+K7+N7+Q7 -> 0 | V7: =C7+F7+I7+L7+O7+R7 -> 0 | W7: =D7+G7+J7+M7+P7+S7 -> 0
A8: =A7+7 -> 46195 | U8: =B8+E8+H8+K8+N8+Q8 -> 0 | V8: =C8+F8+I8+L8+O8+R8 -> 0 | W8: =D8+G8+J8+M8+P8+S8 -> 0
A9: =A8+7 -> 46202 | U9: =B9+E9+H9+K9+N9+Q9 -> 0 | V9: =C9+F9+I9+L9+O9+R9 -> 0 | W9: =D9+G9+J9+M9+P9+S9 -> 0
A10: =A9+7 -> 46209 | U10: =B10+E10+H10+K10+N10+Q10 -> 0 | V10: =C10+F10+I10+L10+O10+R10 -> 0 | W10: =D10+G10+J10+M10+P10+S10 -> 0
A11: =A10+7 -> 46216 | U11: =B11+E11+H11+K11+N11+Q11 -> 0 | V11: =C11+F11+I11+L11+O11+R11 -> 0 | W11: =D11+G11+J11+M11+P11+S11 -> 0
A12: =A11+7 -> 46223 | U12: =B12+E12+H12+K12+N12+Q12 -> 0 | V12: =C12+F12+I12+L12+O12+R12 -> 0 | W12: =D12+G12+J12+M12+P12+S12 -> 0
A13: =A12+7 -> 46230 | U13: =B13+E13+H13+K13+N13+Q13 -> 0 | V13: =C13+F13+I13+L13+O13+R13 -> 0 | W13: =D13+G13+J13+M13+P13+S13 -> 0
A14: =A13+7 -> 46237 | U14: =B14+E14+H14+K14+N14+Q14 -> 0 | V14: =C14+F14+I14+L14+O14+R14 -> 0 | W14: =D14+G14+J14+M14+P14+S14 -> 0
A15: =A14+7 -> 46244 | U15: =B15+E15+H15+K15+N15+Q15 -> 0 | V15: =C15+F15+I15+L15+O15+R15 -> 0 | W15: =D15+G15+J15+M15+P15+S15 -> 0
A16: =A15+7 -> 46251 | U16: =B16+E16+H16+K16+N16+Q16 -> 0 | V16: =C16+F16+I16+L16+O16+R16 -> 0 | W16: =D16+G16+J16+M16+P16+S16 -> 0
A17: =A16+7 -> 46258 | U17: =B17+E17+H17+K17+N17+Q17 -> 0 | V17: =C17+F17+I17+L17+O17+R17 -> 0 | W17: =D17+G17+J17+M17+P17+S17 -> 0
... A52: =A51+7 -> 46503 | U52: =B52+E52+H52+K52+N52+Q52 -> 0 | V52: =C52+F52+I52+L52+O52+R52 -> 0 | W52: =D52+G52+J52+M52+P52+S52 -> 0

Sheet ФАКТ ЧИСТ ПОДЗЕМ
A1: ФАКТ ЧИСТ ПОДЗЕМ | U1: Итого подзем.
A2: Дата | B2: Подземная часть
B3: 8.1.1 Отделка паркинг и рампы | E3: 8.1.2 Отделка эвакуац. лестн. клетки подзем. | H3: 8.1.3 Лифт. холлы, тамбур-шлюзы подзем. | K3: 8.1.4 Технич. помещения подзем. | N3: 8.1.5 Прочие помещения подзем. | Q3: 8.1.6 Коммерч. помещения подзем. | U3: Пол | V3: Стены | W3: Потолок
B4: Пол | C4: Стены | D4: Потолок | E4: Пол | F4: Стены | G4: Потолок | H4: Пол | I4: Стены | J4: Потолок | K4: Пол | L4: Стены | M4: Потолок | N4: Пол | O4: Стены | P4: Потолок | Q4: Пол | R4: Стены | S4: Потолок
A5: =СПРАВОЧНИК!$B$35 -> 46174 | U5: =B5+E5+H5+K5+N5+Q5 -> 0 | V5: =C5+F5+I5+L5+O5+R5 -> 0 | W5: =D5+G5+J5+M5+P5+S5 -> 0
A6: =A5+7 -> 46181 | U6: =B6+E6+H6+K6+N6+Q6 -> 0 | V6: =C6+F6+I6+L6+O6+R6 -> 0 | W6: =D6+G6+J6+M6+P6+S6 -> 0
A7: =A6+7 -> 46188 | U7: =B7+E7+H7+K7+N7+Q7 -> 0 | V7: =C7+F7+I7+L7+O7+R7 -> 0 | W7: =D7+G7+J7+M7+P7+S7 -> 0
A8: =A7+7 -> 46195 | U8: =B8+E8+H8+K8+N8+Q8 -> 0 | V8: =C8+F8+I8+L8+O8+R8 -> 0 | W8: =D8+G8+J8+M8+P8+S8 -> 0
A9: =A8+7 -> 46202 | U9: =B9+E9+H9+K9+N9+Q9 -> 0 | V9: =C9+F9+I9+L9+O9+R9 -> 0 | W9: =D9+G9+J9+M9+P9+S9 -> 0
A10: =A9+7 -> 46209 | U10: =B10+E10+H10+K10+N10+Q10 -> 0 | V10: =C10+F10+I10+L10+O10+R10 -> 0 | W10: =D10+G10+J10+M10+P10+S10 -> 0
A11: =A10+7 -> 46216 | U11: =B11+E11+H11+K11+N11+Q11 -> 0 | V11: =C11+F11+I11+L11+O11+R11 -> 0 | W11: =D11+G11+J11+M11+P11+S11 -> 0
A12: =A11+7 -> 46223 | U12: =B12+E12+H12+K12+N12+Q12 -> 0 | V12: =C12+F12+I12+L12+O12+R12 -> 0 | W12: =D12+G12+J12+M12+P12+S12 -> 0
A13: =A12+7 -> 46230 | U13: =B13+E13+H13+K13+N13+Q13 -> 0 | V13: =C13+F13+I13+L13+O13+R13 -> 0 | W13: =D13+G13+J13+M13+P13+S13 -> 0
A14: =A13+7 -> 46237 | U14: =B14+E14+H14+K14+N14+Q14 -> 0 | V14: =C14+F14+I14+L14+O14+R14 -> 0 | W14: =D14+G14+J14+M14+P14+S14 -> 0
A15: =A14+7 -> 46244 | U15: =B15+E15+H15+K15+N15+Q15 -> 0 | V15: =C15+F15+I15+L15+O15+R15 -> 0 | W15: =D15+G15+J15+M15+P15+S15 -> 0
A16: =A15+7 -> 46251 | U16: =B16+E16+H16+K16+N16+Q16 -> 0 | V16: =C16+F16+I16+L16+O16+R16 -> 0 | W16: =D16+G16+J16+M16+P16+S16 -> 0
A17: =A16+7 -> 46258 | U17: =B17+E17+H17+K17+N17+Q17 -> 0 | V17: =C17+F17+I17+L17+O17+R17 -> 0 | W17: =D17+G17+J17+M17+P17+S17 -> 0
... A52: =A51+7 -> 46503 | U52: =B52+E52+H52+K52+N52+Q52 -> 0 | V52: =C52+F52+I52+L52+O52+R52 -> 0 | W52: =D52+G52+J52+M52+P52+S52 -> 0

Sheet ФАКТ ЧЕРН К1
A1: ФАКТ ЧЕРН К1 | X1: Итого К1
A2: Дата | B2: Надземная часть
B3: 8.2.1 Отделка лобби/гранд-лобби | E3: 8.2.2 Отделка эвакуац. лестн. клетки надзем. | H3: 8.2.3 Лифт. холлы, тамбур-шлюзы надзем. | K3: 8.2.4 Технич. помещения надзем. | N3: 8.2.5 Прочие помещения надзем. | Q3: 8.2.6 Коммерч. помещения надзем. | T3: 8.2.7 Паркинг и рампы надзем. | X3: Пол | Y3: Стены | Z3: Потолок
B4: Пол | C4: Стены | D4: Потолок | E4: Пол | F4: Стены | G4: Потолок | H4: Пол | I4: Стены | J4: Потолок | K4: Пол | L4: Стены | M4: Потолок | N4: Пол | O4: Стены | P4: Потолок | Q4: Пол | R4: Стены | S4: Потолок | T4: Пол | U4: Стены | V4: Потолок
A5: =СПРАВОЧНИК!$B$35 -> 46174 | X5: =B5+E5+H5+K5+N5+Q5+T5 -> 0 | Y5: =C5+F5+I5+L5+O5+R5+U5 -> 0 | Z5: =D5+G5+J5+M5+P5+S5+V5 -> 0
A6: =A5+7 -> 46181 | X6: =B6+E6+H6+K6+N6+Q6+T6 -> 0 | Y6: =C6+F6+I6+L6+O6+R6+U6 -> 0 | Z6: =D6+G6+J6+M6+P6+S6+V6 -> 0
A7: =A6+7 -> 46188 | X7: =B7+E7+H7+K7+N7+Q7+T7 -> 0 | Y7: =C7+F7+I7+L7+O7+R7+U7 -> 0 | Z7: =D7+G7+J7+M7+P7+S7+V7 -> 0
A8: =A7+7 -> 46195 | X8: =B8+E8+H8+K8+N8+Q8+T8 -> 0 | Y8: =C8+F8+I8+L8+O8+R8+U8 -> 0 | Z8: =D8+G8+J8+M8+P8+S8+V8 -> 0
A9: =A8+7 -> 46202 | X9: =B9+E9+H9+K9+N9+Q9+T9 -> 0 | Y9: =C9+F9+I9+L9+O9+R9+U9 -> 0 | Z9: =D9+G9+J9+M9+P9+S9+V9 -> 0
A10: =A9+7 -> 46209 | X10: =B10+E10+H10+K10+N10+Q10+T10 -> 0 | Y10: =C10+F10+I10+L10+O10+R10+U10 -> 0 | Z10: =D10+G10+J10+M10+P10+S10+V10 -> 0
A11: =A10+7 -> 46216 | X11: =B11+E11+H11+K11+N11+Q11+T11 -> 0 | Y11: =C11+F11+I11+L11+O11+R11+U11 -> 0 | Z11: =D11+G11+J11+M11+P11+S11+V11 -> 0
A12: =A11+7 -> 46223 | X12: =B12+E12+H12+K12+N12+Q12+T12 -> 0 | Y12: =C12+F12+I12+L12+O12+R12+U12 -> 0 | Z12: =D12+G12+J12+M12+P12+S12+V12 -> 0
A13: =A12+7 -> 46230 | X13: =B13+E13+H13+K13+N13+Q13+T13 -> 0 | Y13: =C13+F13+I13+L13+O13+R13+U13 -> 0 | Z13: =D13+G13+J13+M13+P13+S13+V13 -> 0
A14: =A13+7 -> 46237 | X14: =B14+E14+H14+K14+N14+Q14+T14 -> 0 | Y14: =C14+F14+I14+L14+O14+R14+U14 -> 0 | Z14: =D14+G14+J14+M14+P14+S14+V14 -> 0
A15: =A14+7 -> 46244 | X15: =B15+E15+H15+K15+N15+Q15+T15 -> 0 | Y15: =C15+F15+I15+L15+O15+R15+U15 -> 0 | Z15: =D15+G15+J15+M15+P15+S15+V15 -> 0
A16: =A15+7 -> 46251 | X16: =B16+E16+H16+K16+N16+Q16+T16 -> 0 | Y16: =C16+F16+I16+L16+O16+R16+U16 -> 0 | Z16: =D16+G16+J16+M16+P16+S16+V16 -> 0
A17: =A16+7 -> 46258 | X17: =B17+E17+H17+K17+N17+Q17+T17 -> 0 | Y17: =C17+F17+I17+L17+O17+R17+U17 -> 0 | Z17: =D17+G17+J17+M17+P17+S17+V17 -> 0
... A52: =A51+7 -> 46503 | X52: =B52+E52+H52+K52+N52+Q52+T52 -> 0 | Y52: =C52+F52+I52+L52+O52+R52+U52 -> 0 | Z52: =D52+G52+J52+M52+P52+S52+V52 -> 0

Sheet ФАКТ ЧИСТ К1
A1: ФАКТ ЧИСТ К1 | Y1: Итого К1
A2: Дата | B2: Надземная часть
B3: 8.2.1 Отделка лобби/гранд-лобби | F3: 8.2.2 Отделка эвакуац. лестн. клетки надзем. | I3: 8.2.3 Лифт. холлы, тамбур-шлюзы надзем. | L3: 8.2.4 Технич. помещения надзем. | O3: 8.2.5 Прочие помещения надзем. | R3: 8.2.6 Коммерч. помещения надзем. | U3: 8.2.7 Паркинг и рампы надзем. | Y3: Пол | Z3: Стены | AA3: Потолок
B4: Пол | C4: Стены | D4: Потолок | E4: Мебл. | F4: Пол | G4: Стены | H4: Потолок | I4: Пол | J4: Стены | K4: Потолок | L4: Пол | M4: Стены | N4: Потолок | O4: Пол | P4: Стены | Q4: Потолок | R4: Пол | S4: Стены | T4: Потолок | U4: Пол | V4: Стены | W4: Потолок
A5: =СПРАВОЧНИК!$B$35 -> 46174 | Y5: =B5+F5+I5+L5+O5+R5+U5 -> 0 | Z5: =C5+G5+J5+M5+P5+S5+V5 -> 0 | AA5: =D5+H5+K5+N5+Q5+T5+W5 -> 0
A6: =A5+7 -> 46181 | Y6: =B6+F6+I6+L6+O6+R6+U6 -> 0 | Z6: =C6+G6+J6+M6+P6+S6+V6 -> 0 | AA6: =D6+H6+K6+N6+Q6+T6+W6 -> 0
A7: =A6+7 -> 46188 | Y7: =B7+F7+I7+L7+O7+R7+U7 -> 0 | Z7: =C7+G7+J7+M7+P7+S7+V7 -> 0 | AA7: =D7+H7+K7+N7+Q7+T7+W7 -> 0
A8: =A7+7 -> 46195 | Y8: =B8+F8+I8+L8+O8+R8+U8 -> 0 | Z8: =C8+G8+J8+M8+P8+S8+V8 -> 0 | AA8: =D8+H8+K8+N8+Q8+T8+W8 -> 0
A9: =A8+7 -> 46202 | Y9: =B9+F9+I9+L9+O9+R9+U9 -> 0 | Z9: =C9+G9+J9+M9+P9+S9+V9 -> 0 | AA9: =D9+H9+K9+N9+Q9+T9+W9 -> 0
A10: =A9+7 -> 46209 | Y10: =B10+F10+I10+L10+O10+R10+U10 -> 0 | Z10: =C10+G10+J10+M10+P10+S10+V10 -> 0 | AA10: =D10+H10+K10+N10+Q10+T10+W10 -> 0
A11: =A10+7 -> 46216 | Y11: =B11+F11+I11+L11+O11+R11+U11 -> 0 | Z11: =C11+G11+J11+M11+P11+S11+V11 -> 0 | AA11: =D11+H11+K11+N11+Q11+T11+W11 -> 0
A12: =A11+7 -> 46223 | Y12: =B12+F12+I12+L12+O12+R12+U12 -> 0 | Z12: =C12+G12+J12+M12+P12+S12+V12 -> 0 | AA12: =D12+H12+K12+N12+Q12+T12+W12 -> 0
A13: =A12+7 -> 46230 | Y13: =B13+F13+I13+L13+O13+R13+U13 -> 0 | Z13: =C13+G13+J13+M13+P13+S13+V13 -> 0 | AA13: =D13+H13+K13+N13+Q13+T13+W13 -> 0
A14: =A13+7 -> 46237 | Y14: =B14+F14+I14+L14+O14+R14+U14 -> 0 | Z14: =C14+G14+J14+M14+P14+S14+V14 -> 0 | AA14: =D14+H14+K14+N14+Q14+T14+W14 -> 0
A15: =A14+7 -> 46244 | Y15: =B15+F15+I15+L15+O15+R15+U15 -> 0 | Z15: =C15+G15+J15+M15+P15+S15+V15 -> 0 | AA15: =D15+H15+K15+N15+Q15+T15+W15 -> 0
A16: =A15+7 -> 46251 | Y16: =B16+F16+I16+L16+O16+R16+U16 -> 0 | Z16: =C16+G16+J16+M16+P16+S16+V16 -> 0 | AA16: =D16+H16+K16+N16+Q16+T16+W16 -> 0
A17: =A16+7 -> 46258 | Y17: =B17+F17+I17+L17+O17+R17+U17 -> 0 | Z17: =C17+G17+J17+M17+P17+S17+V17 -> 0 | AA17: =D17+H17+K17+N17+Q17+T17+W17 -> 0
... A52: =A51+7 -> 46503 | Y52: =B52+F52+I52+L52+O52+R52+U52 -> 0 | Z52: =C52+G52+J52+M52+P52+S52+V52 -> 0 | AA52: =D52+H52+K52+N52+Q52+T52+W52 -> 0

Sheet ФАКТ ЧЕРН К2
A1: ФАКТ ЧЕРН К2 | X1: Итого К2
A2: Дата | B2: Надземная часть
B3: 8.2.1 Отделка лобби/гранд-лобби | E3: 8.2.2 Отделка эвакуац. лестн. клетки надзем. | H3: 8.2.3 Лифт. холлы, тамбур-шлюзы надзем. | K3: 8.2.4 Технич. помещения надзем. | N3: 8.2.5 Прочие помещения надзем. | Q3: 8.2.6 Коммерч. помещения надзем. | T3: 8.2.7 Паркинг и рампы надзем. | X3: Пол | Y3: Стены | Z3: Потолок
B4: Пол | C4: Стены | D4: Потолок | E4: Пол | F4: Стены | G4: Потолок | H4: Пол | I4: Стены | J4: Потолок | K4: Пол | L4: Стены | M4: Потолок | N4: Пол | O4: Стены | P4: Потолок | Q4: Пол | R4: Стены | S4: Потолок | T4: Пол | U4: Стены | V4: Потолок
A5: =СПРАВОЧНИК!$B$35 -> 46174 | X5: =B5+E5+H5+K5+N5+Q5+T5 -> 0 | Y5: =C5+F5+I5+L5+O5+R5+U5 -> 0 | Z5: =D5+G5+J5+M5+P5+S5+V5 -> 0
A6: =A5+7 -> 46181 | X6: =B6+E6+H6+K6+N6+Q6+T6 -> 0 | Y6: =C6+F6+I6+L6+O6+R6+U6 -> 0 | Z6: =D6+G6+J6+M6+P6+S6+V6 -> 0
A7: =A6+7 -> 46188 | X7: =B7+E7+H7+K7+N7+Q7+T7 -> 0 | Y7: =C7+F7+I7+L7+O7+R7+U7 -> 0 | Z7: =D7+G7+J7+M7+P7+S7+V7 -> 0
A8: =A7+7 -> 46195 | X8: =B8+E8+H8+K8+N8+Q8+T8 -> 0 | Y8: =C8+F8+I8+L8+O8+R8+U8 -> 0 | Z8: =D8+G8+J8+M8+P8+S8+V8 -> 0
A9: =A8+7 -> 46202 | X9: =B9+E9+H9+K9+N9+Q9+T9 -> 0 | Y9: =C9+F9+I9+L9+O9+R9+U9 -> 0 | Z9: =D9+G9+J9+M9+P9+S9+V9 -> 0
A10: =A9+7 -> 46209 | X10: =B10+E10+H10+K10+N10+Q10+T10 -> 0 | Y10: =C10+F10+I10+L10+O10+R10+U10 -> 0 | Z10: =D10+G10+J10+M10+P10+S10+V10 -> 0
A11: =A10+7 -> 46216 | X11: =B11+E11+H11+K11+N11+Q11+T11 -> 0 | Y11: =C11+F11+I11+L11+O11+R11+U11 -> 0 | Z11: =D11+G11+J11+M11+P11+S11+V11 -> 0
A12: =A11+7 -> 46223 | X12: =B12+E12+H12+K12+N12+Q12+T12 -> 0 | Y12: =C12+F12+I12+L12+O12+R12+U12 -> 0 | Z12: =D12+G12+J12+M12+P12+S12+V12 -> 0
A13: =A12+7 -> 46230 | X13: =B13+E13+H13+K13+N13+Q13+T13 -> 0 | Y13: =C13+F13+I13+L13+O13+R13+U13 -> 0 | Z13: =D13+G13+J13+M13+P13+S13+V13 -> 0
A14: =A13+7 -> 46237 | X14: =B14+E14+H14+K14+N14+Q14+T14 -> 0 | Y14: =C14+F14+I14+L14+O14+R14+U14 -> 0 | Z14: =D14+G14+J14+M14+P14+S14+V14 -> 0
A15: =A14+7 -> 46244 | X15: =B15+E15+H15+K15+N15+Q15+T15 -> 0 | Y15: =C15+F15+I15+L15+O15+R15+U15 -> 0 | Z15: =D15+G15+J15+M15+P15+S15+V15 -> 0
A16: =A15+7 -> 46251 | X16: =B16+E16+H16+K16+N16+Q16+T16 -> 0 | Y16: =C16+F16+I16+L16+O16+R16+U16 -> 0 | Z16: =D16+G16+J16+M16+P16+S16+V16 -> 0
A17: =A16+7 -> 46258 | X17: =B17+E17+H17+K17+N17+Q17+T17 -> 0 | Y17: =C17+F17+I17+L17+O17+R17+U17 -> 0 | Z17: =D17+G17+J17+M17+P17+S17+V17 -> 0
... A52: =A51+7 -> 46503 | X52: =B52+E52+H52+K52+N52+Q52+T52 -> 0 | Y52: =C52+F52+I52+L52+O52+R52+U52 -> 0 | Z52: =D52+G52+J52+M52+P52+S52+V52 -> 0

Sheet ФАКТ ЧИСТ К2
A1: ФАКТ ЧИСТ К2 | Y1: Итого К2
A2: Дата | B2: Надземная часть
B3: 8.2.1 Отделка лобби/гранд-лобби | F3: 8.2.2 Отделка эвакуац. лестн. клетки надзем. | I3: 8.2.3 Лифт. холлы, тамбур-шлюзы надзем. | L3: 8.2.4 Технич. помещения надзем. | O3: 8.2.5 Прочие помещения надзем. | R3: 8.2.6 Коммерч. помещения надзем. | U3: 8.2.7 Паркинг и рампы надзем. | Y3: Пол | Z3: Стены | AA3: Потолок
B4: Пол | C4: Стены | D4: Потолок | E4: Мебл. | F4: Пол | G4: Стены | H4: Потолок | I4: Пол | J4: Стены | K4: Потолок | L4: Пол | M4: Стены | N4: Потолок | O4: Пол | P4: Стены | Q4: Потолок | R4: Пол | S4: Стены | T4: Потолок | U4: Пол | V4: Стены | W4: Потолок
A5: =СПРАВОЧНИК!$B$35 -> 46174 | Y5: =B5+F5+I5+L5+O5+R5+U5 -> 0 | Z5: =C5+G5+J5+M5+P5+S5+V5 -> 0 | AA5: =D5+H5+K5+N5+Q5+T5+W5 -> 0
A6: =A5+7 -> 46181 | Y6: =B6+F6+I6+L6+O6+R6+U6 -> 0 | Z6: =C6+G6+J6+M6+P6+S6+V6 -> 0 | AA6: =D6+H6+K6+N6+Q6+T6+W6 -> 0
A7: =A6+7 -> 46188 | Y7: =B7+F7+I7+L7+O7+R7+U7 -> 0 | Z7: =C7+G7+J7+M7+P7+S7+V7 -> 0 | AA7: =D7+H7+K7+N7+Q7+T7+W7 -> 0
