Workbook
Name К1_Общий_8_2: SIGNAL!$T:$W
Name К1_Черновая_8_2: SIGNAL!$Z:$AC
Name К1_Чистовая_8_2: SIGNAL!$AF:$AI
Name К2_Общий_8_2: SIGNAL!$AL:$AO
Name К2_Черновая_8_2: SIGNAL!$AR:$AU
Name К2_Чистовая_8_2: SIGNAL!$AX:$BA
Name К3_Общий_8_2: SIGNAL!$BD:$BG
Name К3_Черновая_8_2: SIGNAL!$BJ:$BM
Name К3_Чистовая_8_2: SIGNAL!$BP:$BS
Name Общая: SIGNAL!$CN:$CQ
Name Общий_8_1: SIGNAL!$B:$E
Name Общий_8_2: SIGNAL!$BV:$BY
Name Черновая: SIGNAL!$CT:$CW
Name Черновая_8_1: SIGNAL!$H:$K
Name Черновая_8_2: SIGNAL!$CB:$CE
Name Чистовая: SIGNAL!$CZ:$DC
Name Чистовая_8_1: SIGNAL!$N:$Q
Name Чистовая_8_2: SIGNAL!$CH:$CK

Sheet ИНСТРУКЦИЯ
A1: ИНСТРУКЦИЯ ПО ЗАПОЛНЕНИЮ
A2: Отделка для SIGNAL — Пошаговое руководство
A4: ОБЗОР СТРУКТУРЫ ФАЙЛА
B5: Лист | C5: Назначение | D5: Действия пользователя
B6: СПРАВОЧНИК | C6: Справочник категорий, весов, площадей | D6: Настроить развесовку и площади
B7: ПЛАН ЧЕРН/ЧИСТ * | C7: Плановые м2 по неделям (сетка) | D7: Вносить плановые м2
B8: ФАКТ ЧЕРН/ЧИСТ * | C8: Фактические м2 по неделям (сетка) | D8: Вносить фактические м2
B9: ОТЧЕТ | C9: Сводный отчёт по % выполнения | D9: Только просмотр (авто)
B10: SIGNAL | C10: Карточки для системы SIGNAL | D10: Только просмотр (авто)
A12: ЭТАП 0: СТРУКТУРА ПРОЕКТА
A13: 0.1 | B13: Текущая конфигурация:
B14: Проект рассчитан на фиксированную структуру:
B15: * ПОДЗЕМ — подземная часть (6 подкатегорий: 8.1.1 - 8.1.6)
B16: * К1 — корпус 1 (7 подкатегорий: 8.2.1 - 8.2.7)
B17: * К2 — корпус 2 (аналогично К1)
B18: * К3 — корпус 3 (аналогично К1)
B19: Для изменения количества корпусов используйте конструктор (HTML-генератор).
A21: КАК ОПРЕДЕЛИТЬ ВЕС: МЕТОДИКА
B22: Вес — это доля трудозатрат вида работ от общего объёма. Определяется экспертно в 3 шага.
B24: Шаг 1. Черновая / Чистовая (столбцы E и F)
B25: Представьте: всё помещение = 100% работ по отделке.
B26: Оцените: какую долю общих усилий занимает черновая, а какую чистовая?
B27: Оценивайте по трудозатратам и длительности, не по стоимости материалов.
B28: Черновая обычно тяжелее по трудоёмкости (стяжка, штукатурка),
B29: но чистовая может быть дороже по материалам — это не влияет на вес.
B30: Пример: Черновая = 0.60, Чистовая = 0.40. Сумма = 1.00
B32: Шаг 2. Пол / Стены / Потолок внутри Черновой (столбцы H, I, J)
B33: Теперь возьмите только черновую отделку = 100%. Распределите:
B34: Пол — стяжка, гидроизоляция, выравнивание
B35: Стены — штукатурка, грунтовка, выравнивание
... B52: Доля дней = вес.
A54: ЭТАП 1: СПРАВОЧНИК — РАЗВЕСОВКА
A55: 1.1 | B55: Дата начала проекта | C55: Ячейка СПРАВОЧНИК!B35
B56: Первая дата — это дата первого отчёта в SIGNAL, которая входит в период плановых сроков реализации.
A58: 1.2 | B58: Плановые площади (м2) | C58: Столбец СПРАВОЧНИК!B, строки 3-15
B59: Введите общую плановую площадь (м2) для каждой подкатегории отделки.
B60: Пример: 8.1.1 Парковка = 12500 м2, 8.2.1 Лобби = 3200 м2
B61: Если подкатегория не применяется в проекте (напр. 8.2.6, 8.2.7) — поставьте 0.
B62: При плане = 0 все формулы ОТЧЕТ и SIGNAL по этой категории обнулятся автоматически.
A64: 1.3 | B64: Веса черновой / чистовой | C64: Столбцы СПРАВОЧНИК!E-F, строки 3-15
...

Sheet СПРАВОЧНИК
A1: СПРАВОЧНИК КАТЕГОРИЙ ОТДЕЛКИ
A2: Код | B2: Часть | C2: Название | D2: План м² | E2: Вес черн. | F2: Вес чист. | G2: ∑ весов | H2: Черн:Пол | I2: Черн:Стены | J2: Черн:Потолок | K2: ∑ черн. | L2: Чист:Пол | M2: Чист:Стены | N2: Чист:Потолок | O2: Чист:Запол. | P2: Чист:Мебл. | Q2: ∑ чист. | R2: Начало | S2: Окончание | T2: Длит.(дни) | U2: Труд-proxy | V2: Вес ур.3 (авто) | W2: Вес ур.3 | X2: Глоб. вес
A3: 8.1.1 | B3: Подзем. | C3: Отделка паркинг и рампы | D3: 0 | E3: 0.45 | F3: 0.55 | G3: =E3+F3 | H3: 0.38 | I3: 0.41 | J3: 0.21 | K3: =SUM(H3:J3) | L3: 0.46 | M3: 0.3 | N3: 0.12 | O3: 0.12 | P3: 0 | Q3: =SUM(L3:P3) | T3: =IF(OR(Q3="",R3=""),0,R3-Q3) | U3: =S3*D3 | V3: =IFERROR(T3/SUMIF($B$3:$B$15,$B3,$T$3:$T$15),0) | W3: =U3 | X3: =V3*IF($B3="Подзем.",$V$18,$V$19)
A4: 8.1.2 | B4: Подзем. | C4: Отделка эвакуац. лестн. клетки подзем. | D4: 0 | E4: 0.33 | F4: 0.67 | G4: =E4+F4 | H4: 0.2 | I4: 0.61 | J4: 0.19 | K4: =SUM(H4:J4) | L4: 0.32 | M4: 0.29 | N4: 0.23 | O4: 0.16 | P4: 0 | Q4: =SUM(L4:P4) | T4: =IF(OR(Q4="",R4=""),0,R4-Q4) | U4: =S4*D4 | V4: =IFERROR(T4/SUMIF($B$3:$B$15,$B4,$T$3:$T$15),0) | W4: =U4 | X4: =V4*IF($B4="Подзем.",$V$18,$V$19)
A5: 8.1.3 | B5: Подзем. | C5: Лифт. холлы, тамбур-шлюзы подзем. | D5: 0 | E5: 0.4 | F5: 0.6 | G5: =E5+F5 | H5: 0.4 | I5: 0.3 | J5: 0.3 | K5: =SUM(H5:J5) | L5: 0.2 | M5: 0.6 | N5: 0.2 | O5: 0 | P5: 0 | Q5: =SUM(L5:P5) | T5: =IF(OR(Q5="",R5=""),0,R5-Q5) | U5: =S5*D5 | V5: =IFERROR(T5/SUMIF($B$3:$B$15,$B5,$T$3:$T$15),0) | W5: =U5 | X5: =V5*IF($B5="Подзем.",$V$18,$V$19)
A6: 8.1.4 | B6: Подзем. | C6: Технич. помещения подзем. | D6: 0 | E6: 0.32 | F6: 0.68 | G6: =E6+F6 | H6: 0.3 | I6: 0.52 | J6: 0.18 | K6: =SUM(H6:J6) | L6: 0.33 | M6: 0.38 | N6: 0.13 | O6: 0.16 | P6: 0 | Q6: =SUM(L6:P6) | T6: =IF(OR(Q6="",R6=""),0,R6-Q6) | U6: =S6*D6 | V6: =IFERROR(T6/SUMIF($B$3:$B$15,$B6,$T$3:$T$15),0) | W6: =U6 | X6: =V6*IF($B6="Подзем.",$V$18,$V$19)
A7: 8.1.5 | B7: Подзем. | C7: Прочие помещения подзем. | D7: 0 | E7: 0.4 | F7: 0.6 | G7: =E7+F7 | H7: 0.31 | I7: 0.49 | J7: 0.2 | K7: =SUM(H7:J7) | L7: 0.35 | M7: 0.42 | N7: 0.11 | O7: 0.12 | P7: 0 | Q7: =SUM(L7:P7) | T7: =IF(OR(Q7="",R7=""),0,R7-Q7) | U7: =S7*D7 | V7: =IFERROR(T7/SUMIF($B$3:$B$15,$B7,$T$3:$T$15),0) | W7: =U7 | X7: =V7*IF($B7="Подзем.",$V$18,$V$19)
A8: 8.1.6 | B8: Подзем. | C8: Коммерч. помещения подзем. | D8: 0 | E8: 0.5 | F8: 0.5 | G8: =E8+F8 | H8: 0.3 | I8: 0.69 | J8: 0.01 | K8: =SUM(H8:J8) | L8: 0.2 | M8: 0.6 | N8: 0.2 | O8: 0 | P8: 0 | Q8: =SUM(L8:P8) | T8: =IF(OR(Q8="",R8=""),0,R8-Q8) | U8: =S8*D8 | V8: =IFERROR(T8/SUMIF($B$3:$B$15,$B8,$T$3:$T$15),0) | W8: =U8 | X8: =V8*IF($B8="Подзем.",$V$18,$V$19)
A9: 8.2.1 | B9: Надзем. | C9: Отделка лобби/гранд-лобби | D9: =B28+B29+B30 | E9: 0.4 | F9: 0.6 | G9: =E9+F9 | H9: 0.2 | I9: 0.63 | J9: 0.17 | K9: =SUM(H9:J9) | L9: 0.14 | M9: 0.41 | N9: 0.36 | O9: 0 | P9: 0.09 | Q9: =SUM(L9:P9) | T9: =IF(OR(Q9="",R9=""),0,R9-Q9) | U9: =S9*D9 | V9: =IFERROR(T9/SUMIF($B$3:$B$15,$B9,$T$3:$T$15),0) | W9: =U9 | X9: =V9*IF($B9="Подзем.",$V$18,$V$19)
A10: 8.2.2 | B10: Надзем. | C10: Отделка эвакуац. лестн. клетки надзем. | D10: =C28+C29+C30 | E10: 0.33 | F10: 0.67 | G10: =E10+F10 | H10: 0.2 | I10: 0.61 | J10: 0.19 | K10: =SUM(H10:J10) | L10: 0.32 | M10: 0.29 | N10: 0.23 | O10: 0.16 | P10: 0 | Q10: =SUM(L10:P10) | T10: =IF(OR(Q10="",R10=""),0,R10-Q10) | U10: =S10*D10 | V10: =IFERROR(T10/SUMIF($B$3:$B$15,$B10,$T$3:$T$15),0) | W10: =U10 | X10: =V10*IF($B10="Подзем.",$V$18,$V$19)
A11: 8.2.3 | B11: Надзем. | C11: Лифт. холлы, тамбур-шлюзы надзем. | D11: =D28+D29+D30 | E11: 0.4 | F11: 0.6 | G11: =E11+F11 | H11: 0.4 | I11: 0.3 | J11: 0.3 | K11: =SUM(H11:J11) | L11: 0.2 | M11: 0.6 | N11: 0.2 | O11: 0 | P11: 0 | Q11: =SUM(L11:P11) | T11: =IF(OR(Q11="",R11=""),0,R11-Q11) | U11: =S11*D11 | V11: =IFERROR(T11/SUMIF($B$3:$B$15,$B11,$T$3:$T$15),0) | W11: =U11 | X11: =V11*IF($B11="Подзем.",$V$18,$V$19)
A12: 8.2.4 | B12: Надзем. | C12: Технич. помещения надзем. | D12: =E28+E29+E30 | E12: 0.32 | F12: 0.68 | G12: =E12+F12 | H12: 0.3 | I12: 0.52 | J12: 0.18 | K12: =SUM(H12:J12) | L12: 0.33 | M12: 0.38 | N12: 0.13 | O12: 0.16 | P12: 0 | Q12: =SUM(L12:P12) | T12: =IF(OR(Q12="",R12=""),0,R12-Q12) | U12: =S12*D12 | V12: =IFERROR(T12/SUMIF($B$3:$B$15,$B12,$T$3:$T$15),0) | W12: =U12 | X12: =V12*IF($B12="Подзем.",$V$18,$V$19)
A13: 8.2.5 | B13: Надзем. | C13: Прочие помещения надзем. | D13: =F28+F29+F30 | E13: 0.4 | F13: 0.6 | G13: =E13+F13 | H13: 0.31 | I13: 0.49 | J13: 0.2 | K13: =SUM(H13:J13) | L13: 0.35 | M13: 0.42 | N13: 0.11 | O13: 0.12 | P13: 0 | Q13: =SUM(L13:P13) | T13: =IF(OR(Q13="",R13=""),0,R13-Q13) | U13: =S13*D13 | V13: =IFERROR(T13/SUMIF($B$3:$B$15,$B13,$T$3:$T$15),0) | W13: =U13 | X13: =V13*IF($B13="Подзем.",$V$18,$V$19)
A14: 8.2.6 | B14: Надзем. | C14: Коммерч. помещения надзем. | D14: =G28+G29+G30 | E14: 0.5 | F14: 0.5 | G14: =E14+F14 | H14: 0.3 | I14: 0.69 | J14: 0.01 | K14: =SUM(H14:J14) | L14: 0.2 | M14: 0.6 | N14: 0.2 | O14: 0 | P14: 0 | Q14: =SUM(L14:P14) | T14: =IF(OR(Q14="",R14=""),0,R14-Q14) | U14: =S14*D14 | V14: =IFERROR(T14/SUMIF($B$3:$B$15,$B14,$T$3:$T$15),0) | W14: =U14 | X14: =V14*IF($B14="Подзем.",$V$18,$V$19)
A15: 8.2.7 | B15: Надзем. | C15: Паркинг и рампы надзем. | D15: =H28+H29+H30 | E15: 0.5 | F15: 0.5 | G15: =E15+F15 | H15: 0.3 | I15: 0.69 | J15: 0.01 | K15: =SUM(H15:J15) | L15: 0.2 | M15: 0.6 | N15: 0.2 | O15: 0 | P15: 0 | Q15: =SUM(L15:P15) | T15: =IF(OR(Q15="",R15=""),0,R15-Q15) | U15: =S15*D15 | V15: =IFERROR(T15/SUMIF($B$3:$B$15,$B15,$T$3:$T$15),0) | W15: =U15 | X15: =V15*IF($B15="Подзем.",$V$18,$V$19)
A17: АГРЕГАЦИЯ ПО УРОВНЯМ (ур.3 → ур.2 → ур.1)
A18: 8.1 | C18: Подземная часть | D18: =SUM(D3:D8) | R18: =MIN(Q3:Q8) | S18: =MAX(R3:R8) | T18: =IF(OR(Q18=0,R18=0),0,R18-Q18) | U18: =SUM(T3:T8) | V18: =IFERROR(T18/(T18+T19),0) | W18: =U18 | X18: =V18
A19: 8.2 | C19: Надземная часть | D19: =SUM(D9:D15) | R19: =MIN(Q9:Q15) | S19: =MAX(R9:R15) | T19: =IF(OR(Q19=0,R19=0),0,R19-Q19) | U19: =SUM(T9:T15) | V19: =IFERROR(T19/(T18+T19),0) | W19: =U19 | X19: =V19
C21: ✓ ∑ вес ур.3 подзем. | W21: =SUM(V3:V8)
C22: ✓ ∑ вес ур.3 надзем. | W22: =SUM(V9:V15)
C23: ✓ ∑ вес ур.2 | W23: =V18+V19
C24: ✓ ∑ глоб. вес | X24: =SUM(W3:W15)
A26: РАСПРЕДЕЛЕНИЕ НАДЗЕМНОЙ ЧАСТИ ПО КОРПУСАМ
A27: Корпус | B27: 8.2.1 | C27: 8.2.2 | D27: 8.2.3 | E27: 8.2.4 | F27: 8.2.5 | G27: 8.2.6 | H27: 8.2.7 | I27: Σ план | J27: Вес корп.(авто) | K27: Вес корп.
A28: К1 | B28: 0 | C28: 0 | D28: 0 | E28: 0 | F28: 0 | G28: 0 | H28: 0 | I28: =SUM(B28:H28) | J28: =IFERROR(I28/(I28+I29+I30),0) | K28: =J28
A29: К2 | B29: 0 | C29: 0 | D29: 0 | E29: 0 | F29: 0 | G29: 0 | H29: 0 | I29: =SUM(B29:H29) | J29: =IFERROR(I29/(I28+I29+I30),0) | K29: =J29
A30: К3 | B30: 0 | C30: 0 | D30: 0 | E30: 0 | F30: 0 | G30: 0 | H30: 0 | I30: =SUM(B30:H30) | J30: =IFERROR(I30/(I28+I29+I30),0) | K30: =J30
A32: ✓ ∑ вес корп. | K32: =K28+K29+K30
A35: Дата начала проекта | B35: 46174

Sheet ПЛАН ЧЕРН ПОДЗЕМ
A1: ПЛАН ЧЕРН ПОДЗЕМ | U1: Итого подзем.
A2: Дата | B2: Подземная часть
B3: 8.1.1 Отделка паркинг и рампы | E3: 8.1.2 Отделка эвакуац. лестн. клетки подзем. | H3: 8.1.3 Лифт. холлы, тамбур-шлюзы подзем. | K3: 8.1.4 Технич. помещения подзем. | N3: 8.1.5 Прочие помещения подзем. | Q3: 8.1.6 Коммерч. помещения подзем. | U3: Пол | V3: Стены | W3: Потолок
B4: Пол | C4: Стены | D4: Потолок | E4: Пол | F4: Стены | G4: Потолок | H4: Пол | I4: Стены | J4: Потолок | K4: Пол | L4: Стены | M4: Потолок | N4: Пол | O4: Стены | P4: Потолок | Q4: Пол | R4: Стены | S4: Потолок
A5: =СПРАВОЧНИК!$B$35 | U5: =B5+E5+H5+K5+N5+Q5 | V5: =C5+F5+I5+L5+O5+R5 | W5: =D5+G5+J5+M5+P5+S5
A6: =A5+7 | U6: =B6+E6+H6+K6+N6+Q6 | V6: =C6+F6+I6+L6+O6+R6 | W6: =D6+G6+J6+M6+P6+S6
A7: =A6+7 | U7: =B7+E7+H7+K7+N7+Q7 | V7: =C7+F7+I7+L7+O7+R7 | W7: =D7+G7+J7+M7+P7+S7
A8: =A7+7 | U8: =B8+E8+H8+K8+N8+Q8 | V8: =C8+F8+I8+L8+O8+R8 | W8: =D8+G8+J8+M8+P8+S8
A9: =A8+7 | U9: =B9+E9+H9+K9+N9+Q9 | V9: =C9+F9+I9+L9+O9+R9 | W9: =D9+G9+J9+M9+P9+S9
A10: =A9+7 | U10: =B10+E10+H10+K10+N10+Q10 | V10: =C10+F10+I10+L10+O10+R10 | W10: =D10+G10+J10+M10+P10+S10
A11: =A10+7 | U11: =B11+E11+H11+K11+N11+Q11 | V11: =C11+F11+I11+L11+O11+R11 | W11: =D11+G11+J11+M11+P11+S11
A12: =A11+7 | U12: =B12+E12+H12+K12+N12+Q12 | V12: =C12+F12+I12+L12+O12+R12 | W12: =D12+G12+J12+M12+P12+S12
A13: =A12+7 | U13: =B13+E13+H13+K13+N13+Q13 | V13: =C13+F13+I13+L13+O13+R13 | W13: =D13+G13+J13+M13+P13+S13
A14: =A13+7 | U14: =B14+E14+H14+K14+N14+Q14 | V14: =C14+F14+I14+L14+O14+R14 | W14: =D14+G14+J14+M14+P14+S14
A15: =A14+7 | U15: =B15+E15+H15+K15+N15+Q15 | V15: =C15+F15+I15+L15+O15+R15 | W15: =D15+G15+J15+M15+P15+S15
A16: =A15+7 | U16: =B16+E16+H16+K16+N16+Q16 | V16: =C16+F16+I16+L16+O16+R16 | W16: =D16+G16+J16+M16+P16+S16
A17: =A16+7 | U17: =B17+E17+H17+K17+N17+Q17 | V17: =C17+F17+I17+L17+O17+R17 | W17: =D17+G17+J17+M17+P17+S17
... A52: =A51+7 | U52: =B52+E52+H52+K52+N52+Q52 | V52: =C52+F52+I52+L52+O52+R52 | W52: =D52+G52+J52+M52+P52+S52

Sheet ПЛАН ЧИСТ ПОДЗЕМ
A1: ПЛАН ЧИСТ ПОДЗЕМ
A2: Дата | B2: Подземная часть
B3: 8.1.1 Отделка паркинг и рампы | G3: 8.1.2 Отделка эвакуац. лестн. клетки подзем. | L3: 8.1.3 Лифт. холлы, тамбур-шлюзы подзем. | Q3: 8.1.4 Технич. помещения подзем. | V3: 8.1.5 Прочие помещения подзем. | AA3: 8.1.6 Коммерч. помещения подзем. | AF3: Итого
B4: Пол | C4: Стены | D4: Потолок | E4: Запол. | F4: Мебл. | G4: Пол | H4: Стены | I4: Потолок | J4: Запол. | K4: Мебл. | L4: Пол | M4: Стены | N4: Потолок | O4: Запол. | P4: Мебл. | Q4: Пол | R4: Стены | S4: Потолок | T4: Запол. | U4: Мебл. | V4: Пол | W4: Стены | X4: Потолок | Y4: Запол. | Z4: Мебл. | AA4: Пол | AB4: Стены | AC4: Потолок | AD4: Запол. | AE4: Мебл. | AF4: Пол | AG4: Стены | AH4: Потолок | AI4: Запол. | AJ4: Мебл.
A5: =СПРАВОЧНИК!$B$35 | AF5: =B5+G5+L5+Q5+V5+AA5 | AG5: =C5+H5+M5+R5+W5+AB5 | AH5: =D5+I5+N5+S5+X5+AC5 | AI5: =E5+J5+O5+T5+Y5+AD5 | AJ5: =F5+K5+P5+U5+Z5+AE5
A6: =A5+7 | AF6: =B6+G6+L6+Q6+V6+AA6 | AG6: =C6+H6+M6+R6+W6+AB6 | AH6: =D6+I6+N6+S6+X6+AC6 | AI6: =E6+J6+O6+T6+Y6+AD6 | AJ6: =F6+K6+P6+U6+Z6+AE6
A7: =A6+7 | AF7: =B7+G7+L7+Q7+V7+AA7 | AG7: =C7+H7+M7+R7+W7+AB7 | AH7: =D7+I7+N7+S7+X7+AC7 | AI7: =E7+J7+O7+T7+Y7+AD7 | AJ7: =F7+K7+P7+U7+Z7+AE7
A8: =A7+7 | AF8: =B8+G8+L8+Q8+V8+AA8 | AG8: =C8+H8+M8+R8+W8+AB8 | AH8: =D8+I8+N8+S8+X8+AC8 | AI8: =E8+J8+O8+T8+Y8+AD8 | AJ8: =F8+K8+P8+U8+Z8+AE8
A9: =A8+7 | AF9: =B9+G9+L9+Q9+V9+AA9 | AG9: =C9+H9+M9+R9+W9+AB9 | AH9: =D9+I9+N9+S9+X9+AC9 | AI9: =E9+J9+O9+T9+Y9+AD9 | AJ9: =F9+K9+P9+U9+Z9+AE9
A10: =A9+7 | AF10: =B10+G10+L10+Q10+V10+AA10 | AG10: =C10+H10+M10+R10+W10+AB10 | AH10: =D10+I10+N10+S10+X10+AC10 | AI10: =E10+J10+O10+T10+Y10+AD10 | AJ10: =F10+K10+P10+U10+Z10+AE10
A11: =A10+7 | AF11: =B11+G11+L11+Q11+V11+AA11 | AG11: =C11+H11+M11+R11+W11+AB11 | AH11: =D11+I11+N11+S11+X11+AC11 | AI11: =E11+J11+O11+T11+Y11+AD11 | AJ11: =F11+K11+P11+U11+Z11+AE11
A12: =A11+7 | AF12: =B12+G12+L12+Q12+V12+AA12 | AG12: =C12+H12+M12+R12+W12+AB12 | AH12: =D12+I12+N12+S12+X12+AC12 | AI12: =E12+J12+O12+T12+Y12+AD12 | AJ12: =F12+K12+P12+U12+Z12+AE12
A13: =A12+7 | AF13: =B13+G13+L13+Q13+V13+AA13 | AG13: =C13+H13+M13+R13+W13+AB13 | AH13: =D13+I13+N13+S13+X13+AC13 | AI13: =E13+J13+O13+T13+Y13+AD13 | AJ13: =F13+K13+P13+U13+Z13+AE13
A14: =A13+7 | AF14: =B14+G14+L14+Q14+V14+AA14 | AG14: =C14+H14+M14+R14+W14+AB14 | AH14: =D14+I14+N14+S14+X14+AC14 | AI14: =E14+J14+O14+T14+Y14+AD14 | AJ14: =F14+K14+P14+U14+Z14+AE14
A15: =A14+7 | AF15: =B15+G15+L15+Q15+V15+AA15 | AG15: =C15+H15+M15+R15+W15+AB15 | AH15: =D15+I15+N15+S15+X15+AC15 | AI15: =E15+J15+O15+T15+Y15+AD15 | AJ15: =F15+K15+P15+U15+Z15+AE15
A16: =A15+7 | AF16: =B16+G16+L16+Q16+V16+AA16 | AG16: =C16+H16+M16+R16+W16+AB16 | AH16: =D16+I16+N16+S16+X16+AC16 | AI16: =E16+J16+O16+T16+Y16+AD16 | AJ16: =F16+K16+P16+U16+Z16+AE16
A17: =A16+7 | AF17: =B17+G17+L17+Q17+V17+AA17 | AG17: =C17+H17+M17+R17+W17+AB17 | AH17: =D17+I17+N17+S17+X17+AC17 | AI17: =E17+J17+O17+T17+Y17+AD17 | AJ17: =F17+K17+P17+U17+Z17+AE17
... A52: =A51+7 | AF52: =B52+G52+L52+Q52+V52+AA52 | AG52: =C52+H52+M52+R52+W52+AB52 | AH52: =D52+I52+N52+S52+X52+AC52 | AI52: =E52+J52+O52+T52+Y52+AD52 | AJ52: =F52+K52+P52+U52+Z52+AE52

Sheet ПЛАН ЧЕРН К1
A1: ПЛАН ЧЕРН К1 | X1: Итого К1
A2: Дата | B2: Надземная часть
B3: 8.2.1 Отделка лобби/гранд-лобби | E3: 8.2.2 Отделка эвакуац. лестн. клетки надзем. | H3: 8.2.3 Лифт. холлы, тамбур-шлюзы надзем. | K3: 8.2.4 Технич. помещения надзем. | N3: 8.2.5 Прочие помещения надзем. | Q3: 8.2.6 Коммерч. помещения надзем. | T3: 8.2.7 Паркинг и рампы надзем. | X3: Пол | Y3: Стены | Z3: Потолок
B4: Пол | C4: Стены | D4: Потолок | E4: Пол | F4: Стены | G4: Потолок | H4: Пол | I4: Стены | J4: Потолок | K4: Пол | L4: Стены | M4: Потолок | N4: Пол | O4: Стены | P4: Потолок | Q4: Пол | R4: Стены | S4: Потолок | T4: Пол | U4: Стены | V4: Потолок
A5: =СПРАВОЧНИК!$B$35 | X5: =B5+E5+H5+K5+N5+Q5+T5 | Y5: =C5+F5+I5+L5+O5+R5+U5 | Z5: =D5+G5+J5+M5+P5+S5+V5
A6: =A5+7 | X6: =B6+E6+H6+K6+N6+Q6+T6 | Y6: =C6+F6+I6+L6+O6+R6+U6 | Z6: =D6+G6+J6+M6+P6+S6+V6
A7: =A6+7 | X7: =B7+E7+H7+K7+N7+Q7+T7 | Y7: =C7+F7+I7+L7+O7+R7+U7 | Z7: =D7+G7+J7+M7+P7+S7+V7
A8: =A7+7 | X8: =B8+E8+H8+K8+N8+Q8+T8 | Y8: =C8+F8+I8+L8+O8+R8+U8 | Z8: =D8+G8+J8+M8+P8+S8+V8
A9: =A8+7 | X9: =B9+E9+H9+K9+N9+Q9+T9 | Y9: =C9+F9+I9+L9+O9+R9+U9 | Z9: =D9+G9+J9+M9+P9+S9+V9
A10: =A9+7 | X10: =B10+E10+H10+K10+N10+Q10+T10 | Y10: =C10+F10+I10+L10+O10+R10+U10 | Z10: =D10+G10+J10+M10+P10+S10+V10
A11: =A10+7 | X11: =B11+E11+H11+K11+N11+Q11+T11 | Y11: =C11+F11+I11+L11+O11+R11+U11 | Z11: =D11+G11+J11+M11+P11+S11+V11
A12: =A11+7 | X12: =B12+E12+H12+K12+N12+Q12+T12 | Y12: =C12+F12+I12+L12+O12+R12+U12 | Z12: =D12+G12+J12+M12+P12+S12+V12
A13: =A12+7 | X13: =B13+E13+H13+K13+N13+Q13+T13 | Y13: =C13+F13+I13+L13+O13+R13+U13 | Z13: =D13+G13+J13+M13+P13+S13+V13
A14: =A13+7 | X14: =B14+E14+H14+K14+N14+Q14+T14 | Y14: =C14+F14+I14+L14+O14+R14+U14 | Z14: =D14+G14+J14+M14+P14+S14+V14
A15: =A14+7 | X15: =B15+E15+H15+K15+N15+Q15+T15 | Y15: =C15+F15+I15+L15+O15+R15+U15 | Z15: =D15+G15+J15+M15+P15+S15+V15
A16: =A15+7 | X16: =B16+E16+H16+K16+N16+Q16+T16 | Y16: =C16+F16+I16+L16+O16+R16+U16 | Z16: =D16+G16+J16+M16+P16+S16+V16
A17: =A16+7 | X17: =B17+E17+H17+K17+N17+Q17+T17 | Y17: =C17+F17+I17+L17+O17+R17+U17 | Z17: =D17+G17+J17+M17+P17+S17+V17
... A52: =A51+7 | X52: =B52+E52+H52+K52+N52+Q52+T52 | Y52: =C52+F52+I52+L52+O52+R52+U52 | Z52: =D52+G52+J52+M52+P52+S52+V52

Sheet ПЛАН ЧИСТ К1
A1: ПЛАН ЧИСТ К1
A2: Дата | B2: Надземная часть
B3: 8.2.1 Отделка лобби/гранд-лобби | G3: 8.2.2 Отделка эвакуац. лестн. клетки надзем. | L3: 8.2.3 Лифт. холлы, тамбур-шлюзы надзем. | Q3: 8.2.4 Технич. помещения надзем. | V3: 8.2.5 Прочие помещения надзем. | AA3: 8.2.6 Коммерч. помещения надзем. | AF3: 8.2.7 Паркинг и рампы надзем. | AK3: Итого
B4: Пол | C4: Стены | D4: Потолок | E4: Запол. | F4: Мебл. | G4: Пол | H4: Стены | I4: Потолок | J4: Запол. | K4: Мебл. | L4: Пол | M4: Стены | N4: Потолок | O4: Запол. | P4: Мебл. | Q4: Пол | R4: Стены | S4: Потолок | T4: Запол. | U4: Мебл. | V4: Пол | W4: Стены | X4: Потолок | Y4: Запол. | Z4: Мебл. | AA4: Пол | AB4: Стены | AC4: Потолок | AD4: Запол. | AE4: Мебл. | AF4: Пол | AG4: Стены | AH4: Потолок | AI4: Запол. | AJ4: Мебл. | AK4: Пол | AL4: Стены | AM4: Потолок | AN4: Запол. | AO4: Мебл.
A5: =СПРАВОЧНИК!$B$35 | AK5: =B5+G5+L5+Q5+V5+AA5+AF5 | AL5: =C5+H5+M5+R5+W5+AB5+AG5 | AM5: =D5+I5+N5+S5+X5+AC5+AH5 | AN5: =E5+J5+O5+T5+Y5+AD5+AI5 | AO5: =F5+K5+P5+U5+Z5+AE5+AJ5
A6: =A5+7 | AK6: =B6+G6+L6+Q6+V6+AA6+AF6 | AL6: =C6+H6+M6+R6+W6+AB6+AG6 | AM6: =D6+I6+N6+S6+X6+AC6+AH6 | AN6: =E6+J6+O6+T6+Y6+AD6+AI6 | AO6: =F6+K6+P6+U6+Z6+AE6+AJ6
A7: =A6+7 | AK7: =B7+G7+L7+Q7+V7+AA7+AF7 | AL7: =C7+H7+M7+R7+W7+AB7+AG7 | AM7: =D7+I7+N7+S7+X7+AC7+AH7 | AN7: =E7+J7+O7+T7+Y7+AD7+AI7 | AO7: =F7+K7+P7+U7+Z7+AE7+AJ7
A8: =A7+7 | AK8: =B8+G8+L8+Q8+V8+AA8+AF8 | AL8: =C8+H8+M8+R8+W8+AB8+AG8 | AM8: =D8+I8+N8+S8+X8+AC8+AH8 | AN8: =E8+J8+O8+T8+Y8+AD8+AI8 | AO8: =F8+K8+P8+U8+Z8+AE8+AJ8
A9: =A8+7 | AK9: =B9+G9+L9+Q9+V9+AA9+AF9 | AL9: =C9+H9+M9+R9+W9+AB9+AG9 | AM9: =D9+I9+N9+S9+X9+AC9+AH9 | AN9: =E9+J9+O9+T9+Y9+AD9+AI9 | AO9: =F9+K9+P9+U9+Z9+AE9+AJ9
A10: =A9+7 | AK10: =B10+G10+L10+Q10+V10+AA10+AF10 | AL10: =C10+H10+M10+R10+W10+AB10+AG10 | AM10: =D10+I10+N10+S10+X10+AC10+AH10 | AN10: =E10+J10+O10+T10+Y10+AD10+AI10 | AO10: =F10+K10+P10+U10+Z10+AE10+AJ10
A11: =A10+7 | AK11: =B11+G11+L11+Q11+V11+AA11+AF11 | AL11: =C11+H11+M11+R11+W11+AB11+AG11 | AM11: =D11+I11+N11+S11+X11+AC11+AH11 | AN11: =E11+J11+O11+T11+Y11+AD11+AI11 | AO11: =F11+K11+P11+U11+Z11+AE11+AJ11
A12: =A11+7 | AK12: =B12+G12+L12+Q12+V12+AA12+AF12 | AL12: =C12+H12+M12+R12+W12+AB12+AG12 | AM12: =D12+I12+N12+S12+X12+AC12+AH12 | AN12: =E12+J12+O12+T12+Y12+AD12+AI12 | AO12: =F12+K12+P12+U12+Z12+AE12+AJ12
A13: =A12+7 | AK13: =B13+G13+L13+Q13+V13+AA13+AF13 | AL13: =C13+H13+M13+R13+W13+AB13+AG13 | AM13: =D13+I13+N13+S13+X13+AC13+AH13 | AN13: =E13+J13+O13+T13+Y13+AD13+AI13 | AO13: =F13+K13+P13+U13+Z13+AE13+AJ13
A14: =A13+7 | AK14: =B14+G14+L14+Q14+V14+AA14+AF14 | AL14: =C14+H14+M14+R14+W14+AB14+AG14 | AM14: =D14+I14+N14+S14+X14+AC14+AH14 | AN14: =E14+J14+O14+T14+Y14+AD14+AI14 | AO14: =F14+K14+P14+U14+Z14+AE14+AJ14
A15: =A14+7 | AK15: =B15+G15+L15+Q15+V15+AA15+AF15 | AL15: =C15+H15+M15+R15+W15+AB15+AG15 | AM15: =D15+I15+N15+S15+X15+AC15+AH15 | AN15: =E15+J15+O15+T15+Y15+AD15+AI15 | AO15: =F15+K15+P15+U15+Z15+AE15+AJ15
A16: =A15+7 | AK16: =B16+G16+L16+Q16+V16+AA16+AF16 | AL16: =C16+H16+M16+R16+W16+AB16+AG16 | AM16: =D16+I16+N16+S16+X16+AC16+AH16 | AN16: =E16+J16+O16+T16+Y16+AD16+AI16 | AO16: =F16+K16+P16+U16+Z16+AE16+AJ16
A17: =A16+7 | AK17: =B17+G17+L17+Q17+V17+AA17+AF17 | AL17: =C17+H17+M17+R17+W17+AB17+AG17 | AM17: =D17+I17+N17+S17+X17+AC17+AH17 | AN17: =E17+J17+O17+T17+Y17+AD17+AI17 | AO17: =F17+K17+P17+U17+Z17+AE17+AJ17
... A52: =A51+7 | AK52: =B52+G52+L52+Q52+V52+AA52+AF52 | AL52: =C52+H52+M52+R52+W52+AB52+AG52 | AM52: =D52+I52+N52+S52+X52+AC52+AH52 | AN52: =E52+J52+O52+T52+Y52+AD52+AI52 | AO52: =F52+K52+P52+U52+Z52+AE52+AJ52

Sheet ПЛАН ЧЕРН К2
A1: ПЛАН ЧЕРН К2 | X1: Итого К2
A2: Дата | B2: Надземная часть
B3: 8.2.1 Отделка лобби/гранд-лобби | E3: 8.2.2 Отделка эвакуац. лестн. клетки надзем. | H3: 8.2.3 Лифт. холлы, тамбур-шлюзы надзем. | K3: 8.2.4 Технич. помещения надзем. | N3: 8.2.5 Прочие помещения надзем. | Q3: 8.2.6 Коммерч. помещения надзем. | T3: 8.2.7 Паркинг и рампы надзем. | X3: Пол | Y3: Стены | Z3: Потолок
B4: Пол | C4: Стены | D4: Потолок | E4: Пол | F4: Стены | G4: Потолок | H4: Пол | I4: Стены | J4: Потолок | K4: Пол | L4: Стены | M4: Потолок | N4: Пол | O4: Стены | P4: Потолок | Q4: Пол | R4: Стены | S4: Потолок | T4: Пол | U4: Стены | V4: Потолок
A5: =СПРАВОЧНИК!$B$35 | X5: =B5+E5+H5+K5+N5+Q5+T5 | Y5: =C5+F5+I5+L5+O5+R5+U5 | Z5: =D5+G5+J5+M5+P5+S5+V5
A6: =A5+7 | X6: =B6+E6+H6+K6+N6+Q6+T6 | Y6: =C6+F6+I6+L6+O6+R6+U6 | Z6: =D6+G6+J6+M6+P6+S6+V6
A7: =A6+7 | X7: =B7+E7+H7+K7+N7+Q7+T7 | Y7: =C7+F7+I7+L7+O7+R7+U7 | Z7: =D7+G7+J7+M7+P7+S7+V7
A8: =A7+7 | X8: =B8+E8+H8+K8+N8+Q8+T8 | Y8: =C8+F8+I8+L8+O8+R8+U8 | Z8: =D8+G8+J8+M8+P8+S8+V8
A9: =A8+7 | X9: =B9+E9+H9+K9+N9+Q9+T9 | Y9: =C9+F9+I9+L9+O9+R9+U9 | Z9: =D9+G9+J9+M9+P9+S9+V9
A10: =A9+7 | X10: =B10+E10+H10+K10+N10+Q10+T10 | Y10: =C10+F10+I10+L10+O10+R10+U10 | Z10: =D10+G10+J10+M10+P10+S10+V10
A11: =A10+7 | X11: =B11+E11+H11+K11+N11+Q11+T11 | Y11: =C11+F11+I11+L11+O11+R11+U11 | Z11: =D11+G11+J11+M11+P11+S11+V11
A12: =A11+7 | X12: =B12+E12+H12+K12+N12+Q12+T12 | Y12: =C12+F12+I12+L12+O12+R12+U12 | Z12: =D12+G12+J12+M12+P12+S12+V12
A13: =A12+7 | X13: =B13+E13+H13+K13+N13+Q13+T13 | Y13: =C13+F13+I13+L13+O13+R13+U13 | Z13: =D13+G13+J13+M13+P13+S13+V13
A14: =A13+7 | X14: =B14+E14+H14+K14+N14+Q14+T14 | Y14: =C14+F14+I14+L14+O14+R14+U14 | Z14: =D14+G14+J14+M14+P14+S14+V14
A15: =A14+7 | X15: =B15+E15+H15+K15+N15+Q15+T15 | Y15: =C15+F15+I15+L15+O15+R15+U15 | Z15: =D15+G15+J15+M15+P15+S15+V15
A16: =A15+7 | X16: =B16+E16+H16+K16+N16+Q16+T16 | Y16: =C16+F16+I16+L16+O16+R16+U16 | Z16: =D16+G16+J16+M16+P16+S16+V16
A17: =A16+7 | X17: =B17+E17+H17+K17+N17+Q17+T17 | Y17: =C17+F17+I17+L17+O17+R17+U17 | Z17: =D17+G17+J17+M17+P17+S17+V17
... A52: =A51+7 | X52: =B52+E52+H52+K52+N52+Q52+T52 | Y52: =C52+F52+I52+L52+O52+R52+U52 | Z52: =D52+G52+J52+M52+P52+S52+V52

Sheet ПЛАН ЧИСТ К2
A1: ПЛАН ЧИСТ К2
A2: Дата | B2: Надземная часть
B3: 8.2.1 Отделка лобби/гранд-лобби | G3: 8.2.2 Отделка эвакуац. лестн. клетки надзем. | L3: 8.2.3 Лифт. холлы, тамбур-шлюзы надзем. | Q3: 8.2.4 Технич. помещения надзем. | V3: 8.2.5 Прочие помещения надзем. | AA3: 8.2.6 Коммерч. помещения надзем. | AF3: 8.2.7 Паркинг и рампы надзем. | AK3: Итого
B4: Пол | C4: Стены | D4: Потолок | E4: Запол. | F4: Мебл. | G4: Пол | H4: Стены | I4: Потолок | J4: Запол. | K4: Мебл. | L4: Пол | M4: Стены | N4: Потолок | O4: Запол. | P4: Мебл. | Q4: Пол | R4: Стены | S4: Потолок | T4: Запол. | U4: Мебл. | V4: Пол | W4: Стены | X4: Потолок | Y4: Запол. | Z4: Мебл. | AA4: Пол | AB4: Стены | AC4: Потолок | AD4: Запол. | AE4: Мебл. | AF4: Пол | AG4: Стены | AH4: Потолок | AI4: Запол. | AJ4: Мебл. | AK4: Пол | AL4: Стены | AM4: Потолок | AN4: Запол. | AO4: Мебл.
A5: =СПРАВОЧНИК!$B$35 | AK5: =B5+G5+L5+Q5+V5+AA5+AF5 | AL5: =C5+H5+M5+R5+W5+AB5+AG5 | AM5: =D5+I5+N5+S5+X5+AC5+AH5 | AN5: =E5+J5+O5+T5+Y5+AD5+AI5 | AO5: =F5+K5+P5+U5+Z5+AE5+AJ5
A6: =A5+7 | AK6: =B6+G6+L6+Q6+V6+AA6+AF6 | AL6: =C6+H6+M6+R6+W6+AB6+AG6 | AM6: =D6+I6+N6+S6+X6+AC6+AH6 | AN6: =E6+J6+O6+T6+Y6+AD6+AI6 | AO6: =F6+K6+P6+U6+Z6+AE6+AJ6
A7: =A6+7 | AK7: =B7+G7+L7+Q7+V7+AA7+AF7 | AL7: =C7+H7+M7+R7+W7+AB7+AG7 | AM7: =D7+I7+N7+S7+X7+AC7+AH7 | AN7: =E7+J7+O7+T7+Y7+AD7+AI7 | AO7: =F7+K7+P7+U7+Z7+AE7+AJ7
A8: =A7+7 | AK8: =B8+G8+L8+Q8+V8+AA8+AF8 | AL8: =C8+H8+M8+R8+W8+AB8+AG8 | AM8: =D8+I8+N8+S8+X8+AC8+AH8 | AN8: =E8+J8+O8+T8+Y8+AD8+AI8 | AO8: =F8+K8+P8+U8+Z8+AE8+AJ8
A9: =A8+7 | AK9: =B9+G9+L9+Q9+V9+AA9+AF9 | AL9: =C9+H9+M9+R9+W9+AB9+AG9 | AM9: =D9+I9+N9+S9+X9+AC9+AH9 | AN9: =E9+J9+O9+T9+Y9+AD9+AI9 | AO9: =F9+K9+P9+U9+Z9+AE9+AJ9
A10: =A9+7 | AK10: =B10+G10+L10+Q10+V10+AA10+AF10 | AL10: =C10+H10+M10+R10+W10+AB10+AG10 | AM10: =D10+I10+N10+S10+X10+AC10+AH10 | AN10: =E10+J10+O10+T10+Y10+AD10+AI10 | AO10: =F10+K10+P10+U10+Z10+AE10+AJ10
A11: =A10+7 | AK11: =B11+G11+L11+Q11+V11+AA11+AF11 | AL11: =C11+H11+M11+R11+W11+AB11+AG11 | AM11: =D11+I11+N11+S11+X11+AC11+AH11 | AN11: =E11+J11+O11+T11+Y11+AD11+AI11 | AO11: =F11+K11+P11+U11+Z11+AE11+AJ11
A12: =A11+7 | AK12: =B12+G12+L12+Q12+V12+AA12+AF12 | AL12: =C12+H12+M12+R12+W12+AB12+AG12 | AM12: =D12+I12+N12+S12+X12+AC12+AH12 | AN12: =E12+J12+O12+T12+Y12+AD12+AI12 | AO12: =F12+K12+P12+U12+Z12+AE12+AJ12
A13: =A12+7 | AK13: =B13+G13+L13+Q13+V13+AA13+AF13 | AL13: =C13+H13+M13+R13+W13+AB13+AG13 | AM13: =D13+I13+N13+S13+X13+AC13+AH13 | AN13: =E13+J13+O13+T13+Y13+AD13+AI13 | AO13: =F13+K13+P13+U13+Z13+AE13+AJ13
A14: =A13+7 | AK14: =B14+G14+L14+Q14+V14+AA14+AF14 | AL14: =C14+H14+M14+R14+W14+AB14+AG14 | AM14: =D14+I14+N14+S14+X14+AC14+AH14 | AN14: =E14+J14+O14+T14+Y14+AD14+AI14 | AO14: =F14+K14+P14+U14+Z14+AE14+AJ14
A15: =A14+7 | AK15: =B15+G15+L15+Q15+V15+AA15+AF15 | AL15: =C15+H15+M15+R15+W15+AB15+AG15 | AM15: =D15+I15+N15+S15+X15+AC15+AH15 | AN15: =E15+J15+O15+T15+Y15+AD15+AI15 | AO15: =F15+K15+P15+U15+Z15+AE15+AJ15
A16: =A15+7 | AK16: =B16+G16+L16+Q16+V16+AA16+AF16 | AL16: =C16+H16+M16+R16+W16+AB16+AG16 | AM16: =D16+I16+N16+S16+X16+AC16+AH16 | AN16: =E16+J16+O16+T16+Y16+AD16+AI16 | AO16: =F16+K16+P16+U16+Z16+AE16+AJ16
A17: =A16+7 | AK17: =B17+G17+L17+Q17+V17+AA17+AF17 | AL17: =C17+H17+M17+R17+W17+AB17+AG17 | AM17: =D17+I17+N17+S17+X17+AC17+AH17 | AN17: =E17+J17+O17+T17+Y17+AD17+AI17 | AO17: =F17+K17+P17+U17+Z17+AE17+AJ17
... A52: =A51+7 | AK52: =B52+G52+L52+Q52+V52+AA52+AF52 | AL52: =C52+H52+M52+R52+W52+AB52+AG52 | AM52: =D52+I52+N52+S52+X52+AC52+AH52 | AN52: =E52+J52+O52+T52+Y52+AD52+AI52 | AO52: =F52+K52+P52+U52+Z52+AE52+AJ52

Sheet ПЛАН ЧЕРН К3
A1: ПЛАН ЧЕРН К3 | X1: Итого К3
A2: Дата | B2: Надземная часть
B3: 8.2.1 Отделка лобби/гранд-лобби | E3: 8.2.2 Отделка эвакуац. лестн. клетки надзем. | H3: 8.2.3 Лифт. холлы, тамбур-шлюзы надзем. | K3: 8.2.4 Технич. помещения надзем. | N3: 8.2.5 Прочие помещения надзем. | Q3: 8.2.6 Коммерч. помещения надзем. | T3: 8.2.7 Паркинг и рампы надзем. | X3: Пол | Y3: Стены | Z3: Потолок
B4: Пол | C4: Стены | D4: Потолок | E4: Пол | F4: Стены | G4: Потолок | H4: Пол | I4: Стены | J4: Потолок | K4: Пол | L4: Стены | M4: Потолок | N4: Пол | O4: Стены | P4: Потолок | Q4: Пол | R4: Стены | S4: Потолок | T4: Пол | U4: Стены | V4: Потолок
A5: =СПРАВОЧНИК!$B$35 | X5: =B5+E5+H5+K5+N5+Q5+T5 | Y5: =C5+F5+I5+L5+O5+R5+U5 | Z5: =D5+G5+J5+M5+P5+S5+V5
A6: =A5+7 | X6: =B6+E6+H6+K6+N6+Q6+T6 | Y6: =C6+F6+I6+L6+O6+R6+U6 | Z6: =D6+G6+J6+M6+P6+S6+V6
A7: =A6+7 | X7: =B7+E7+H7+K7+N7+Q7+T7 | Y7: =C7+F7+I7+L7+O7+R7+U7 | Z7: =D7+G7+J7+M7+P7+S7+V7
A8: =A7+7 | X8: =B8+E8+H8+K8+N8+Q8+T8 | Y8: =C8+F8+I8+L8+O8+R8+U8 | Z8: =D8+G8+J8+M8+P8+S8+V8
A9: =A8+7 | X9: =B9+E9+H9+K9+N9+Q9+T9 | Y9: =C9+F9+I9+L9+O9+R9+U9 | Z9: =D9+G9+J9+M9+P9+S9+V9
A10: =A9+7 | X10: =B10+E10+H10+K10+N10+Q10+T10 | Y10: =C10+F10+I10+L10+O10+R10+U10 | Z10: =D10+G10+J10+M10+P10+S10+V10
A11: =A10+7 | X11: =B11+E11+H11+K11+N11+Q11+T11 | Y11: =C11+F11+I11+L11+O11+R11+U11 | Z11: =D11+G11+J11+M11+P11+S11+V11
A12: =A11+7 | X12: =B12+E12+H12+K12+N12+Q12+T12 | Y12: =C12+F12+I12+L12+O12+R12+U12 | Z12: =D12+G12+J12+M12+P12+S12+V12
A13: =A12+7 | X13: =B13+E13+H13+K13+N13+Q13+T13 | Y13: =C13+F13+I13+L13+O13+R13+U13 | Z13: =D13+G13+J13+M13+P13+S13+V13
A14: =A13+7 | X14: =B14+E14+H14+K14+N14+Q14+T14 | Y14: =C14+F14+I14+L14+O14+R14+U14 | Z14: =D14+G14+J14+M14+P14+S14+V14
A15: =A14+7 | X15: =B15+E15+H15+K15+N15+Q15+T15 | Y15: =C15+F15+I15+L15+O15+R15+U15 | Z15: =D15+G15+J15+M15+P15+S15+V15
A16: =A15+7 | X16: =B16+E16+H16+K16+N16+Q16+T16 | Y16: =C16+F16+I16+L16+O16+R16+U16 | Z16: =D16+G16+J16+M16+P16+S16+V16
A17: =A16+7 | X17: =B17+E17+H17+K17+N17+Q17+T17 | Y17: =C17+F17+I17+L17+O17+R17+U17 | Z17: =D17+G17+J17+M17+P17+S17+V17
... A52: =A51+7 | X52: =B52+E52+H52+K52+N52+Q52+T52 | Y52: =C52+F52+I52+L52+O52+R52+U52 | Z52: =D52+G52+J52+M52+P52+S52+V52

Sheet ПЛАН ЧИСТ К3
A1: ПЛАН ЧИСТ К3
A2: Дата | B2: Надземная часть
B3: 8.2.1 Отделка лобби/гранд-лобби | G3: 8.2.2 Отделка эвакуац. лестн. клетки надзем. | L3: 8.2.3 Лифт. холлы, тамбур-шлюзы надзем. | Q3: 8.2.4 Технич. помещения надзем. | V3: 8.2.5 Прочие помещения надзем. | AA3: 8.2.6 Коммерч. помещения надзем. | AF3: 8.2.7 Паркинг и рампы надзем. | AK3: Итого
B4: Пол | C4: Стены | D4: Потолок | E4: Запол. | F4: Мебл. | G4: Пол | H4: Стены | I4: Потолок | J4: Запол. | K4: Мебл. | L4: Пол | M4: Стены | N4: Потолок | O4: Запол. | P4: Мебл. | Q4: Пол | R4: Стены | S4: Потолок | T4: Запол. | U4: Мебл. | V4: Пол | W4: Стены | X4: Потолок | Y4: Запол. | Z4: Мебл. | AA4: Пол | AB4: Стены | AC4: Потолок | AD4: Запол. | AE4: Мебл. | AF4: Пол | AG4: Стены | AH4: Потолок | AI4: Запол. | AJ4: Мебл. | AK4: Пол | AL4: Стены | AM4: Потолок | AN4: Запол. | AO4: Мебл.
A5: =СПРАВОЧНИК!$B$35 | AK5: =B5+G5+L5+Q5+V5+AA5+AF5 | AL5: =C5+H5+M5+R5+W5+AB5+AG5 | AM5: =D5+I5+N5+S5+X5+AC5+AH5 | AN5: =E5+J5+O5+T5+Y5+AD5+AI5 | AO5: =F5+K5+P5+U5+Z5+AE5+AJ5
A6: =A5+7 | AK6: =B6+G6+L6+Q6+V6+AA6+AF6 | AL6: =C6+H6+M6+R6+W6+AB6+AG6 | AM6: =D6+I6+N6+S6+X6+AC6+AH6 | AN6: =E6+J6+O6+T6+Y6+AD6+AI6 | AO6: =F6+K6+P6+U6+Z6+AE6+AJ6
A7: =A6+7 | AK7: =B7+G7+L7+Q7+V7+AA7+AF7 | AL7: =C7+H7+M7+R7+W7+AB7+AG7 | AM7: =D7+I7+N7+S7+X7+AC7+AH7 | AN7: =E7+J7+O7+T7+Y7+AD7+AI7 | AO7: =F7+K7+P7+U7+Z7+AE7+AJ7
A8: =A7+7 | AK8: =B8+G8+L8+Q8+V8+AA8+AF8 | AL8: =C8+H8+M8+R8+W8+AB8+AG8 | AM8: =D8+I8+N8+S8+X8+AC8+AH8 | AN8: =E8+J8+O8+T8+Y8+AD8+AI8 | AO8: =F8+K8+P8+U8+Z8+AE8+AJ8
A9: =A8+7 | AK9: =B9+G9+L9+Q9+V9+AA9+AF9 | AL9: =C9+H9+M9+R9+W9+AB9+AG9 | AM9: =D9+I9+N9+S9+X9+AC9+AH9 | AN9: =E9+J9+O9+T9+Y9+AD9+AI9 | AO9: =F9+K9+P9+U9+Z9+AE9+AJ9
A10: =A9+7 | AK10: =B10+G10+L10+Q10+V10+AA10+AF10 | AL10: =C10+H10+M10+R10+W10+AB10+AG10 | AM10: =D10+I10+N10+S10+X10+AC10+AH10 | AN10: =E10+J10+O10+T10+Y10+AD10+AI10 | AO10: =F10+K10+P10+U10+Z10+AE10+AJ10
A11: =A10+7 | AK11: =B11+G11+L11+Q11+V11+AA11+AF11 | AL11: =C11+H11+M11+R11+W11+AB11+AG11 | AM11: =D11+I11+N11+S11+X11+AC11+AH11 | AN11: =E11+J11+O11+T11+Y11+AD11+AI11 | AO11: =F11+K11+P11+U11+Z11+AE11+AJ11
A12: =A11+7 | AK12: =B12+G12+L12+Q12+V12+AA12+AF12 | AL12: =C12+H12+M12+R12+W12+AB12+AG12 | AM12: =D12+I12+N12+S12+X12+AC12+AH12 | AN12: =E12+J12+O12+T12+Y12+AD12+AI12 | AO12: =F12+K12+P12+U12+Z12+AE12+AJ12
A13: =A12+7 | AK13: =B13+G13+L13+Q13+V13+AA13+AF13 | AL13: =C13+H13+M13+R13+W13+AB13+AG13 | AM13: =D13+I13+N13+S13+X13+AC13+AH13 | AN13: =E13+J13+O13+T13+Y13+AD13+AI13 | AO13: =F13+K13+P13+U13+Z13+AE13+AJ13
A14: =A13+7 | AK14: =B14+G14+L14+Q14+V14+AA14+AF14 | AL14: =C14+H14+M14+R14+W14+AB14+AG14 | AM14: =D14+I14+N14+S14+X14+AC14+AH14 | AN14: =E14+J14+O14+T14+Y14+AD14+AI14 | AO14: =F14+K14+P14+U14+Z14+AE14+AJ14
A15: =A14+7 | AK15: =B15+G15+L15+Q15+V15+AA15+AF15 | AL15: =C15+H15+M15+R15+W15+AB15+AG15 | AM15: =D15+I15+N15+S15+X15+AC15+AH15 | AN15: =E15+J15+O15+T15+Y15+AD15+AI15 | AO15: =F15+K15+P15+U15+Z15+AE15+AJ15
A16: =A15+7 | AK16: =B16+G16+L16+Q16+V16+AA16+AF16 | AL16: =C16+H16+M16+R16+W16+AB16+AG16 | AM16: =D16+I16+N16+S16+X16+AC16+AH16 | AN16: =E16+J16+O16+T16+Y16+AD16+AI16 | AO16: =F16+K16+P16+U16+Z16+AE16+AJ16
A17: =A16+7 | AK17: =B17+G17+L17+Q17+V17+AA17+AF17 | AL17: =C17+H17+M17+R17+W17+AB17+AG17 | AM17: =D17+I17+N17+S17+X17+AC17+AH17 | AN17: =E17+J17+O17+T17+Y17+AD17+AI17 | AO17: =F17+K17+P17+U17+Z17+AE17+AJ17
... A52: =A51+7 | AK52: =B52+G52+L52+Q52+V52+AA52+AF52 | AL52: =C52+H52+M52+R52+W52+AB52+AG52 | AM52: =D52+I52+N52+S52+X52+AC52+AH52 | AN52: =E52+J52+O52+T52+Y52+AD52+AI52 | AO52: =F52+K52+P52+U52+Z52+AE52+AJ52

Sheet ФАКТ ЧЕРН ПОДЗЕМ
A1: ФАКТ ЧЕРН ПОДЗЕМ | U1: Итого подзем.
A2: Дата | B2: Подземная часть
B3: 8.1.1 Отделка паркинг и рампы | E3: 8.1.2 Отделка эвакуац. лестн. клетки подзем. | H3: 8.1.3 Лифт. холлы, тамбур-шлюзы подзем. | K3: 8.1.4 Технич. помещения подзем. | N3: 8.1.5 Прочие помещения подзем. | Q3: 8.1.6 Коммерч. помещения подзем. | U3: Пол | V3: Стены | W3: Потолок
B4: Пол | C4: Стены | D4: Потолок | E4: Пол | F4: Стены | G4: Потолок | H4: Пол | I4: Стены | J4: Потолок | K4: Пол | L4: Стены | M4: Потолок | N4: Пол | O4: Стены | P4: Потолок | Q4: Пол | R4: Стены | S4: Потолок
A5: =СПРАВОЧНИК!$B$35 | U5: =B5+E5+H5+K5+N5+Q5 | V5: =C5+F5+I5+L5+O5+R5 | W5: =D5+G5+J5+M5+P5+S5
A6: =A5+7 | U6: =B6+E6+H6+K6+N6+Q6 | V6: =C6+F6+I6+L6+O6+R6 | W6: =D6+G6+J6+M6+P6+S6
A7: =A6+7 | U7: =B7+E7+H7+K7+N7+Q7 | V7: =C7+F7+I7+L7+O7+R7 | W7: =D7+G7+J7+M7+P7+S7
A8: =A7+7 | U8: =B8+E8+H8+K8+N8+Q8 | V8: =C8+F8+I8+L8+O8+R8 | W8: =D8+G8+J8+M8+P8+S8
A9: =A8+7 | U9: =B9+E9+H9+K9+N9+Q9 | V9: =C9+F9+I9+L9+O9+R9 | W9: =D9+G9+J9+M9+P9+S9
A10: =A9+7 | U10: =B10+E10+H10+K10+N10+Q10 | V10: =C10+F10+I10+L10+O10+R10 | W10: =D10+G10+J10+M10+P10+S10
A11: =A10+7 | U11: =B11+E11+H11+K11+N11+Q11 | V11: =C11+F11+I11+L11+O11+R11 | W11: =D11+G11+J11+M11+P11+S11
A12: =A11+7 | U12: =B12+E12+H12+K12+N12+Q12 | V12: =C12+F12+I12+L12+O12+R12 | W12: =D12+G12+J12+M12+P12+S12
A13: =A12+7 | U13: =B13+E13+H13+K13+N13+Q13 | V13: =C13+F13+I13+L13+O13+R13 | W13: =D13+G13+J13+M13+P13+S13
A14: =A13+7 | U14: =B14+E14+H14+K14+N14+Q14 | V14: =C14+F14+I14+L14+O14+R14 | W14: =D14+G14+J14+M14+P14+S14
A15: =A14+7 | U15: =B15+E15+H15+K15+N15+Q15 | V15: =C15+F15+I15+L15+O15+R15 | W15: =D15+G15+J15+M15+P15+S15
A16: =A15+7 | U16: =B16+E16+H16+K16+N16+Q16 | V16: =C16+F16+I16+L16+O16+R16 | W16: =D16+G16+J16+M16+P16+S16
A17: =A16+7 | U17: =B17+E17+H17+K17+N17+Q17 | V17: =C17+F17+I17+L17+O17+R17 | W17: =D17+G17+J17+M17+P17+S17
... A52: =A51+7 | U52: =B52+E52+H52+K52+N52+Q52 | V52: =C52+F52+I52+L52+O52+R52 | W52: =D52+G52+J52+M52+P52+S52

Sheet ФАКТ ЧИСТ ПОДЗЕМ
A1: ФАКТ ЧИСТ ПОДЗЕМ
A2: Дата | B2: Подземная часть
B3: 8.1.1 Отделка паркинг и рампы | G3: 8.1.2 Отделка эвакуац. лестн. клетки подзем. | L3: 8.1.3 Лифт. холлы, тамбур-шлюзы подзем. | Q3: 8.1.4 Технич. помещения подзем. | V3: 8.1.5 Прочие помещения подзем. | AA3: 8.1.6 Коммерч. помещения подзем. | AF3: Итого
B4: Пол | C4: Стены | D4: Потолок | E4: Запол. | F4: Мебл. | G4: Пол | H4: Стены | I4: Потолок | J4: Запол. | K4: Мебл. | L4: Пол | M4: Стены | N4: Потолок | O4: Запол. | P4: Мебл. | Q4: Пол | R4: Стены | S4: Потолок | T4: Запол. | U4: Мебл. | V4: Пол | W4: Стены | X4: Потолок | Y4: Запол. | Z4: Мебл. | AA4: Пол | AB4: Стены | AC4: Потолок | AD4: Запол. | AE4: Мебл. | AF4: Пол | AG4: Стены | AH4: Потолок | AI4: Запол. | AJ4: Мебл.
A5: =СПРАВОЧНИК!$B$35 | AF5: =B5+G5+L5+Q5+V5+AA5 | AG5: =C5+H5+M5+R5+W5+AB5 | AH5: =D5+I5+N5+S5+X5+AC5 | AI5: =E5+J5+O5+T5+Y5+AD5 | AJ5: =F5+K5+P5+U5+Z5+AE5
A6: =A5+7 | AF6: =B6+G6+L6+Q6+V6+AA6 | AG6: =C6+H6+M6+R6+W6+AB6 | AH6: =D6+I6+N6+S6+X6+AC6 | AI6: =E6+J6+O6+T6+Y6+AD6 | AJ6: =F6+K6+P6+U6+Z6+AE6
A7: =A6+7 | AF7: =B7+G7+L7+Q7+V7+AA7 | AG7: =C7+H7+M7+R7+W7+AB7 | AH7: =D7+I7+N7+S7+X7+AC7 | AI7: =E7+J7+O7+T7+Y7+AD7 | AJ7: =F7+K7+P7+U7+Z7+AE7
A8: =A7+7 | AF8: =B8+G8+L8+Q8+V8+AA8 | AG8: =C8+H8+M8+R8+W8+AB8 | AH8: =D8+I8+N8+S8+X8+AC8 | AI8: =E8+J8+O8+T8+Y8+AD8 | AJ8: =F8+K8+P8+U8+Z8+AE8
A9: =A8+7 | AF9: =B9+G9+L9+Q9+V9+AA9 | AG9: =C9+H9+M9+R9+W9+AB9 | AH9: =D9+I9+N9+S9+X9+AC9 | AI9: =E9+J9+O9+T9+Y9+AD9 | AJ9: =F9+K9+P9+U9+Z9+AE9
A10: =A9+7 | AF10: =B10+G10+L10+Q10+V10+AA10 | AG10: =C10+H10+M10+R10+W10+AB10 | AH10: =D10+I10+N10+S10+X10+AC10 | AI10: =E10+J10+O10+T10+Y10+AD10 | AJ10: =F10+K10+P10+U10+Z10+AE10
A11: =A10+7 | AF11: =B11+G11+L11+Q11+V11+AA11 | AG11: =C11+H11+M11+R11+W11+AB11 | AH11: =D11+I11+N11+S11+X11+AC11 | AI11: =E11+J11+O11+T11+Y11+AD11 | AJ11: =F11+K11+P11+U11+Z11+AE11
A12: =A11+7 | AF12: =B12+G12+L12+Q12+V12+AA12 | AG12: =C12+H12+M12+R12+W12+AB12 | AH12: =D12+I12+N12+S12+X12+AC12 | AI12: =E12+J12+O12+T12+Y12+AD12 | AJ12: =F12+K12+P12+U12+Z12+AE12
A13: =A12+7 | AF13: =B13+G13+L13+Q13+V13+AA13 | AG13: =C13+H13+M13+R13+W13+AB13 | AH13: =D13+I13+N13+S13+X13+AC13 | AI13: =E13+J13+O13+T13+Y13+AD13 | AJ13: =F13+K13+P13+U13+Z13+AE13
A14: =A13+7 | AF14: =B14+G14+L14+Q14+V14+AA14 | AG14: =C14+H14+M14+R14+W14+AB14 | AH14: =D14+I14+N14+S14+X14+AC14 | AI14: =E14+J14+O14+T14+Y14+AD14 | AJ14: =F14+K14+P14+U14+Z14+AE14
A15: =A14+7 | AF15: =B15+G15+L15+Q15+V15+AA15 | AG15: =C15+H15+M15+R15+W15+AB15 | AH15: =D15+I15+N15+S15+X15+AC15 | AI15: =E15+J15+O15+T15+Y15+AD15 | AJ15: =F15+K15+P15+U15+Z15+AE15
A16: =A15+7 | AF16: =B16+G16+L16+Q16+V16+AA16 | AG16: =C16+H16+M16+R16+W16+AB16 | AH16: =D16+I16+N16+S16+X16+AC16 | AI16: =E16+J16+O16+T16+Y16+AD16 | AJ16: =F16+K16+P16+U16+Z16+AE16
A17: =A16+7 | AF17: =B17+G17+L17+Q17+V17+AA17 | AG17: =C17+H17+M17+R17+W17+AB17 | AH17: =D17+I17+N17+S17+X17+AC17 | AI17: =E17+J17+O17+T17+Y17+AD17 | AJ17: =F17+K17+P17+U17+Z17+AE17
... A52: =A51+7 | AF52: =B52+G52+L52+Q52+V52+AA52 | AG52: =C52+H52+M52+R52+W52+AB52 | AH52: =D52+I52+N52+S52+X52+AC52 | AI52: =E52+J52+O52+T52+Y52+AD52 | AJ52: =F52+K52+P52+U52+Z52+AE52

Sheet ФАКТ ЧЕРН К1
A1: ФАКТ ЧЕРН К1 | X1: Итого К1
A2: Дата | B2: Надземная часть
B3: 8.2.1 Отделка лобби/гранд-лобби | E3: 8.2.2 Отделка эвакуац. лестн. клетки надзем. | H3: 8.2.3 Лифт. холлы, тамбур-шлюзы надзем. | K3: 8.2.4 Технич. помещения надзем. | N3: 8.2.5 Прочие помещения надзем. | Q3: 8.2.6 Коммерч. помещения надзем. | T3: 8.2.7 Паркинг и рампы надзем. | X3: Пол | Y3: Стены | Z3: Потолок
B4: Пол | C4: Стены | D4: Потолок | E4: Пол | F4: Стены | G4: Потолок | H4: Пол | I4: Стены | J4: Потолок | K4: Пол | L4: Стены | M4: Потолок | N4: Пол | O4: Стены | P4: Потолок | Q4: Пол | R4: Стены | S4: Потолок | T4: Пол | U4: Стены | V4: Потолок
A5: =СПРАВОЧНИК!$B$35 | X5: =B5+E5+H5+K5+N5+Q5+T5 | Y5: =C5+F5+I5+L5+O5+R5+U5 | Z5: =D5+G5+J5+M5+P5+S5+V5
A6: =A5+7 | X6: =B6+E6+H6+K6+N6+Q6+T6 | Y6: =C6+F6+I6+L6+O6+R6+U6 | Z6: =D6+G6+J6+M6+P6+S6+V6
A7: =A6+7 | X7: =B7+E7+H7+K7+N7+Q7+T7 | Y7: =C7+F7+I7+L7+O7+R7+U7 | Z7: =D7+G7+J7+M7+P7+S7+V7
A8: =A7+7 | X8: =B8+E8+H8+K8+N8+Q8+T8 | Y8: =C8+F8+I8+L8+O8+R8+U8 | Z8: =D8+G8+J8+M8+P8+S8+V8
A9: =A8+7 | X9: =B9+E9+H9+K9+N9+Q9+T9 | Y9: =C9+F9+I9+L9+O9+R9+U9 | Z9: =D9+G9+J9+M9+P9+S9+V9
A10: =A9+7 | X10: =B10+E10+H10+K10+N10+Q10+T10 | Y10: =C10+F10+I10+L10+O10+R10+U10 | Z10: =D10+G10+J10+M10+P10+S10+V10
A11: =A10+7 | X11: =B11+E11+H11+K11+N11+Q11+T11 | Y11: =C11+F11+I11+L11+O11+R11+U11 | Z11: =D11+G11+J11+M11+P11+S11+V11
A12: =A11+7 | X12: =B12+E12+H12+K12+N12+Q12+T12 | Y12: =C12+F12+I12+L12+O12+R12+U12 | Z12: =D12+G12+J12+M12+P12+S12+V12
A13: =A12+7 | X13: =B13+E13+H13+K13+N13+Q13+T13 | Y13: =C13+F13+I13+L13+O13+R13+U13 | Z13: =D13+G13+J13+M13+P13+S13+V13
A14: =A13+7 | X14: =B14+E14+H14+K14+N14+Q14+T14 | Y14: =C14+F14+I14+L14+O14+R14+U14 | Z14: =D14+G14+J14+M14+P14+S14+V14
A15: =A14+7 | X15: =B15+E15+H15+K15+N15+Q15+T15 | Y15: =C15+F15+I15+L15+O15+R15+U15 | Z15: =D15+G15+J15+M15+P15+S15+V15
A16: =A15+7 | X16: =B16+E16+H16+K16+N16+Q16+T16 | Y16: =C16+F16+I16+L16+O16+R16+U16 | Z16: =D16+G16+J16+M16+P16+S16+V16
A17: =A16+7 | X17: =B17+E17+H17+K17+N17+Q17+T17 | Y17: =C17+F17+I17+L17+O17+R17+U17 | Z17: =D17+G17+J17+M17+P17+S17+V17
... A52: =A51+7 | X52: =B52+E52+H52+K52+N52+Q52+T52 | Y52: =C52+F52+I52+L52+O52+R52+U52 | Z52: =D52+G52+J52+M52+P52+S52+V52

Sheet ФАКТ ЧИСТ К1
A1: ФАКТ ЧИСТ К1
A2: Дата | B2: Надземная часть
B3: 8.2.1 Отделка лобби/гранд-лобби | G3: 8.2.2 Отделка эвакуац. лестн. клетки надзем. | L3: 8.2.3 Лифт. холлы, тамбур-шлюзы надзем. | Q3: 8.2.4 Технич. помещения надзем. | V3: 8.2.5 Прочие помещения надзем. | AA3: 8.2.6 Коммерч. помещения надзем. | AF3: 8.2.7 Паркинг и рампы надзем. | AK3: Итого
B4: Пол | C4: Стены | D4: Потолок | E4: Запол. | F4: Мебл. | G4: Пол | H4: Стены | I4: Потолок | J4: Запол. | K4: Мебл. | L4: Пол | M4: Стены | N4: Потолок | O4: Запол. | P4: Мебл. | Q4: Пол | R4: Стены | S4: Потолок | T4: Запол. | U4: Мебл. | V4: Пол | W4: Стены | X4: Потолок | Y4: Запол. | Z4: Мебл. | AA4: Пол | AB4: Стены | AC4: Потолок | AD4: Запол. | AE4: Мебл. | AF4: Пол | AG4: Стены | AH4: Потолок | AI4: Запол. | AJ4: Мебл. | AK4: Пол | AL4: Стены | AM4: Потолок | AN4: Запол. | AO4: Мебл.
A5: =СПРАВОЧНИК!$B$35 | AK5: =B5+G5+L5+Q5+V5+AA5+AF5 | AL5: =C5+H5+M5+R5+W5+AB5+AG5 | AM5: =D5+I5+N5+S5+X5+AC5+AH5 | AN5: =E5+J5+O5+T5+Y5+AD5+AI5 | AO5: =F5+K5+P5+U5+Z5+AE5+AJ5
A6: =A5+7 | AK6: =B6+G6+L6+Q6+V6+AA6+AF6 | AL6: =C6+H6+M6+R6+W6+AB6+AG6 | AM6: =D6+I6+N6+S6+X6+AC6+AH6 | AN6: =E6+J6+O6+T6+Y6+AD6+AI6 | AO6: =F6+K6+P6+U6+Z6+AE6+AJ6
A7: =A6+7 | AK7: =B7+G7+L7+Q7+V7+AA7+AF7 | AL7: =C7+H7+M7+R7+W7+AB7+AG7 | AM7: =D7+I7+N7+S7+X7+AC7+AH7 | AN7: =E7+J7+O7+T7+Y7+AD7+AI7 | AO7: =F7+K7+P7+U7+Z7+AE7+AJ7
A8: =A7+7 | AK8: =B8+G8+L8+Q8+V8+AA8+AF8 | AL8: =C8+H8+M8+R8+W8+AB8+AG8 | AM8: =D8+I8+N8+S8+X8+AC8+AH8 | AN8: =E8+J8+O8+T8+Y8+AD8+AI8 | AO8: =F8+K8+P8+U8+Z8+AE8+AJ8
A9: =A8+7 | AK9: =B9+G9+L9+Q9+V9+AA9+AF9 | AL9: =C9+H9+M9+R9+W9+AB9+AG9 | AM9: =D9+I9+N9+S9+X9+AC9+AH9 | AN9: =E9+J9+O9+T9+Y9+AD9+AI9 | AO9: =F9+K9+P9+U9+Z9+AE9+AJ9
A10: =A9+7 | AK10: =B10+G10+L10+Q10+V10+AA10+AF10 | AL10: =C10+H10+M10+R10+W10+AB10+AG10 | AM10: =D10+I10+N10+S10+X10+AC10+AH10 | AN10: =E10+J10+O10+T10+Y10+AD10+AI10 | AO10: =F10+K10+P10+U10+Z10+AE10+AJ10
A11: =A10+7 | AK11: =B11+G11+L11+Q11+V11+AA11+AF11 | AL11: =C11+H11+M11+R11+W11+AB11+AG11 | AM11: =D11+I11+N11+S11+X11+AC11+AH11 | AN11: =E11+J11+O11+T11+Y11+AD11+AI11 | AO11: =F11+K11+P11+U11+Z11+AE11+AJ11
A12: =A11+7 | AK12: =B12+G12+L12+Q12+V12+AA12+AF12 | AL12: =C12+H12+M12+R12+W12+AB12+AG12 | AM12: =D12+I12+N12+S12+X12+AC12+AH12 | AN12: =E12+J12+O12+T12+Y12+AD12+AI12 | AO12: =F12+K12+P12+U12+Z12+AE12+AJ12
A13: =A12+7 | AK13: =B13+G13+L13+Q13+V13+AA13+AF13 | AL13: =C13+H13+M13+R13+W13+AB13+AG13 | AM13: =D13+I13+N13+S13+X13+AC13+AH13 | AN13: =E13+J13+O13+T13+Y13+AD13+AI13 | AO13: =F13+K13+P13+U13+Z13+AE13+AJ13
A14: =A13+7 | AK14: =B14+G14+L14+Q14+V14+AA14+AF14 | AL14: =C14+H14+M14+R14+W14+AB14+AG14 | AM14: =D14+I14+N14+S14+X14+AC14+AH14 | AN14: =E14+J14+O14+T14+Y14+AD14+AI14 | AO14: =F14+K14+P14+U14+Z14+AE14+AJ14
A15: =A14+7 | AK15: =B15+G15+L15+Q15+V15+AA15+AF15 | AL15: =C15+H15+M15+R15+W15+AB15+AG15 | AM15: =D15+I15+N15+S15+X15+AC15+AH15 | AN15: =E15+J15+O15+T15+Y15+AD15+AI15 | AO15: =F15+K15+P15+U15+Z15+AE15+AJ15
A16: =A15+7 | AK16: =B16+G16+L16+Q16+V16+AA16+AF16 | AL16: =C16+H16+M16+R16+W16+AB16+AG16 | AM16: =D16+I16+N16+S16+X16+AC16+AH16 | AN16: =E16+J16+O16+T16+Y16+AD16+AI16 | AO16: =F16+K16+P16+U16+Z16+AE16+AJ16
A17: =A16+7 | AK17: =B17+G17+L17+Q17+V17+AA17+AF17 | AL17: =C17+H17+M17+R17+W17+AB17+AG17 | AM17: =D17+I17+N17+S17+X17+AC17+AH17 | AN17: =E17+J17+O17+T17+Y17+AD17+AI17 | AO17: =F17+K17+P17+U17+Z17+AE17+AJ17
... A52: =A51+7 | AK52: =B52+G52+L52+Q52+V52+AA52+AF52 | AL52: =C52+H52+M52+R52+W52+AB52+AG52 | AM52: =D52+I52+N52+S52+X52+AC52+AH52 | AN52: =E52+J52+O52+T52+Y52+AD52+AI52 | AO52: =F52+K52+P52+U52+Z52+AE52+AJ52

Sheet ФАКТ ЧЕРН К2
A1: ФАКТ ЧЕРН К2 | X1: Итого К2
A2: Дата | B2: Надземная часть
B3: 8.2.1 Отделка лобби/гранд-лобби | E3: 8.2.2 Отделка эвакуац. лестн. клетки надзем. | H3: 8.2.3 Лифт. холлы, тамбур-шлюзы надзем. | K3: 8.2.4 Технич. помещения надзем. | N3: 8.2.5 Прочие помещения надзем. | Q3: 8.2.6 Коммерч. помещения надзем. | T3: 8.2.7 Паркинг и рампы надзем. | X3: Пол | Y3: Стены | Z3: Потолок
B4: Пол | C4: Стены | D4: Потолок | E4: Пол | F4: Стены | G4: Потолок | H4: Пол | I4: Стены | J4: Потолок | K4: Пол | L4: Стены | M4: Потолок | N4: Пол | O4: Стены | P4: Потолок | Q4: Пол | R4: Стены | S4: Потолок | T4: Пол | U4: Стены | V4: Потолок
A5: =СПРАВОЧНИК!$B$35 | X5: =B5+E5+H5+K5+N5+Q5+T5 | Y5: =C5+F5+I5+L5+O5+R5+U5 | Z5: =D5+G5+J5+M5+P5+S5+V5
A6: =A5+7 | X6: =B6+E6+H6+K6+N6+Q6+T6 | Y6: =C6+F6+I6+L6+O6+R6+U6 | Z6: =D6+G6+J6+M6+P6+S6+V6
A7: =A6+7 | X7: =B7+E7+H7+K7+N7+Q7+T7 | Y7: =C7+F7+I7+L7+O7+R7+U7 | Z7: =D7+G7+J7+M7+P7+S7+V7
A8: =A7+7 | X8: =B8+E8+H8+K8+N8+Q8+T8 | Y8: =C8+F8+I8+L8+O8+R8+U8 | Z8: =D8+G8+J8+M8+P8+S8+V8
A9: =A8+7 | X9: =B9+E9+H9+K9+N9+Q9+T9 | Y9: =C9+F9+I9+L9+O9+R9+U9 | Z9: =D9+G9+J9+M9+P9+S9+V9
A10: =A9+7 | X10: =B10+E10+H10+K10+N10+Q10+T10 | Y10: =C10+F10+I10+L10+O10+R10+U10 | Z10: =D10+G10+J10+M10+P10+S10+V10
A11: =A10+7 | X11: =B11+E11+H11+K11+N11+Q11+T11 | Y11: =C11+F11+I11+L11+O11+R11+U11 | Z11: =D11+G11+J11+M11+P11+S11+V11
A12: =A11+7 | X12: =B12+E12+H12+K12+N12+Q12+T12 | Y12: =C12+F12+I12+L12+O12+R12+U12 | Z12: =D12+G12+J12+M12+P12+S12+V12
A13: =A12+7 | X13: =B13+E13+H13+K13+N13+Q13+T13 | Y13: =C13+F13+I13+L13+O13+R13+U13 | Z13: =D13+G13+J13+M13+P13+S13+V13
A14: =A13+7 | X14: =B14+E14+H14+K14+N14+Q14+T14 | Y14: =C14+F14+I14+L14+O14+R14+U14 | Z14: =D14+G14+J14+M14+P14+S14+V14
A15: =A14+7 | X15: =B15+E15+H15+K15+N15+Q15+T15 | Y15: =C15+F15+I15+L15+O15+R15+U15 | Z15: =D15+G15+J15+M15+P15+S15+V15
A16: =A15+7 | X16: =B16+E16+H16+K16+N16+Q16+T16 | Y16: =C16+F16+I16+L16+O16+R16+U16 | Z16: =D16+G16+J16+M16+P16+S16+V16
A17: =A16+7 | X17: =B17+E17+H17+K17+N17+Q17+T17 | Y17: =C17+F17+I17+L17+O17+R17+U17 | Z17: =D17+G17+J17+M17+P17+S17+V17
... A52: =A51+7 | X52: =B52+E52+H52+K52+N52+Q52+T52 | Y52: =C52+F52+I52+L52+O52+R52+U52 | Z52: =D52+G52+J52+M52+P52+S52+V52

Sheet ФАКТ ЧИСТ К2
A1: ФАКТ ЧИСТ К2
A2: Дата | B2: Надземная часть
B3: 8.2.1 Отделка лобби/гранд-лобби | G3: 8.2.2 Отделка эвакуац. лестн. клетки надзем. | L3: 8.2.3 Лифт. холлы, тамбур-шлюзы надзем. | Q3: 8.2.4 Технич. помещения надзем. | V3: 8.2.5 Прочие помещения надзем. | AA3: 8.2.6 Коммерч. помещения надзем. | AF3: 8.2.7 Паркинг и рампы надзем. | AK3: Итого
B4: Пол | C4: Стены | D4: Потолок | E4: Запол. | F4: Мебл. | G4: Пол | H4: Стены | I4: Потолок | J4: Запол. | K4: Мебл. | L4: Пол | M4: Стены | N4: Потолок | O4: Запол. | P4: Мебл. | Q4: Пол | R4: Стены | S4: Потолок | T4: Запол. | U4: Мебл. | V4: Пол | W4: Стены | X4: Потолок | Y4: Запол. | Z4: Мебл. | AA4: Пол | AB4: Стены | AC4: Потолок | AD4: Запол. | AE4: Мебл. | AF4: Пол | AG4: Стены | AH4: Потолок | AI4: Запол. | AJ4: Мебл. | AK4: Пол | AL4: Стены | AM4: Потолок | AN4: Запол. | AO4: Мебл.
A5: =СПРАВОЧНИК!$B$35 | AK5: =B5+G5+L5+Q5+V5+AA5+AF5 | AL5: =C5+H5+M5+R5+W5+AB5+AG5 | AM5: =D5+I5+N5+S5+X5+AC5+AH5 | AN5: =E5+J5+O5+T5+Y5+AD5+AI5 | AO5: =F5+K5+P5+U5+Z5+AE5+AJ5
A6: =A5+7 | AK6: =B6+G6+L6+Q6+V6+AA6+AF6 | AL6: =C6+H6+M6+R6+W6+AB6+AG6 | AM6: =D6+I6+N6+S6+X6+AC6+AH6 | AN6: =E6+J6+O6+T6+Y6+AD6+AI6 | AO6: =F6+K6+P6+U6+Z6+AE6+AJ6
A7: =A6+7 | AK7: =B7+G7+L7+Q7+V7+AA7+AF7 | AL7: =C7+H7+M7+R7+W7+AB7+AG7 | AM7: =D7+I7+N7+S7+X7+AC7+AH7 | AN7: =E7+J7+O7+T7+Y7+AD7+AI7 | AO7: =F7+K7+P7+U7+Z7+AE7+AJ7
A8: =A7+7 | AK8: =B8+G8+L8+Q8+V8+AA8+AF8 | AL8: =C8+H8+M8+R8+W8+AB8+AG8 | AM8: =D8+I8+N8+S8+X8+AC8+AH8 | AN8: =E8+J8+O8+T8+Y8+AD8+AI8 | AO8: =F8+K8+P8+U8+Z8+AE8+AJ8
A9: =A8+7 | AK9: =B9+G9+L9+Q9+V9+AA9+AF9 | AL9: =C9+H9+M9+R9+W9+AB9+AG9 | AM9: =D9+I9+N9+S9+X9+AC9+AH9 | AN9: =E9+J9+O9+T9+Y9+AD9+AI9 | AO9: =F9+K9+P9+U9+Z9+AE9+AJ9
A10: =A9+7 | AK10: =B10+G10+L10+Q10+V10+AA10+AF10 | AL10: =C10+H10+M10+R10+W10+AB10+AG10 | AM10: =D10+I10+N10+S10+X10+AC10+AH10 | AN10: =E10+J10+O10+T10+Y10+AD10+AI10 | AO10: =F10+K10+P10+U10+Z10+AE10+AJ10
A11: =A10+7 | AK11: =B11+G11+L11+Q11+V11+AA11+AF11 | AL11: =C11+H11+M11+R11+W11+AB11+AG11 | AM11: =D11+I11+N11+S11+X11+AC11+AH11 | AN11: =E11+J11+O11+T11+Y11+AD11+AI11 | AO11: =F11+K11+P11+U11+Z11+AE11+AJ11
A12: =A11+7 | AK12: =B12+G12+L12+Q12+V12+AA12+AF12 | AL12: =C12+H12+M12+R12+W12+AB12+AG12 | AM12: =D12+I12+N12+S12+X12+AC12+AH12 | AN12: =E12+J12+O12+T12+Y12+AD12+AI12 | AO12: =F12+K12+P12+U12+Z12+AE12+AJ12
A13: =A12+7 | AK13: =B13+G13+L13+Q13+V13+AA13+AF13 | AL13: =C13+H13+M13+R13+W13+AB13+AG13 | AM13: =D13+I13+N13+S13+X13+AC13+AH13 | AN13: =E13+J13+O13+T13+Y13+AD13+AI13 | AO13: =F13+K13+P13+U13+Z13+AE13+AJ13
A14: =A13+7 | AK14: =B14+G14+L14+Q14+V14+AA14+AF14 | AL14: =C14+H14+M14+R14+W14+AB14+AG14 | AM14: =D14+I14+N14+S14+X14+AC14+AH14 | AN14: =E14+J14+O14+T14+Y14+AD14+AI14 | AO14: =F14+K14+P14+U14+Z14+AE14+AJ14
A15: =A14+7 | AK15: =B15+G15+L15+Q15+V15+AA15+AF15 | AL15: =C15+H15+M15+R15+W15+AB15+AG15 | AM15: =D15+I15+N15+S15+X15+AC15+AH15 | AN15: =E15+J15+O15+T15+Y15+AD15+AI15 | AO15: =F15+K15+P15+U15+Z15+AE15+AJ15
A16: =A15+7 | AK16: =B16+G16+L16+Q16+V16+AA16+AF16 | AL16: =C16+H16+M16+R16+W16+AB16+AG16 | AM16: =D16+I16+N16+S16+X16+AC16+AH16 | AN16: =E16+J16+O16+T16+Y16+AD16+AI16 | AO16: =F16+K16+P16+U16+Z16+AE16+AJ16
A17: =A16+7 | AK17: =B17+G17+L17+Q17+V17+AA17+AF17 | AL17: =C17+H17+M17+R17+W17+AB17+AG17 | AM17: =D17+I17+N17+S17+X17+AC17+AH17 | AN17: =E17+J17+O17+T17+Y17+AD17+AI17 | AO17: =F17+K17+P17+U17+Z17+AE17+AJ17
... A52: =A51+7 | AK52: =B52+G52+L52+Q52+V52+AA52+AF52 | AL52: =C52+H52+M52+R52+W52+AB52+AG52 | AM52: =D52+I52+N52+S52+X52+AC52+AH52 | AN52: =E52+J52+O52+T52+Y52+AD52+AI52 | AO52: =F52+K52+P52+U52+Z52+AE52+AJ52

Sheet ФАКТ ЧЕРН К3
A1: ФАКТ ЧЕРН К3 | X1: Итого К3
A2: Дата | B2: Надземная часть
B3: 8.2.1 Отделка лобби/гранд-лобби | E3: 8.2.2 Отделка эвакуац. лестн. клетки надзем. | H3: 8.2.3 Лифт. холлы, тамбур-шлюзы надзем. | K3: 8.2.4 Технич. помещения надзем. | N3: 8.2.5 Прочие помещения надзем. | Q3: 8.2.6 Коммерч. помещения надзем. | T3: 8.2.7 Паркинг и рампы надзем. | X3: Пол | Y3: Стены | Z3: Потолок
B4: Пол | C4: Стены | D4: Потолок | E4: Пол | F4: Стены | G4: Потолок | H4: Пол | I4: Стены | J4: Потолок | K4: Пол | L4: Стены | M4: Потолок | N4: Пол | O4: Стены | P4: Потолок | Q4: Пол | R4: Стены | S4: Потолок | T4: Пол | U4: Стены | V4: Потолок
A5: =СПРАВОЧНИК!$B$35 | X5: =B5+E5+H5+K5+N5+Q5+T5 | Y5: =C5+F5+I5+L5+O5+R5+U5 | Z5: =D5+G5+J5+M5+P5+S5+V5
A6: =A5+7 | X6: =B6+E6+H6+K6+N6+Q6+T6 | Y6: =C6+F6+I6+L6+O6+R6+U6 | Z6: =D6+G6+J6+M6+P6+S6+V6
A7: =A6+7 | X7: =B7+E7+H7+K7+N7+Q7+T7 | Y7: =C7+F7+I7+L7+O7+R7+U7 | Z7: =D7+G7+J7+M7+P7+S7+V7
A8: =A7+7 | X8: =B8+E8+H8+K8+N8+Q8+T8 | Y8: =C8+F8+I8+L8+O8+R8+U8 | Z8: =D8+G8+J8+M8+P8+S8+V8
A9: =A8+7 | X9: =B9+E9+H9+K9+N9+Q9+T9 | Y9: =C9+F9+I9+L9+O9+R9+U9 | Z9: =D9+G9+J9+M9+P9+S9+V9
A10: =A9+7 | X10: =B10+E10+H10+K10+N10+Q10+T10 | Y10: =C10+F10+I10+L10+O10+R10+U10 | Z10: =D10+G10+J10+M10+P10+S10+V10
A11: =A10+7 | X11: =B11+E11+H11+K11+N11+Q11+T11 | Y11: =C11+F11+I11+L11+O11+R11+U11 | Z11: =D11+G11+J11+M11+P11+S11+V11
A12: =A11+7 | X12: =B12+E12+H12+K12+N12+Q12+T12 | Y12: =C12+F12+I12+L12+O12+R12+U12 | Z12: =D12+G12+J12+M12+P12+S12+V12
A13: =A12+7 | X13: =B13+E13+H13+K13+N13+Q13+T13 | Y13: =C13+F13+I13+L13+O13+R13+U13 | Z13: =D13+G13+J13+M13+P13+S13+V13
A14: =A13+7 | X14: =B14+E14+H14+K14+N14+Q14+T14 | Y14: =C14+F14+I14+L14+O14+R14+U14 | Z14: =D14+G14+J14+M14+P14+S14+V14
A15: =A14+7 | X15: =B15+E15+H15+K15+N15+Q15+T15 | Y15: =C15+F15+I15+L15+O15+R15+U15 | Z15: =D15+G15+J15+M15+P15+S15+V15
A16: =A15+7 | X16: =B16+E16+H16+K16+N16+Q16+T16 | Y16: =C16+F16+I16+L16+O16+R16+U16 | Z16: =D16+G16+J16+M16+P16+S16+V16
A17: =A16+7 | X17: =B17+E17+H17+K17+N17+Q17+T17 | Y17: =C17+F17+I17+L17+O17+R17+U17 | Z17: =D17+G17+J17+M17+P17+S17+V17
... A52: =A51+7 | X52: =B52+E52+H52+K52+N52+Q52+T52 | Y52: =C52+F52+I52+L52+O52+R52+U52 | Z52: =D52+G52+J52+M52+P52+S52+V52

Sheet ФАКТ ЧИСТ К3
A1: ФАКТ ЧИСТ К3
A2: Дата | B2: Надземная часть
B3: 8.2.1 Отделка лобби/гранд-лобби | G3: 8.2.2 Отделка эвакуац. лестн. клетки надзем. | L3: 8.2.3 Лифт. холлы, тамбур-шлюзы надзем. | Q3: 8.2.4 Технич. помещения надзем. | V3: 8.2.5 Прочие помещения надзем. | AA3: 8.2.6 Коммерч. помещения надзем. | AF3: 8.2.7 Паркинг и рампы надзем. | AK3: Итого
B4: Пол | C4: Стены | D4: Потолок | E4: Запол. | F4: Мебл. | G4: Пол | H4: Стены | I4: Потолок | J4: Запол. | K4: Мебл. | L4: Пол | M4: Стены | N4: Потолок | O4: Запол. | P4: Мебл. | Q4: Пол | R4: Стены | S4: Потолок | T4: Запол. | U4: Мебл. | V4: Пол | W4: Стены | X4: Потолок | Y4: Запол. | Z4: Мебл. | AA4: Пол | AB4: Стены | AC4: Потолок | AD4: Запол. | AE4: Мебл. | AF4: Пол | AG4: Стены | AH4: Потолок | AI4: Запол. | AJ4: Мебл. | AK4: Пол | AL4: Стены | AM4: Потолок | AN4: Запол. | AO4: Мебл.
A5: =СПРАВОЧНИК!$B$35 | AK5: =B5+G5+L5+Q5+V5+AA5+AF5 | AL5: =C5+H5+M5+R5+W5+AB5+AG5 | AM5: =D5+I5+N5+S5+X5+AC5+AH5 | AN5: =E5+J5+O5+T5+Y5+AD5+AI5 | AO5: =F5+K5+P5+U5+Z5+AE5+AJ5
A6: =A5+7 | AK6: =B6+G6+L6+Q6+V6+AA6+AF6 | AL6: =C6+H6+M6+R6+W6+AB6+AG6 | AM6: =D6+I6+N6+S6+X6+AC6+AH6 | AN6: =E6+J6+O6+T6+Y6+AD6+AI6 | AO6: =F6+K6+P6+U6+Z6+AE6+AJ6
A7: =A6+7 | AK7: =B7+G7+L7+Q7+V7+AA7+AF7 | AL7: =C7+H7+M7+R7+W7+AB7+AG7 | AM7: =D7+I7+N7+S7+X7+AC7+AH7 | AN7: =E7+J7+O7+T7+Y7+AD7+AI7 | AO7: =F7+K7+P7+U7+Z7+AE7+AJ7
A8: =A7+7 | AK8: =B8+G8+L8+Q8+V8+AA8+AF8 | AL8: =C8+H8+M8+R8+W8+AB8+AG8 | AM8: =D8+I8+N8+S8+X8+AC8+AH8 | AN8: =E8+J8+O8+T8+Y8+AD8+AI8 | AO8: =F8+K8+P8+U8+Z8+AE8+AJ8
A9: =A8+7 | AK9: =B9+G9+L9+Q9+V9+AA9+AF9 | AL9: =C9+H9+M9+R9+W9+AB9+AG9 | AM9: =D9+I9+N9+S9+X9+AC9+AH9 | AN9: =E9+J9+O9+T9+Y9+AD9+AI9 | AO9: =F9+K9+P9+U9+Z9+AE9+AJ9
A10: =A9+7 | AK10: =B10+G10+L10+Q10+V10+AA10+AF10 | AL10: =C10+H10+M10+R10+W10+AB10+AG10 | AM10: =D10+I10+N10+S10+X10+AC10+AH10 | AN10: =E10+J10+O10+T10+Y10+AD10+AI10 | AO10: =F10+K10+P10+U10+Z10+AE10+AJ10
A11: =A10+7 | AK11: =B11+G11+L11+Q11+V11+AA11+AF11 | AL11: =C11+H11+M11+R11+W11+AB11+AG11 | AM11: =D11+I11+N11+S11+X11+AC11+AH11 | AN11: =E11+J11+O11+T11+Y11+AD11+AI11 | AO11: =F11+K11+P11+U11+Z11+AE11+AJ11
A12: =A11+7 | AK12: =B12+G12+L12+Q12+V12+AA12+AF12 | AL12: =C12+H12+M12+R12+W12+AB12+AG12 | AM12: =D12+I12+N12+S12+X12+AC12+AH12 | AN12: =E12+J12+O12+T12+Y12+AD12+AI12 | AO12: =F12+K12+P12+U12+Z12+AE12+AJ12
A13: =A12+7 | AK13: =B13+G13+L13+Q13+V13+AA13+AF13 | AL13: =C13+H13+M13+R13+W13+AB13+AG13 | AM13: =D13+I13+N13+S13+X13+AC13+AH13 | AN13: =E13+J13+O13+T13+Y13+AD13+AI13 | AO13: =F13+K13+P13+U13+Z13+AE13+AJ13
A14: =A13+7 | AK14: =B14+G14+L14+Q14+V14+AA14+AF14 | AL14: =C14+H14+M14+R14+W14+AB14+AG14 | AM14: =D14+I14+N14+S14+X14+AC14+AH14 | AN14: =E14+J14+O14+T14+Y14+AD14+AI14 | AO14: =F14+K14+P14+U14+Z14+AE14+AJ14
A15: =A14+7 | AK15: =B15+G15+L15+Q15+V15+AA15+AF15 | AL15: =C15+H15+M15+R15+W15+AB15+AG15 | AM15: =D15+I15+N15+S15+X15+AC15+AH15 | AN15: =E15+J15+O15+T15+Y15+AD15+AI15 | AO15: =F15+K15+P15+U15+Z15+AE15+AJ15
A16: =A15+7 | AK16: =B16+G16+L16+Q16+V16+AA16+AF16 | AL16: =C16+H16+M16+R16+W16+AB16+AG16 | AM16: =D16+I16+N16+S16+X16+AC16+AH16 | AN16: =E16+J16+O16+T16+Y16+AD16+AI16 | AO16: =F16+K16+P16+U16+Z16+AE16+AJ16
A17: =A16+7 | AK17: =B17+G17+L17+Q17+V17+AA17+AF17 | AL17: =C17+H17+M17+R17+W17+AB17+AG17 | AM17: =D17+I17+N17+S17+X17+AC17+AH17 | AN17: =E17+J17+O17+T17+Y17+AD17+AI17 | AO17: =F17+K17+P17+U17+Z17+AE17+AJ17
... A52: =A51+7 | AK52: =B52+G52+L52+Q52+V52+AA52+AF52 | AL52: =C52+H52+M52+R52+W52+AB52+AG52 | AM52: =D52+I52+N52+S52+X52+AC52+AH52 | AN52: =E52+J52+O52+T52+Y52+AD52+AI52 | AO52: =F52+K52+P52+U52+Z52+AE52+AJ52

Sheet ОТЧЕТ
A1: ОТЧЁТ ПО ОТДЕЛОЧНЫМ РАБОТАМ
A2: ⚠ Автоматический. Не вносите данные напрямую.
A4: ПОДЗЕМНАЯ ЧАСТЬ
A5: Код | B5: Название | C5: Тип | D5: Вес ур.4 | E5: Вес ур.5 | F5: План м² | G5: Факт м² | H5: Факт % | I5: Взвеш. %
A6: 8.1.1 | B6: =СПРАВОЧНИК!C3 | C6: Главная | F6: =СПРАВОЧНИК!D3 | G6: =G7*D7+G11*D11 | H6: =IF(F6=0,0,G6/F6) | I6: =I7+I11
B7: Черновая | C7: Категория | D7: =СПРАВОЧНИК!E3 | F7: =F6 | G7: =G8*E8+G9*E9+G10*E10 | H7: =IF(F7=0,0,G7/F7) | I7: =H7*D7
B8: Пол | C8: Вид | E8: =СПРАВОЧНИК!$H$3 | F8: =F6 | G8: =SUM('ФАКТ ЧЕРН ПОДЗЕМ'!B5:B100) | H8: =IF(F8=0,0,G8/F8) | I8: =H8*E8
B9: Стены | C9: Вид | E9: =СПРАВОЧНИК!$I$3 | F9: =F6 | G9: =SUM('ФАКТ ЧЕРН ПОДЗЕМ'!C5:C100) | H9: =IF(F9=0,0,G9/F9) | I9: =H9*E9
B10: Потолок | C10: Вид | E10: =СПРАВОЧНИК!$J$3 | F10: =F6 | G10: =SUM('ФАКТ ЧЕРН ПОДЗЕМ'!D5:D100) | H10: =IF(F10=0,0,G10/F10) | I10: =H10*E10
B11: Чистовая | C11: Категория | D11: =СПРАВОЧНИК!F3 | F11: =F6 | G11: =G12*E12+G13*E13+G14*E14+G15*E15+G16*E16 | H11: =IF(F11=0,0,G11/F11) | I11: =H11*D11
B12: Пол | C12: Вид | E12: =СПРАВОЧНИК!$L$3 | F12: =F6 | G12: =SUM('ФАКТ ЧИСТ ПОДЗЕМ'!B5:B100) | H12: =IF(F12=0,0,G12/F12) | I12: =H12*E12
B13: Стены | C13: Вид | E13: =СПРАВОЧНИК!$M$3 | F13: =F6 | G13: =SUM('ФАКТ ЧИСТ ПОДЗЕМ'!C5:C100) | H13: =IF(F13=0,0,G13/F13) | I13: =H13*E13
B14: Потолок | C14: Вид | E14: =СПРАВОЧНИК!$N$3 | F14: =F6 | G14: =SUM('ФАКТ ЧИСТ ПОДЗЕМ'!D5:D100) | H14: =IF(F14=0,0,G14/F14) | I14: =H14*E14
B15: Заполн. проемов | C15: Вид | E15: =СПРАВОЧНИК!$O$3 | F15: =F6 | G15: =SUM('ФАКТ ЧИСТ ПОДЗЕМ'!E5:E100) | H15: =IF(F15=0,0,G15/F15) | I15: =H15*E15
B16: Меблировка | C16: Вид | E16: =СПРАВОЧНИК!$P$3 | F16: =F6 | G16: =SUM('ФАКТ ЧИСТ ПОДЗЕМ'!F5:F100) | H16: =IF(F16=0,0,G16/F16) | I16: =H16*E16
B17: ✓ Сумма | D17: =D7+D11
A19: 8.1.2 | B19: =СПРАВОЧНИК!C4 | C19: Главная | F19: =СПРАВОЧНИК!D4 | G19: =G20*D20+G24*D24 | H19: =IF(F19=0,0,G19/F19) | I19: =I20+I24
B20: Черновая | C20: Категория | D20: =СПРАВОЧНИК!E4 | F20: =F19 | G20: =G21*E21+G22*E22+G23*E23 | H20: =IF(F20=0,0,G20/F20) | I20: =H20*D20
B21: Пол | C21: Вид | E21: =СПРАВОЧНИК!$H$4 | F21: =F19 | G21: =SUM('ФАКТ ЧЕРН ПОДЗЕМ'!E5:E100) | H21: =IF(F21=0,0,G21/F21) | I21: =H21*E21
B22: Стены | C22: Вид | E22: =СПРАВОЧНИК!$I$4 | F22: =F19 | G22: =SUM('ФАКТ ЧЕРН ПОДЗЕМ'!F5:F100) | H22: =IF(F22=0,0,G22/F22) | I22: =H22*E22
B23: Потолок | C23: Вид | E23: =СПРАВОЧНИК!$J$4 | F23: =F19 | G23: =SUM('ФАКТ ЧЕРН ПОДЗЕМ'!G5:G100) | H23: =IF(F23=0,0,G23/F23) | I23: =H23*E23
B24: Чистовая | C24: Категория | D24: =СПРАВОЧНИК!F4 | F24: =F19 | G24: =G25*E25+G26*E26+G27*E27+G28*E28+G29*E29 | H24: =IF(F24=0,0,G24/F24) | I24: =H24*D24
B25: Пол | C25: Вид | E25: =СПРАВОЧНИК!$L$4 | F25: =F19 | G25: =SUM('ФАКТ ЧИСТ ПОДЗЕМ'!G5:G100) | H25: =IF(F25=0,0,G25/F25) | I25: =H25*E25
B26: Стены | C26: Вид | E26: =СПРАВОЧНИК!$M$4 | F26: =F19 | G26: =SUM('ФАКТ ЧИСТ ПОДЗЕМ'!H5:H100) | H26: =IF(F26=0,0,G26/F26) | I26: =H26*E26
B27: Потолок | C27: Вид | E27: =СПРАВОЧНИК!$N$4 | F27: =F19 | G27: =SUM('ФАКТ ЧИСТ ПОДЗЕМ'!I5:I100) | H27: =IF(F27=0,0,G27/F27) | I27: =H27*E27
B28: Заполн. проемов | C28: Вид | E28: =СПРАВОЧНИК!$O$4 | F28: =F19 | G28: =SUM('ФАКТ ЧИСТ ПОДЗЕМ'!J5:J100) | H28: =IF(F28=0,0,G28/F28) | I28: =H28*E28
B29: Меблировка | C29: Вид | E29: =СПРАВОЧНИК!$P$4 | F29: =F19 | G29: =SUM('ФАКТ ЧИСТ ПОДЗЕМ'!K5:K100) | H29: =IF(F29=0,0,G29/F29) | I29: =H29*E29
B30: ✓ Сумма | D30: =D20+D24
A32: 8.1.3 | B32: =СПРАВОЧНИК!C5 | C32: Главная | F32: =СПРАВОЧНИК!D5 | G32: =G33*D33+G37*D37 | H32: =IF(F32=0,0,G32/F32) | I32: =I33+I37
B33: Черновая | C33: Категория | D33: =СПРАВОЧНИК!E5 | F33: =F32 | G33: =G34*E34+G35*E35+G36*E36 | H33: =IF(F33=0,0,G33/F33) | I33: =H33*D33
B34: Пол | C34: Вид | E34: =СПРАВОЧНИК!$H$5 | F34: =F32 | G34: =SUM('ФАКТ ЧЕРН ПОДЗЕМ'!H5:H100) | H34: =IF(F34=0,0,G34/F34) | I34: =H34*E34
B35: Стены | C35: Вид | E35: =СПРАВОЧНИК!$I$5 | F35: =F32 | G35: =SUM('ФАКТ ЧЕРН ПОДЗЕМ'!I5:I100) | H35: =IF(F35=0,0,G35/F35) | I35: =H35*E35
B36: Потолок | C36: Вид | E36: =СПРАВОЧНИК!$J$5 | F36: =F32 | G36: =SUM('ФАКТ ЧЕРН ПОДЗЕМ'!J5:J100) | H36: =IF(F36=0,0,G36/F36) | I36: =H36*E36
B37: Чистовая | C37: Категория | D37: =СПРАВОЧНИК!F5 | F37: =F32 | G37: =G38*E38+G39*E39+G40*E40+G41*E41+G42*E42 | H37: =IF(F37=0,0,G37/F37) | I37: =H37*D37
B38: Пол | C38: Вид | E38: =СПРАВОЧНИК!$L$5 | F38: =F32 | G38: =SUM('ФАКТ ЧИСТ ПОДЗЕМ'!L5:L100) | H38: =IF(F38=0,0,G38/F38) | I38: =H38*E38
B39: Стены | C39: Вид | E39: =СПРАВОЧНИК!$M$5 | F39: =F32 | G39: =SUM('ФАКТ ЧИСТ ПОДЗЕМ'!M5:M100) | H39: =IF(F39=0,0,G39/F39) | I39: =H39*E39
B40: Потолок | C40: Вид | E40: =СПРАВОЧНИК!$N$5 | F40: =F32 | G40: =SUM('ФАКТ ЧИСТ ПОДЗЕМ'!N5:N100) | H40: =IF(F40=0,0,G40/F40) | I40: =H40*E40
B41: Заполн. проемов | C41: Вид | E41: =СПРАВОЧНИК!$O$5 | F41: =F32 | G41: =SUM('ФАКТ ЧИСТ ПОДЗЕМ'!O5:O100) | H41: =IF(F41=0,0,G41/F41) | I41: =H41*E41
